Workbook

Sheet 구매요청서
A1: 관급자재 구매 요청서
A3: □ 공사개요
B4: ○ | C4: 공사명 | D4: : | E4: 국도5호선 신림~판부1 도로건설 전기공사(4차)
B5: ○ | C5: 주요공종 | D5: : | E5: CABLE TRAY 및 접지설비 공사
B6: ○ | C6: 관급자재품목 | D6: : | E6: 케이블트레이,조이너
B7: ○ | C7: 공사기간 | D7: : | E7: 2026. 03. 16 ~ 2027. 11. 12
B8: ○ | C8: 공사위치 | D8: : | E8: 강원특별자치도 원주시 신림면 신림리 ~ 원주시 판부면 금대리
A10: □ 관급자재 요구내역 | M10: (부가세 포함)
A12: 자 재 명 | F12: 규 격 | J12: 단위 | K12: 수 량 | L12: 단 가(원) | M12: 금 액(원) | N12: 비 고
A13: Ⅱ 전기공사 관급자재 | M13: =SUM(M15)
A14: 1. 도급자관급 | M14: =M15
M15: =SUM(M16:M35)
A16: =IF(구매내역현황!A10="","",구매내역현황!A10) | F16: =IF(구매내역현황!A10="","",구매내역현황!B10) | J16: =IF(구매내역현황!A10="","",구매내역현황!C10) | K16: =IF(구매내역현황!A10="","",구매내역현황!N10) | L16: =IF(구매내역현황!A10="","",구매내역현황!O10) | M16: =IF(구매내역현황!A10="","",TRUNC(K16*L16,0))
A17: =IF(구매내역현황!A11="","",구매내역현황!A11) | F17: =IF(구매내역현황!A11="","",구매내역현황!B11) | J17: =IF(구매내역현황!A11="","",구매내역현황!C11) | K17: =IF(구매내역현황!A11="","",구매내역현황!N11) | L17: =IF(구매내역현황!A11="","",구매내역현황!O11) | M17: =IF(구매내역현황!A11="","",TRUNC(K17*L17,0))
A18: =IF(구매내역현황!A12="","",구매내역현황!A12) | F18: =IF(구매내역현황!A12="","",구매내역현황!B12) | J18: =IF(구매내역현황!A12="","",구매내역현황!C12) | K18: =IF(구매내역현황!A12="","",구매내역현황!N12) | L18: =IF(구매내역현황!A12="","",구매내역현황!O12) | M18: =IF(구매내역현황!A12="","",TRUNC(K18*L18,0))
A19: =IF(구매내역현황!A13="","",구매내역현황!A13) | F19: =IF(구매내역현황!A13="","",구매내역현황!B13) | J19: =IF(구매내역현황!A13="","",구매내역현황!C13) | K19: =IF(구매내역현황!A13="","",구매내역현황!N13) | L19: =IF(구매내역현황!A13="","",구매내역현황!O13) | M19: =IF(구매내역현황!A13="","",TRUNC(K19*L19,0))
A20: =IF(구매내역현황!A14="","",구매내역현황!A14) | F20: =IF(구매내역현황!A14="","",구매내역현황!B14) | J20: =IF(구매내역현황!A14="","",구매내역현황!C14) | K20: =IF(구매내역현황!A14="","",구매내역현황!N14) | L20: =IF(구매내역현황!A14="","",구매내역현황!O14) | M20: =IF(구매내역현황!A14="","",TRUNC(K20*L20,0))
A21: =IF(구매내역현황!A15="","",구매내역현황!A15) | F21: =IF(구매내역현황!A15="","",구매내역현황!B15) | J21: =IF(구매내역현황!A15="","",구매내역현황!C15) | K21: =IF(구매내역현황!A15="","",구매내역현황!N15) | L21: =IF(구매내역현황!A15="","",구매내역현황!O15) | M21: =IF(구매내역현황!A15="","",TRUNC(K21*L21,0))
A22: =IF(구매내역현황!A16="","",구매내역현황!A16) | F22: =IF(구매내역현황!A16="","",구매내역현황!B16) | J22: =IF(구매내역현황!A16="","",구매내역현황!C16) | K22: =IF(구매내역현황!A16="","",구매내역현황!N16) | L22: =IF(구매내역현황!A16="","",구매내역현황!O16) | M22: =IF(구매내역현황!A16="","",TRUNC(K22*L22,0))
A23: =IF(구매내역현황!A17="","",구매내역현황!A17) | F23: =IF(구매내역현황!A17="","",구매내역현황!B17) | J23: =IF(구매내역현황!A17="","",구매내역현황!C17) | K23: =IF(구매내역현황!A17="","",구매내역현황!N17) | L23: =IF(구매내역현황!A17="","",구매내역현황!O17) | M23: =IF(구매내역현황!A17="","",TRUNC(K23*L23,0))
A24: =IF(구매내역현황!A18="","",구매내역현황!A18) | F24: =IF(구매내역현황!A18="","",구매내역현황!B18) | J24: =IF(구매내역현황!A18="","",구매내역현황!C18) | K24: =IF(구매내역현황!A18="","",구매내역현황!N18) | L24: =IF(구매내역현황!A18="","",구매내역현황!O18) | M24: =IF(구매내역현황!A18="","",TRUNC(K24*L24,0))
A25: =IF(구매내역현황!A19="","",구매내역현황!A19) | F25: =IF(구매내역현황!A19="","",구매내역현황!B19) | J25: =IF(구매내역현황!A19="","",구매내역현황!C19) | K25: =IF(구매내역현황!A19="","",구매내역현황!N19) | L25: =IF(구매내역현황!A19="","",구매내역현황!O19) | M25: =IF(구매내역현황!A19="","",TRUNC(K25*L25,0))
A26: =IF(구매내역현황!A20="","",구매내역현황!A20) | F26: =IF(구매내역현황!A20="","",구매내역현황!B20) | J26: =IF(구매내역현황!A20="","",구매내역현황!C20) | K26: =IF(구매내역현황!A20="","",구매내역현황!N20) | L26: =IF(구매내역현황!A20="","",구매내역현황!O20) | M26: =IF(구매내역현황!A20="","",TRUNC(K26*L26,0))
A27: =IF(구매내역현황!A21="","",구매내역현황!A21) | F27: =IF(구매내역현황!A21="","",구매내역현황!B21) | J27: =IF(구매내역현황!A21="","",구매내역현황!C21) | K27: =IF(구매내역현황!A21="","",구매내역현황!N21) | L27: =IF(구매내역현황!A21="","",구매내역현황!O21) | M27: =IF(구매내역현황!A21="","",TRUNC(K27*L27,0))
... A35: =IF(구매내역현황!A29="","",구매내역현황!A29) | F35: =IF(구매내역현황!A29="","",구매내역현황!B29) | J35: =IF(구매내역현황!A29="","",구매내역현황!C29) | K35: =IF(구매내역현황!A29="","",구매내역현황!N29) | L35: =IF(구매내역현황!A29="","",구매내역현황!O29) | M35: =IF(구매내역현황!A29="","",TRUNC(K35*L35,0))

Sheet 구매내역현황
A1: 관급자재 내역현황
A3: □ 공 사 명 : 국도5호선 신림~판부1 도로건설 전기공사(3차)
A4: □ 관급자재품목
A5: 명 칭 | B5: 규 격 | C5: 단위 | E5: 설계내역 | K5: 기구매 내역 | N5: 금회 구매요청 내역 | Q5: 잔여 내역 | T5: 비 고
E6: 전체수량 | G6: 4차수량 | H6: 단 가 | I6: 전 체 | J6: 금 회 4차 | K6: 수 량 | L6: 단 가 | M6: 금 액 | N6: 수 량 | O6: 단 가 | P6: 금 액 | Q6: 수 량 | R6: 단 가 | S6: 금 액
A7: Ⅱ. 관급자재대 | I7: =I8 | J7: =J8 | M7: =M8 | P7: =P8 | S7: =S8
A8: 1. 도급자관급 | I8: =I9 | J8: =J9 | M8: =M9 | P8: =P9 | S8: =S9
I9: =SUM(I10:I29) | J9: =SUM(J10:J29) | M9: =SUM(M10:M29) | P9: =SUM(P10:P29) | S9: =SUM(S10:S29)
I10: =IF(A10="","",E10*H10) | J10: =IF(A10="","",G10*H10) | M10: =IF(A10="","",TRUNC(K10*L10)) | O10: =IF(A10="","",단가및인증현황조사!BF6) | P10: =IF(A10="","",TRUNC(N10*O10)) | Q10: =IF(A10="","",E10-K10-N10) | R10: =IF(A10="","",H10-O10) | S10: =IF(A10="","",J10-M10-P10)
I11: =IF(A11="","",E11*H11) | J11: =IF(A11="","",G11*H11) | M11: =IF(A11="","",TRUNC(K11*L11)) | O11: =IF(A11="","",단가및인증현황조사!BF7) | P11: =IF(A11="","",TRUNC(N11*O11)) | Q11: =IF(A11="","",E11-K11-N11) | R11: =IF(A11="","",H11-O11) | S11: =IF(A11="","",J11-M11-P11)
I12: =IF(A12="","",E12*H12) | J12: =IF(A12="","",G12*H12) | M12: =IF(A12="","",TRUNC(K12*L12)) | O12: =IF(A12="","",단가및인증현황조사!BF8) | P12: =IF(A12="","",TRUNC(N12*O12)) | Q12: =IF(A12="","",E12-K12-N12) | R12: =IF(A12="","",H12-O12) | S12: =IF(A12="","",J12-M12-P12)
I13: =IF(A13="","",E13*H13) | J13: =IF(A13="","",G13*H13) | M13: =IF(A13="","",TRUNC(K13*L13)) | O13: =IF(A13="","",단가및인증현황조사!BF9) | P13: =IF(A13="","",TRUNC(N13*O13)) | Q13: =IF(A13="","",E13-K13-N13) | R13: =IF(A13="","",H13-O13) | S13: =IF(A13="","",J13-M13-P13)
I14: =IF(A14="","",E14*H14) | J14: =IF(A14="","",G14*H14) | M14: =IF(A14="","",TRUNC(K14*L14)) | O14: =IF(A14="","",단가및인증현황조사!BF10) | P14: =IF(A14="","",TRUNC(N14*O14)) | Q14: =IF(A14="","",E14-K14-N14) | R14: =IF(A14="","",H14-O14) | S14: =IF(A14="","",J14-M14-P14)
I15: =IF(A15="","",E15*H15) | J15: =IF(A15="","",G15*H15) | M15: =IF(A15="","",TRUNC(K15*L15)) | O15: =IF(A15="","",단가및인증현황조사!BF11) | P15: =IF(A15="","",TRUNC(N15*O15)) | Q15: =IF(A15="","",E15-K15-N15) | R15: =IF(A15="","",H15-O15) | S15: =IF(A15="","",J15-M15-P15)
I16: =IF(A16="","",E16*H16) | J16: =IF(A16="","",G16*H16) | M16: =IF(A16="","",TRUNC(K16*L16)) | O16: =IF(A16="","",단가및인증현황조사!BF12) | P16: =IF(A16="","",TRUNC(N16*O16)) | Q16: =IF(A16="","",E16-K16-N16) | R16: =IF(A16="","",H16-O16) | S16: =IF(A16="","",J16-M16-P16)
I17: =IF(A17="","",E17*H17) | J17: =IF(A17="","",G17*H17) | M17: =IF(A17="","",TRUNC(K17*L17)) | O17: =IF(A17="","",단가및인증현황조사!BF13) | P17: =IF(A17="","",TRUNC(N17*O17)) | Q17: =IF(A17="","",E17-K17-N17) | R17: =IF(A17="","",H17-O17) | S17: =IF(A17="","",J17-M17-P17)
I18: =IF(A18="","",E18*H18) | J18: =IF(A18="","",G18*H18) | M18: =IF(A18="","",TRUNC(K18*L18)) | O18: =IF(A18="","",단가및인증현황조사!BF14) | P18: =IF(A18="","",TRUNC(N18*O18)) | Q18: =IF(A18="","",E18-K18-N18) | R18: =IF(A18="","",H18-O18) | S18: =IF(A18="","",J18-M18-P18)
I19: =IF(A19="","",E19*H19) | J19: =IF(A19="","",G19*H19) | M19: =IF(A19="","",TRUNC(K19*L19)) | O19: =IF(A19="","",단가및인증현황조사!BF15) | P19: =IF(A19="","",TRUNC(N19*O19)) | Q19: =IF(A19="","",E19-K19-N19) | R19: =IF(A19="","",H19-O19) | S19: =IF(A19="","",J19-M19-P19)
I20: =IF(A20="","",E20*H20) | J20: =IF(A20="","",G20*H20) | M20: =IF(A20="","",TRUNC(K20*L20)) | O20: =IF(A20="","",단가및인증현황조사!BF16) | P20: =IF(A20="","",TRUNC(N20*O20)) | Q20: =IF(A20="","",E20-K20-N20) | R20: =IF(A20="","",H20-O20) | S20: =IF(A20="","",J20-M20-P20)
I21: =IF(A21="","",E21*H21) | J21: =IF(A21="","",G21*H21) | M21: =IF(A21="","",TRUNC(K21*L21)) | O21: =IF(A21="","",단가및인증현황조사!BF17) | P21: =IF(A21="","",TRUNC(N21*O21)) | Q21: =IF(A21="","",E21-K21-N21) | R21: =IF(A21="","",H21-O21) | S21: =IF(A21="","",J21-M21-P21)
... I29: =IF(A29="","",E29*H29) | J29: =IF(A29="","",G29*H29) | M29: =IF(A29="","",TRUNC(K29*L29)) | O29: =IF(A29="","",단가및인증현황조사!BF25) | P29: =IF(A29="","",TRUNC(N29*O29)) | Q29: =IF(A29="","",E29-K29-N29) | R29: =IF(A29="","",H29-O29) | S29: =IF(A29="","",J29-M29-P29)

Sheet 관급단가 비교표
C1: □ 품목명 :
C3: 구분 | D3: 제 조 사 | E3: 본 사 소재지 | F3: 물품식별번호 | G3: 단위 | H3: 단 가 (부가세포함) | I3: 인 증 현 황 | P3: 외 형 도 | Q3: 비 고
C5: 1
C6: 2
C7: 3
C8: 4
C9: 5
C10: 6
C11: 7
C12: ※ 인증마크 : | P12: ◎ : 우선(의무) 구매대상
C14: □ 품목명 :
C16: 구분 | D16: 제 조 사 | E16: 본 사 소재지 | F16: 물품식별번호 | G16: 단위 | H16: 단 가 (부가세포함) | I16: 인 증 현 황 | P16: 외 형 도 | Q16: 비 고
C18: 1
C19: 2
C20: 3
C21: 4
C22: 5
C23: 6
C24: 7
C25: ※ 인증마크 : | P25: ◎ : 우선(의무) 구매대상
C27: □ 품목명 :
C29: 구분 | D29: 제 조 사 | E29: 본 사 소재지 | F29: 물품식별번호 | G29: 단위 | H29: 단 가 (부가세포함) | I29: 인 증 현 황 | P29: 외 형 도 | Q29: 비 고
C31: 1
C32: 2
C33: 3
C34: 4
C35: 5
C36: 6
C37: 7
C38: ※ 인증마크 : | P38: ◎ : 우선(의무) 구매대상
C40: □ 품목명 :
C42: 구분 | D42: 제 조 사 | E42: 본 사 소재지 | F42: 물품식별번호 | G42: 단위 | H42: 단 가 (부가세포함) | I42: 인 증 현 황 | P42: 외 형 도 | Q42: 비 고
C44: 1
C45: 2
C46: 3
C47: 4
C48: 5
C49: 6
C50: 7
C51: ※ 인증마크 : | P51: ◎ : 우선(의무) 구매대상
...

Sheet 단가및인증현황조사
A1: 관급자재 조달단가 및 인증현황 조사표
BD2: ◎ : 우선(의무) 구매대상
A3: 품 명 | B3: 규 격 | C3: 단 위 | D3: 수 량 | H3: ='관급단가 비교표'!D5 | S3: ='관급단가 비교표'!D6 | AB3: ='관급단가 비교표'!D7 | BF3: 평균단가
D4: 치악재 | G4: 계 | H4: 물품번호 | I4: 단 가 | J4: 금 액 | K4: 품질 보증 조달 물품 | L4: KS | M4: 성능 인증 제품 | N4: 여성 기업 | O4: 소상 공인 | P4: 우수조달물품 | Q4: G-P ASS 기업 | R4: 물품번호 | S4: 단 가 | T4: 금 액 | U4: 품질 보증 조달 물품 | V4: KS | W4: 성능 인증 제품 | X4: 여성 기업 | Y4: 소상 공인 | Z4: G-P ASS 기업 | AA4: 장애 인기 업제 품 | AB4: 물품번호 | AC4: 단 가 | AD4: 금 액 | AE4: 품질 보증 조달 물품 | AF4: KS | AG4: 성능 인증 제품 | AH4: 여성 기업 | AI4: 소상 공인 | AJ4: G-P ASS 기업 | AK4: 장애 인기 업제 품 | AL4: 물품번호 | AM4: 단 가 | AN4: 금 액 | AO4: 품질 보증 조달 물품 | AP4: KS | AQ4: 성능 인증 제품 | AR4: 여성 기업 | AS4: 소상 공인 | AT4: G-P ASS 기업 | AU4: 장애 인기 업제 품 | AV4: 물품번호 | AW4: 단 가 | AX4: 금 액 | AY4: 품질 보증 조달 물품 | AZ4: KS | BA4: 성능 인증 제품 | BB4: 여성 기업 | BC4: 소상 공인 | BD4: G-P ASS 기업 | BE4: 장애 인기 업제 품 | BF4: (최저단가 제외)
A5: 인 증 마 크
D6: =IF(A6="","",구매내역현황!N10) | G6: =IF(A6="","",D6) | H6: =IF('관급단가 비교표'!F5="","",'관급단가 비교표'!F5) | I6: =IF('관급단가 비교표'!H5="","",'관급단가 비교표'!H5) | J6: =IF(OR(A6="",I6=""),"",TRUNC($G6*I6)) | R6: =IF('관급단가 비교표'!F6="","",'관급단가 비교표'!F6) | S6: =IF('관급단가 비교표'!H6="","",'관급단가 비교표'!H6) | T6: =IF(OR(A6="",S6=""),"",TRUNC($G6*S6)) | AB6: =IF('관급단가 비교표'!F7="","",'관급단가 비교표'!F7) | AC6: =IF('관급단가 비교표'!H7="","",'관급단가 비교표'!H7) | AD6: =IF(OR(A6="",AC6=""),"",TRUNC($G6*AC6)) | BF6: =IF(A6="","",TRUNC(AVERAGE(S6,AC6),0))
D7: =IF(A7="","",구매내역현황!N11) | G7: =IF(A7="","",D7) | H7: =IF('관급단가 비교표'!F18="","",'관급단가 비교표'!F18) | I7: =IF('관급단가 비교표'!H18="","",'관급단가 비교표'!H18) | J7: =IF(OR(A7="",I7=""),"",TRUNC($G7*I7)) | R7: =IF('관급단가 비교표'!F19="","",'관급단가 비교표'!F19) | S7: =IF('관급단가 비교표'!H19="","",'관급단가 비교표'!H19) | T7: =IF(OR(A7="",S7=""),"",TRUNC($G7*S7)) | AB7: =IF('관급단가 비교표'!F20="","",'관급단가 비교표'!F20) | AC7: =IF('관급단가 비교표'!H20="","",'관급단가 비교표'!H20) | AD7: =IF(OR(A7="",AC7=""),"",TRUNC($G7*AC7)) | BF7: =IF(A7="","",TRUNC(AVERAGE(S7,AC7),0))
D8: =IF(A8="","",구매내역현황!N12) | G8: =IF(A8="","",D8) | H8: =IF('관급단가 비교표'!F31="","",'관급단가 비교표'!F31) | I8: =IF('관급단가 비교표'!H31="","",'관급단가 비교표'!H31) | J8: =IF(OR(A8="",I8=""),"",TRUNC($G8*I8)) | R8: =IF('관급단가 비교표'!F32="","",'관급단가 비교표'!F32) | S8: =IF('관급단가 비교표'!H32="","",'관급단가 비교표'!H32) | T8: =IF(OR(A8="",S8=""),"",TRUNC($G8*S8)) | AB8: =IF('관급단가 비교표'!F33="","",'관급단가 비교표'!F33) | AC8: =IF('관급단가 비교표'!H33="","",'관급단가 비교표'!H33) | AD8: =IF(OR(A8="",AC8=""),"",TRUNC($G8*AC8)) | BF8: =IF(A8="","",TRUNC(AVERAGE(S8,AC8),0))
D9: =IF(A9="","",구매내역현황!N13) | G9: =IF(A9="","",D9) | H9: =IF('관급단가 비교표'!F44="","",'관급단가 비교표'!F44) | I9: =IF('관급단가 비교표'!H44="","",'관급단가 비교표'!H44) | J9: =IF(OR(A9="",I9=""),"",TRUNC($G9*I9)) | R9: =IF('관급단가 비교표'!F45="","",'관급단가 비교표'!F45) | S9: =IF('관급단가 비교표'!H45="","",'관급단가 비교표'!H45) | T9: =IF(OR(A9="",S9=""),"",TRUNC($G9*S9)) | AB9: =IF('관급단가 비교표'!F46="","",'관급단가 비교표'!F46) | AC9: =IF('관급단가 비교표'!H46="","",'관급단가 비교표'!H46) | AD9: =IF(OR(A9="",AC9=""),"",TRUNC($G9*AC9)) | BF9: =IF(A9="","",TRUNC(AVERAGE(S9,AC9),0))
D10: =IF(A10="","",구매내역현황!N14) | G10: =IF(A10="","",D10) | H10: =IF('관급단가 비교표'!F57="","",'관급단가 비교표'!F57) | I10: =IF('관급단가 비교표'!H57="","",'관급단가 비교표'!H57) | J10: =IF(OR(A10="",I10=""),"",TRUNC($G10*I10)) | R10: =IF('관급단가 비교표'!F58="","",'관급단가 비교표'!F58) | S10: =IF('관급단가 비교표'!H58="","",'관급단가 비교표'!H58) | T10: =IF(OR(A10="",S10=""),"",TRUNC($G10*S10)) | AB10: =IF('관급단가 비교표'!F59="","",'관급단가 비교표'!F59) | AC10: =IF('관급단가 비교표'!H59="","",'관급단가 비교표'!H59) | AD10: =IF(OR(A10="",AC10=""),"",TRUNC($G10*AC10)) | BF10: =IF(A10="","",TRUNC(AVERAGE(S10,AC10),0))
D11: =IF(A11="","",구매내역현황!N15) | G11: =IF(A11="","",D11) | H11: =IF('관급단가 비교표'!F70="","",'관급단가 비교표'!F70) | I11: =IF('관급단가 비교표'!H70="","",'관급단가 비교표'!H70) | J11: =IF(OR(A11="",I11=""),"",TRUNC($G11*I11)) | R11: =IF('관급단가 비교표'!F71="","",'관급단가 비교표'!F71) | S11: =IF('관급단가 비교표'!H71="","",'관급단가 비교표'!H71) | T11: =IF(OR(A11="",S11=""),"",TRUNC($G11*S11)) | AB11: =IF('관급단가 비교표'!F72="","",'관급단가 비교표'!F72) | AC11: =IF('관급단가 비교표'!H72="","",'관급단가 비교표'!H72) | AD11: =IF(OR(A11="",AC11=""),"",TRUNC($G11*AC11)) | BF11: =IF(A11="","",TRUNC(AVERAGE(S11,AC11),0))
D12: =IF(A12="","",구매내역현황!N16) | G12: =IF(A12="","",D12) | H12: =IF('관급단가 비교표'!F83="","",'관급단가 비교표'!F83) | I12: =IF('관급단가 비교표'!H83="","",'관급단가 비교표'!H83) | J12: =IF(OR(A12="",I12=""),"",TRUNC($G12*I12)) | R12: =IF('관급단가 비교표'!F84="","",'관급단가 비교표'!F84) | S12: =IF('관급단가 비교표'!H84="","",'관급단가 비교표'!H84) | T12: =IF(OR(A12="",S12=""),"",TRUNC($G12*S12)) | AB12: =IF('관급단가 비교표'!F85="","",'관급단가 비교표'!F85) | AC12: =IF('관급단가 비교표'!H85="","",'관급단가 비교표'!H85) | AD12: =IF(OR(A12="",AC12=""),"",TRUNC($G12*AC12)) | BF12: =IF(A12="","",TRUNC(AVERAGE(S12,AC12),0))
D13: =IF(A13="","",구매내역현황!N17) | G13: =IF(A13="","",D13) | H13: =IF('관급단가 비교표'!F96="","",'관급단가 비교표'!F96) | I13: =IF('관급단가 비교표'!H96="","",'관급단가 비교표'!H96) | J13: =IF(OR(A13="",I13=""),"",TRUNC($G13*I13)) | R13: =IF('관급단가 비교표'!F97="","",'관급단가 비교표'!F97) | S13: =IF('관급단가 비교표'!H97="","",'관급단가 비교표'!H97) | T13: =IF(OR(A13="",S13=""),"",TRUNC($G13*S13)) | AB13: =IF('관급단가 비교표'!F98="","",'관급단가 비교표'!F98) | AC13: =IF('관급단가 비교표'!H98="","",'관급단가 비교표'!H98) | AD13: =IF(OR(A13="",AC13=""),"",TRUNC($G13*AC13)) | BF13: =IF(A13="","",TRUNC(AVERAGE(S13,AC13),0))
D14: =IF(A14="","",구매내역현황!N18) | G14: =IF(A14="","",D14) | H14: =IF('관급단가 비교표'!F109="","",'관급단가 비교표'!F109) | I14: =IF('관급단가 비교표'!H109="","",'관급단가 비교표'!H109) | J14: =IF(OR(A14="",I14=""),"",TRUNC($G14*I14)) | R14: =IF('관급단가 비교표'!F110="","",'관급단가 비교표'!F110) | S14: =IF('관급단가 비교표'!H110="","",'관급단가 비교표'!H110) | T14: =IF(OR(A14="",S14=""),"",TRUNC($G14*S14)) | AB14: =IF('관급단가 비교표'!F111="","",'관급단가 비교표'!F111) | AC14: =IF('관급단가 비교표'!H111="","",'관급단가 비교표'!H111) | AD14: =IF(OR(A14="",AC14=""),"",TRUNC($G14*AC14)) | BF14: =IF(A14="","",TRUNC(AVERAGE(S14,AC14),0))
D15: =IF(A15="","",구매내역현황!N19) | G15: =IF(A15="","",D15) | H15: =IF('관급단가 비교표'!F122="","",'관급단가 비교표'!F122) | I15: =IF('관급단가 비교표'!H122="","",'관급단가 비교표'!H122) | J15: =IF(OR(A15="",I15=""),"",TRUNC($G15*I15)) | R15: =IF('관급단가 비교표'!F123="","",'관급단가 비교표'!F123) | S15: =IF('관급단가 비교표'!H123="","",'관급단가 비교표'!H123) | T15: =IF(OR(A15="",S15=""),"",TRUNC($G15*S15)) | AB15: =IF('관급단가 비교표'!F124="","",'관급단가 비교표'!F124) | AC15: =IF('관급단가 비교표'!H124="","",'관급단가 비교표'!H124) | AD15: =IF(OR(A15="",AC15=""),"",TRUNC($G15*AC15)) | BF15: =IF(A15="","",TRUNC(AVERAGE(S15,AC15),0))
D16: =IF(A16="","",구매내역현황!N20) | G16: =IF(A16="","",D16) | H16: =IF('관급단가 비교표'!F135="","",'관급단가 비교표'!F135) | I16: =IF('관급단가 비교표'!H135="","",'관급단가 비교표'!H135) | J16: =IF(OR(A16="",I16=""),"",TRUNC($G16*I16)) | R16: =IF('관급단가 비교표'!F136="","",'관급단가 비교표'!F136) | S16: =IF('관급단가 비교표'!H136="","",'관급단가 비교표'!H136) | T16: =IF(OR(A16="",S16=""),"",TRUNC($G16*S16)) | AB16: =IF('관급단가 비교표'!F137="","",'관급단가 비교표'!F137) | AC16: =IF('관급단가 비교표'!H137="","",'관급단가 비교표'!H137) | AD16: =IF(OR(A16="",AC16=""),"",TRUNC($G16*AC16)) | BF16: =IF(A16="","",TRUNC(AVERAGE(S16,AC16),0))
D17: =IF(A17="","",구매내역현황!N21) | G17: =IF(A17="","",D17) | H17: =IF('관급단가 비교표'!F148="","",'관급단가 비교표'!F148) | I17: =IF('관급단가 비교표'!H148="","",'관급단가 비교표'!H148) | J17: =IF(OR(A17="",I17=""),"",TRUNC($G17*I17)) | R17: =IF('관급단가 비교표'!F149="","",'관급단가 비교표'!F149) | S17: =IF('관급단가 비교표'!H149="","",'관급단가 비교표'!H149) | T17: =IF(OR(A17="",S17=""),"",TRUNC($G17*S17)) | AB17: =IF('관급단가 비교표'!F150="","",'관급단가 비교표'!F150) | AC17: =IF('관급단가 비교표'!H150="","",'관급단가 비교표'!H150) | AD17: =IF(OR(A17="",AC17=""),"",TRUNC($G17*AC17)) | BF17: =IF(A17="","",TRUNC(AVERAGE(S17,AC17),0))
D18: =IF(A18="","",구매내역현황!N22) | G18: =IF(A18="","",D18) | H18: =IF('관급단가 비교표'!F161="","",'관급단가 비교표'!F161) | I18: =IF('관급단가 비교표'!H161="","",'관급단가 비교표'!H161) | J18: =IF(OR(A18="",I18=""),"",TRUNC($G18*I18)) | R18: =IF('관급단가 비교표'!F162="","",'관급단가 비교표'!F162) | S18: =IF('관급단가 비교표'!H162="","",'관급단가 비교표'!H162) | T18: =IF(OR(A18="",S18=""),"",TRUNC($G18*S18)) | AB18: =IF('관급단가 비교표'!F163="","",'관급단가 비교표'!F163) | AC18: =IF('관급단가 비교표'!H163="","",'관급단가 비교표'!H163) | AD18: =IF(OR(A18="",AC18=""),"",TRUNC($G18*AC18)) | BF18: =IF(A18="","",TRUNC(AVERAGE(S18,AC18),0))
D19: =IF(A19="","",구매내역현황!N23) | G19: =IF(A19="","",D19) | H19: =IF('관급단가 비교표'!F174="","",'관급단가 비교표'!F174) | I19: =IF('관급단가 비교표'!H174="","",'관급단가 비교표'!H174) | J19: =IF(OR(A19="",I19=""),"",TRUNC($G19*I19)) | R19: =IF('관급단가 비교표'!F175="","",'관급단가 비교표'!F175) | S19: =IF('관급단가 비교표'!H175="","",'관급단가 비교표'!H175) | T19: =IF(OR(A19="",S19=""),"",TRUNC($G19*S19)) | AB19: =IF('관급단가 비교표'!F176="","",'관급단가 비교표'!F176) | AC19: =IF('관급단가 비교표'!H176="","",'관급단가 비교표'!H176) | AD19: =IF(OR(A19="",AC19=""),"",TRUNC($G19*AC19)) | BF19: =IF(A19="","",TRUNC(AVERAGE(S19,AC19),0))
D20: =IF(A20="","",구매내역현황!N24) | G20: =IF(A20="","",D20) | H20: =IF('관급단가 비교표'!F187="","",'관급단가 비교표'!F187) | I20: =IF('관급단가 비교표'!H187="","",'관급단가 비교표'!H187) | J20: =IF(OR(A20="",I20=""),"",TRUNC($G20*I20)) | R20: =IF('관급단가 비교표'!F188="","",'관급단가 비교표'!F188) | S20: =IF('관급단가 비교표'!H188="","",'관급단가 비교표'!H188) | T20: =IF(OR(A20="",S20=""),"",TRUNC($G20*S20)) | AB20: =IF('관급단가 비교표'!F189="","",'관급단가 비교표'!F189) | AC20: =IF('관급단가 비교표'!H189="","",'관급단가 비교표'!H189) | AD20: =IF(OR(A20="",AC20=""),"",TRUNC($G20*AC20)) | BF20: =IF(A20="","",TRUNC(AVERAGE(S20,AC20),0))
D21: =IF(A21="","",구매내역현황!N25) | G21: =IF(A21="","",D21) | H21: =IF('관급단가 비교표'!F200="","",'관급단가 비교표'!F200) | I21: =IF('관급단가 비교표'!H200="","",'관급단가 비교표'!H200) | J21: =IF(OR(A21="",I21=""),"",TRUNC($G21*I21)) | R21: =IF('관급단가 비교표'!F201="","",'관급단가 비교표'!F201) | S21: =IF('관급단가 비교표'!H201="","",'관급단가 비교표'!H201) | T21: =IF(OR(A21="",S21=""),"",TRUNC($G21*S21)) | AB21: =IF('관급단가 비교표'!F202="","",'관급단가 비교표'!F202) | AC21: =IF('관급단가 비교표'!H202="","",'관급단가 비교표'!H202) | AD21: =IF(OR(A21="",AC21=""),"",TRUNC($G21*AC21)) | BF21: =IF(A21="","",TRUNC(AVERAGE(S21,AC21),0))
D22: =IF(A22="","",구매내역현황!N26) | G22: =IF(A22="","",D22) | H22: =IF('관급단가 비교표'!F213="","",'관급단가 비교표'!F213) | I22: =IF('관급단가 비교표'!H213="","",'관급단가 비교표'!H213) | J22: =IF(OR(A22="",I22=""),"",TRUNC($G22*I22)) | R22: =IF('관급단가 비교표'!F214="","",'관급단가 비교표'!F214) | S22: =IF('관급단가 비교표'!H214="","",'관급단가 비교표'!H214) | T22: =IF(OR(A22="",S22=""),"",TRUNC($G22*S22)) | AB22: =IF('관급단가 비교표'!F215="","",'관급단가 비교표'!F215) | AC22: =IF('관급단가 비교표'!H215="","",'관급단가 비교표'!H215) | AD22: =IF(OR(A22="",AC22=""),"",TRUNC($G22*AC22)) | BF22: =IF(A22="","",TRUNC(AVERAGE(S22,AC22),0))
D23: =IF(A23="","",구매내역현황!N27) | G23: =IF(A23="","",D23) | H23: =IF('관급단가 비교표'!F226="","",'관급단가 비교표'!F226) | I23: =IF('관급단가 비교표'!H226="","",'관급단가 비교표'!H226) | J23: =IF(OR(A23="",I23=""),"",TRUNC($G23*I23)) | R23: =IF('관급단가 비교표'!F227="","",'관급단가 비교표'!F227) | S23: =IF('관급단가 비교표'!H227="","",'관급단가 비교표'!H227) | T23: =IF(OR(A23="",S23=""),"",TRUNC($G23*S23)) | AB23: =IF('관급단가 비교표'!F228="","",'관급단가 비교표'!F228) | AC23: =IF('관급단가 비교표'!H228="","",'관급단가 비교표'!H228) | AD23: =IF(OR(A23="",AC23=""),"",TRUNC($G23*AC23)) | BF23: =IF(A23="","",TRUNC(AVERAGE(S23,AC23),0))
D24: =IF(A24="","",구매내역현황!N28) | G24: =IF(A24="","",D24) | H24: =IF('관급단가 비교표'!F239="","",'관급단가 비교표'!F239) | I24: =IF('관급단가 비교표'!H239="","",'관급단가 비교표'!H239) | J24: =IF(OR(A24="",I24=""),"",TRUNC($G24*I24)) | R24: =IF('관급단가 비교표'!F240="","",'관급단가 비교표'!F240) | S24: =IF('관급단가 비교표'!H240="","",'관급단가 비교표'!H240) | T24: =IF(OR(A24="",S24=""),"",TRUNC($G24*S24)) | AB24: =IF('관급단가 비교표'!F241="","",'관급단가 비교표'!F241) | AC24: =IF('관급단가 비교표'!H241="","",'관급단가 비교표'!H241) | AD24: =IF(OR(A24="",AC24=""),"",TRUNC($G24*AC24)) | BF24: =IF(A24="","",TRUNC(AVERAGE(S24,AC24),0))
D25: =IF(A25="","",구매내역현황!N29) | G25: =IF(A25="","",D25) | H25: =IF('관급단가 비교표'!F252="","",'관급단가 비교표'!F252) | I25: =IF('관급단가 비교표'!H252="","",'관급단가 비교표'!H252) | J25: =IF(OR(A25="",I25=""),"",TRUNC($G25*I25)) | R25: =IF('관급단가 비교표'!F253="","",'관급단가 비교표'!F253) | S25: =IF('관급단가 비교표'!H253="","",'관급단가 비교표'!H253) | T25: =IF(OR(A25="",S25=""),"",TRUNC($G25*S25)) | AB25: =IF('관급단가 비교표'!F254="","",'관급단가 비교표'!F254) | AC25: =IF('관급단가 비교표'!H254="","",'관급단가 비교표'!H254) | AD25: =IF(OR(A25="",AC25=""),"",TRUNC($G25*AC25)) | BF25: =IF(A25="","",TRUNC(AVERAGE(S25,AC25),0))
A26: 합 계 | J26: =SUM(J6:J25) | K26: =COUNTA(K6:Q25) | T26: =SUM(T6:T25) | V26: =COUNTA(U6:AA25) | AD26: =SUM(AD6:AD25) | AE26: =COUNTA(AE6:AK25)
