Workbook
Name __JJ132: #REF!
Name __JK132: #REF!
Name __JN132: #REF!
Name __p1: #REF!
Name _95년_포상금_지급내역: #REF!
Name _JJ132: #REF!
Name _JK132: #REF!
Name _JN132: #REF!
Name _p1: #REF!
Name a: #REF!
Name alf: #REF!
Name b: #REF!
Name BOX형수로집계: #REF!
Name CV_1C: #REF!
Name CV_1C: #REF!
Name d: #REF!
Name N: #REF!
Name P: #REF!
Name Print_Area_MI: #REF!
Name Q: #REF!
Name SIZE: #REF!
Name SIZE: #REF!
Name 강감찬: #REF!
Name 경계점말뚝: #REF!
Name 계약단가: #REF!
Name 고급: #REF!
Name 공공시설: #REF!
Name 공사비: #REF!
Name 공업용뇌관2: #REF!
Name 교육: #REF!
Name 교통: #REF!
Name 기간: #REF!
Name 김유신: #REF!
Name 노임: #REF!
Name 노임: #REF!
Name 다이너마이트2: #REF!
Name 단가: #REF!
Name 단가: #REF!
Name 단순공종: #REF!
Name 대기질: #REF!
Name 대기질측정: #REF!
Name 대안설정: #REF!
Name 동식물상: #REF!
Name ㅁ1: #REF!
Name 명수: #REF!
Name 문화재: #REF!
Name 백색페인트: #REF!
Name 보정계수1: #REF!
Name 보정계수2: #REF!
Name 보정계수3: #REF!
Name 보조: #REF!
Name 보통공종: #REF!
Name 보통인부: #REF!
Name 복잡공종: #REF!
Name 비닐전화선: #REF!
Name 뿌로마이드: #REF!
Name 사정: #REF!
Name 사후환경조사: #REF!
Name 산업: #REF!
Name 선택: #REF!

Sheet 원가
A1: 원 가 계 산 서
A3: 공사명: | C3: 강릉시 입암동 통합공공임대주택 건립사업 신축공사(전기)
A4: 비 목 | C4: 구 분 | D4: 금 액 | E4: 구 성 비 | I4: 요율 | J4: 수량 | K4: 금액 | L4: 이윤 | M4: 끝자리 맞추기
B5: 재 료 비 | C5: 직 접 재 료 비 | D5: =옵션!$B$2 -> 344292005 | J5: 1 | K5: =D5*J5 -> 344292005
C6: 간 접 재 료 비 | K6: =D6*J6 -> 0
C7: ( 소 계 ) | D7: =SUM(D5:D6) -> 344292005 | K7: =D7*J7 -> 0
A8: 순 | B8: 노 무 비 | C8: 직 접 노 무 비 | D8: =옵션!$C$2 -> 897549290 | J8: 1 | K8: =D8*J8 -> 897549290
C9: 간 접 노 무 비 | D9: =TRUNC(D8*I9/100) -> 135529942 | E9: (직접 노무비) * 15.1 % | I9: 15.1 | J9: 1 | K9: =D9*J9 -> 135529942
C10: ( 소 계 ) | D10: =SUM(D8:D9) -> 1033079232 | K10: =D10*J10 -> 0
C11: 기 계 경 비 | D11: =옵션!$D$2 -> 542331 | J11: 1 | K11: =D11*J11 -> 542331
C12: 산 재 보 험 료 | D12: =TRUNC(D10*I12/100) -> 36777620 | E12: (노무비) * 3.56 % | I12: 3.56 | J12: 1 | K12: =D12*J12 -> 36777620
A13: 공 | C13: 고 용 보 험 료 | D13: =TRUNC(D10*I13/100) -> 10434100 | E13: (노무비) * 1.01 % | I13: 1.01 | J13: 1 | K13: =D13*J13 -> 10434100
B14: 경 | C14: 퇴 직 금 공 제 | D14: =TRUNC(D8*I14/100) -> 20643633 | E14: (직접 노무비) * 2.3 % | I14: 2.3 | J14: 1 | K14: =D14*J14 -> 20643633
C15: 안 전 관 리 비 | D15: =TRUNC((4325000+(D7+D8+D32/1.1))*I15/100) -> 32595894 | E15: (재료+직노) * 2.28 % | I15: 2.28 | J15: 1 | K15: =D15*J15 -> 32595894
C16: 기 타 경 비 | D16: =TRUNC((D7+D10)*I16/100) -> 70245933 | E16: (재료+노무) * 5.1 % | I16: 5.1 | J16: 1 | K16: =D16*J16 -> 70245933
C17: 건 강 보 험 료 | D17: =TRUNC(D8*I17/100) -> 32266896 | E17: (직접 노무비) * 3.595 % | I17: 3.595 | J17: 1 | K17: =D17*J17 -> 32266896
A18: 사 | C18: 연 금 보 험 료 | D18: =TRUNC(D8*I18/100) -> 42633591 | E18: (직접 노무비) * 4.75 % | I18: 4.75 | J18: 1 | K18: =D18*J18 -> 42633591
C19: 노인장기요양보험 | D19: =TRUNC(D17*I19/100) -> 4239870 | E19: (건강 보험료) * 13.14 % | I19: 13.14 | J19: 1 | K19: =D19*J19 -> 4239870
K20: =D20*J20 -> 0
K21: =D21*J21 -> 0
B22: 비 | K22: =D22*J22 -> 0
A23: 비 | K23: =D23*J23 -> 0
K24: =D24*J24 -> 0
C25: ( 소 계 ) | D25: =SUM(D11:D24) -> 250379868 | K25: =D25*J25 -> 0
B26: ( 순 공 사 비 계 ) | D26: =D7+D10+D25 -> 1627751105 | K26: =D26*J26 -> 0
A27: 일 반 관 리 비 | D27: =TRUNC((D7+D10+D25)*I27/100) -> 105803821 | E27: (재료+노무+경비) * 6.5 % | I27: 6.5 | J27: 1 | K27: =D27*J27 -> 105803821
A28: 이 윤 | D28: =TRUNC(((D10+D25+D27))*I28/100)-752 -> 208388686 | E28: (노무+경비+일반관리비) * 15 % | I28: 15 | J28: 1 | K28: =D28*J28 -> 208388686
A29: ( 총 원 가 ) | D29: =SUM(K5:K28) -> 1941943612 | K29: =D29*J29 -> 0
A30: 부 가 가 치 세 | D30: =TRUNC(D7*10%) -> 34429200 | E30: 재료비의10% | I30: 10 | J30: 1 | K30: =D30*J30 -> 34429200
D31: 0 | I31: 10 | J31: 1 | K31: =D31*J31 -> 0
A32: 도 급 자 관 급 | D32: =옵션!$F$3+999 -> 201826000 | J32: 1 | K32: =D32*J32 -> 201826000
A33: 관 급 자 관 급 | D33: =옵션!$F$4+787 -> 427708000 | J33: 1 | K33: =D33*J33 -> 427708000
A34: 한 전 불 입 금 | D34: =한전불입금및사용전검사비!J84 -> 14670000 | J34: 1 | K34: =D34*J34 -> 14670000
J35: 1 | K35: =D35*J35 -> 0
A36: ( 총 계 ) | D36: =K36 -> 2620576812 | K36: =SUM(K5:K35) -> 2620576812

Sheet 총괄표
A1: 총줄수-> | B1: 237 | D1: [ 강릉시 입암동 통합공공임대주택 건립사업 신축공사 ] | AA1: 연속견적가로형식
A2: 번호 | B2: 공종코드 | C2: … | D2: 공 종 명 | E2: 규격 | F2: 단위 | G2: 수량 | H2: 재료비 | J2: 노무비 | M2: 경비 | P2: 계 | Q2: 비고
H3: 단가 | I3: 금액 | J3: 수량 | K3: 단가 | L3: 금액 | M3: 단가 | N3: 금액 | O3: 단가
B4: 공종줄 | D4: 강릉시 입암동 통합공공임대주택 건립사업 신
B5: 01 | D5: 1.전기공사 | F5: 식 | G5: 1 | H5: =총괄표!I81 -> 344292005 | I5: =G5*H5 -> 344292005 | K5: =총괄표!L81 -> 897549290 | L5: =G5*K5 -> 897549290 | M5: =총괄표!N81 -> 542331 | N5: =G5*M5 -> 542331 | O5: =IF((H5+K5+M5)=0, "", (H5+K5+M5)) -> 1242383626 | P5: =SUM(I5,L5,N5) -> 1242383626
C29: Total | D29: ( 합 계 ) | I29: =TRUNC(SUM(I4:I28)) -> 344292005 | L29: =TRUNC(SUM(L4:L28)) -> 897549290 | N29: =TRUNC(SUM(N4:N28)) -> 542331 | O29: =IF((H29+K29+M29)=0, "", (H29+K29+M29)) | P29: =TRUNC(SUM(P4:P28)) -> 1242383626
B30: 공종줄 | D30: 강릉시 입암동 통합공공임대주택 건립사업 신
B31: 02 | D31: 2.도급자관급 | F31: 식 | G31: 1 | H31: =총괄표!I211 -> 201825001 | I31: =G31*H31 -> 201825001 | K31: =총괄표!L211 -> 0 | L31: =G31*K31 -> 0 | M31: =총괄표!N211 -> 0 | N31: =G31*M31 -> 0 | O31: =IF((H31+K31+M31)=0, "", (H31+K31+M31)) -> 201825001 | P31: =SUM(I31,L31,N31) -> 201825001
B32: 03 | D32: 3.관급자관급 | F32: 식 | G32: 1 | H32: =총괄표!I237 -> 424636881 | I32: =G32*H32 -> 424636881 | K32: =총괄표!L237 -> 0 | L32: =G32*K32 -> 0 | M32: =총괄표!N237 -> 3070332 | N32: =G32*M32 -> 3070332 | O32: =IF((H32+K32+M32)=0, "", (H32+K32+M32)) -> 427707213 | P32: =SUM(I32,L32,N32) -> 427707213
C55: Total | D55: ( 합 계 ) | I55: =TRUNC(SUM(I30:I54)) -> 626461882 | L55: =TRUNC(SUM(L30:L54)) -> 0 | N55: =TRUNC(SUM(N30:N54)) -> 3070332 | O55: =IF((H55+K55+M55)=0, "", (H55+K55+M55)) | P55: =TRUNC(SUM(P30:P54)) -> 629532214
B56: 공종줄 | D56: 1.전기공사
B57: 0101 | D57: 1-1.공동주택 | F57: 식 | G57: 1 | H57: =총괄표!I107 -> 189884042 | I57: =G57*H57 -> 189884042 | K57: =총괄표!L107 -> 644295815 | L57: =G57*K57 -> 644295815 | M57: =총괄표!N107 -> 2508 | N57: =G57*M57 -> 2508 | O57: =IF((H57+K57+M57)=0, "", (H57+K57+M57)) -> 834182365 | P57: =SUM(I57,L57,N57) -> 834182365
B58: 0102 | D58: 1-2.부대시설 | F58: 식 | G58: 1 | H58: =총괄표!I159 -> 17288143 | I58: =G58*H58 -> 17288143 | K58: =총괄표!L159 -> 44218688 | L58: =G58*K58 -> 44218688 | M58: =총괄표!N159 -> 0 | N58: =G58*M58 -> 0 | O58: =IF((H58+K58+M58)=0, "", (H58+K58+M58)) -> 61506831 | P58: =SUM(I58,L58,N58) -> 61506831
B59: 0103 | D59: 1-3.지하주차장 | F59: 식 | G59: 1 | H59: =총괄표!I185 -> 137119820 | I59: =G59*H59 -> 137119820 | K59: =총괄표!L185 -> 209034787 | L59: =G59*K59 -> 209034787 | M59: =총괄표!N185 -> 539823 | N59: =G59*M59 -> 539823 | O59: =IF((H59+K59+M59)=0, "", (H59+K59+M59)) -> 346694430 | P59: =SUM(I59,L59,N59) -> 346694430
B81: 01 | C81: Total | D81: ( 합 계 ) | I81: =TRUNC(SUM(I56:I80)) -> 344292005 | L81: =TRUNC(SUM(L56:L80)) -> 897549290 | N81: =TRUNC(SUM(N56:N80)) -> 542331 | O81: =IF((H81+K81+M81)=0, "", (H81+K81+M81)) | P81: =TRUNC(SUM(P56:P80)) -> 1242383626
B82: 공종줄 | D82: 1.전기공사::1-1.공동주택
B83: 010101 | D83: 1-1-1.전기단위세대공사 | F83: 식 | G83: 1 | H83: =총괄표!I133 -> 70170959 | I83: =G83*H83 -> 70170959 | K83: =총괄표!L133 -> 445848834 | L83: =G83*K83 -> 445848834 | M83: =총괄표!N133 -> 0 | N83: =G83*M83 -> 0 | O83: =IF((H83+K83+M83)=0, "", (H83+K83+M83)) -> 516019793 | P83: =SUM(I83,L83,N83) -> 516019793
B84: 010102 | D84: 1-1-2.전력간선설비공사 | F84: 식 | G84: 1 | H84: =내역서!I289 -> 51374819 | I84: =G84*H84 -> 51374819 | K84: =내역서!L289 -> 87042155 | L84: =G84*K84 -> 87042155 | M84: =내역서!N289 -> 0 | N84: =G84*M84 -> 0 | O84: =IF((H84+K84+M84)=0, "", (H84+K84+M84)) -> 138416974 | P84: =SUM(I84,L84,N84) -> 138416974
B85: 010103 | D85: 1-1-3.동력설비공사 | F85: 식 | G85: 1 | H85: =내역서!I315 -> 412004 | I85: =G85*H85 -> 412004 | K85: =내역서!L315 -> 1359615 | L85: =G85*K85 -> 1359615 | M85: =내역서!N315 -> 0 | N85: =G85*M85 -> 0 | O85: =IF((H85+K85+M85)=0, "", (H85+K85+M85)) -> 1771619 | P85: =SUM(I85,L85,N85) -> 1771619
B86: 010104 | D86: 1-1-4.전등설비공사 | F86: 식 | G86: 1 | H86: =내역서!I341 -> 3339695 | I86: =G86*H86 -> 3339695 | K86: =내역서!L341 -> 29974439 | L86: =G86*K86 -> 29974439 | M86: =내역서!N341 -> 0 | N86: =G86*M86 -> 0 | O86: =IF((H86+K86+M86)=0, "", (H86+K86+M86)) -> 33314134 | P86: =SUM(I86,L86,N86) -> 33314134
B87: 010105 | D87: 1-1-5.전열설비공사 | F87: 식 | G87: 1 | H87: =내역서!I367 -> 1815363 | I87: =G87*H87 -> 1815363 | K87: =내역서!L367 -> 8043692 | L87: =G87*K87 -> 8043692 | M87: =내역서!N367 -> 0 | N87: =G87*M87 -> 0 | O87: =IF((H87+K87+M87)=0, "", (H87+K87+M87)) -> 9859055 | P87: =SUM(I87,L87,N87) -> 9859055
B88: 010106 | D88: 1-1-6.피뢰설비공사 | F88: 식 | G88: 1 | H88: =내역서!I393 -> 8415881 | I88: =G88*H88 -> 8415881 | K88: =내역서!L393 -> 11631411 | L88: =G88*K88 -> 11631411 | M88: =내역서!N393 -> 2508 | N88: =G88*M88 -> 2508 | O88: =IF((H88+K88+M88)=0, "", (H88+K88+M88)) -> 20049800 | P88: =SUM(I88,L88,N88) -> 20049800
B89: 010107 | D89: 1-1-7.태양광설비공사 | F89: 식 | G89: 1 | H89: =내역서!I419 -> 4736754 | I89: =G89*H89 -> 4736754 | K89: =내역서!L419 -> 9995296 | L89: =G89*K89 -> 9995296 | M89: =내역서!N419 -> 0 | N89: =G89*M89 -> 0 | O89: =IF((H89+K89+M89)=0, "", (H89+K89+M89)) -> 14732050 | P89: =SUM(I89,L89,N89) -> 14732050
B90: 010108 | D90: 1-1-8.원격검침설비공사 | F90: 식 | G90: 1 | H90: =내역서!I445 -> 49618567 | I90: =G90*H90 -> 49618567 | K90: =내역서!L445 -> 50400373 | L90: =G90*K90 -> 50400373 | M90: =내역서!N445 -> 0 | N90: =G90*M90 -> 0 | O90: =IF((H90+K90+M90)=0, "", (H90+K90+M90)) -> 100018940 | P90: =SUM(I90,L90,N90) -> 100018940
B107: 0101 | C107: Total | D107: ( 합 계 ) | I107: =TRUNC(SUM(I82:I106)) -> 189884042 | L107: =TRUNC(SUM(L82:L106)) -> 644295815 | N107: =TRUNC(SUM(N82:N106)) -> 2508 | O107: =IF((H107+K107+M107)=0, "", (H107+K107+M107)) | P107: =TRUNC(SUM(P82:P106)) -> 834182365
B108: 공종줄 | D108: 1.전기공사::1-1.공동주택::1-1-1.전기단위세대공사
B109: 01010101 | D109: 1-1-1-1.전기단위세대(52㎡-4세대) | F109: 식 | G109: 1 | H109: =내역서!I55 -> 3695743 | I109: =G109*H109 -> 3695743 | K109: =내역서!L55 -> 24100672 | L109: =G109*K109 -> 24100672 | M109: =내역서!N55 -> 0 | N109: =G109*M109 -> 0 | O109: =IF((H109+K109+M109)=0, "", (H109+K109+M109)) -> 27796415 | P109: =SUM(I109,L109,N109) -> 27796415
B110: 01010102 | D110: 1-1-1-2.전기단위세대(51㎡-39세대) | F110: 식 | G110: 1 | H110: =내역서!I107 -> 36293190 | I110: =G110*H110 -> 36293190 | K110: =내역서!L107 -> 236792377 | L110: =G110*K110 -> 236792377 | M110: =내역서!N107 -> 0 | N110: =G110*M110 -> 0 | O110: =IF((H110+K110+M110)=0, "", (H110+K110+M110)) -> 273085567 | P110: =SUM(I110,L110,N110) -> 273085567
B111: 01010103 | D111: 1-1-1-3.전기단위세대(42㎡-17세대) | F111: 식 | G111: 1 | H111: =내역서!I159 -> 15770169 | I111: =G111*H111 -> 15770169 | K111: =내역서!L159 -> 103149180 | L111: =G111*K111 -> 103149180 | M111: =내역서!N159 -> 0 | N111: =G111*M111 -> 0 | O111: =IF((H111+K111+M111)=0, "", (H111+K111+M111)) -> 118919349 | P111: =SUM(I111,L111,N111) -> 118919349
B112: 01010104 | D112: 1-1-1-4.전기단위세대(20㎡-20세대) | F112: 식 | G112: 1 | H112: =내역서!I211 -> 14411857 | I112: =G112*H112 -> 14411857 | K112: =내역서!L211 -> 81806605 | L112: =G112*K112 -> 81806605 | M112: =내역서!N211 -> 0 | N112: =G112*M112 -> 0 | O112: =IF((H112+K112+M112)=0, "", (H112+K112+M112)) -> 96218462 | P112: =SUM(I112,L112,N112) -> 96218462
B133: 010101 | C133: Total | D133: ( 합 계 ) | I133: =TRUNC(SUM(I108:I132)) -> 70170959 | L133: =TRUNC(SUM(L108:L132)) -> 445848834 | N133: =TRUNC(SUM(N108:N132)) -> 0 | O133: =IF((H133+K133+M133)=0, "", (H133+K133+M133)) | P133: =TRUNC(SUM(P108:P132)) -> 516019793
B134: 공종줄 | D134: 1.전기공사::1-2.부대시설
B135: 010201 | D135: 1-2-1.전력간선설비공사 | F135: 식 | G135: 1 | H135: =내역서!I497 -> 8146951 | I135: =G135*H135 -> 8146951 | K135: =내역서!L497 -> 15234857 | L135: =G135*K135 -> 15234857 | M135: =내역서!N497 -> 0 | N135: =G135*M135 -> 0 | O135: =IF((H135+K135+M135)=0, "", (H135+K135+M135)) -> 23381808 | P135: =SUM(I135,L135,N135) -> 23381808
B136: 010202 | D136: 1-2-2.동력설비공사 | F136: 식 | G136: 1 | H136: =내역서!I549 -> 2800156 | I136: =G136*H136 -> 2800156 | K136: =내역서!L549 -> 9612794 | L136: =G136*K136 -> 9612794 | M136: =내역서!N549 -> 0 | N136: =G136*M136 -> 0 | O136: =IF((H136+K136+M136)=0, "", (H136+K136+M136)) -> 12412950 | P136: =SUM(I136,L136,N136) -> 12412950
B137: 010203 | D137: 1-2-3.전등설비공사 | F137: 식 | G137: 1 | H137: =내역서!I575 -> 4056614 | I137: =G137*H137 -> 4056614 | K137: =내역서!L575 -> 7981123 | L137: =G137*K137 -> 7981123 | M137: =내역서!N575 -> 0 | N137: =G137*M137 -> 0 | O137: =IF((H137+K137+M137)=0, "", (H137+K137+M137)) -> 12037737 | P137: =SUM(I137,L137,N137) -> 12037737
B138: 010204 | D138: 1-2-4.전열설비공사 | F138: 식 | G138: 1 | H138: =내역서!I601 -> 1527040 | I138: =G138*H138 -> 1527040 | K138: =내역서!L601 -> 10243086 | L138: =G138*K138 -> 10243086 | M138: =내역서!N601 -> 0 | N138: =G138*M138 -> 0 | O138: =IF((H138+K138+M138)=0, "", (H138+K138+M138)) -> 11770126 | P138: =SUM(I138,L138,N138) -> 11770126
B139: 010205 | D139: 1-2-5.원격검침설비공사 | F139: 식 | G139: 1 | H139: =내역서!I627 -> 757382 | I139: =G139*H139 -> 757382 | K139: =내역서!L627 -> 1146828 | L139: =G139*K139 -> 1146828 | M139: =내역서!N627 -> 0 | N139: =G139*M139 -> 0 | O139: =IF((H139+K139+M139)=0, "", (H139+K139+M139)) -> 1904210 | P139: =SUM(I139,L139,N139) -> 1904210
B159: 0102 | C159: Total | D159: ( 합 계 ) | I159: =TRUNC(SUM(I134:I158)) -> 17288143 | L159: =TRUNC(SUM(L134:L158)) -> 44218688 | N159: =TRUNC(SUM(N134:N158)) -> 0 | O159: =IF((H159+K159+M159)=0, "", (H159+K159+M159)) | P159: =TRUNC(SUM(P134:P158)) -> 61506831
B160: 공종줄 | D160: 1.전기공사::1-3.지하주차장
B161: 010301 | D161: 1-3-1.옥외보안등공사 | F161: 식 | G161: 1 | H161: =내역서!I653 -> 2462251 | I161: =G161*H161 -> 2462251 | K161: =내역서!L653 -> 4636151 | L161: =G161*K161 -> 4636151 | M161: =내역서!N653 -> 374879 | N161: =G161*M161 -> 374879 | O161: =IF((H161+K161+M161)=0, "", (H161+K161+M161)) -> 7473281 | P161: =SUM(I161,L161,N161) -> 7473281
...

Sheet 내역서
A1: 총줄수-> | B1: 1173 | D1: [ 강릉시 입암동 통합공공임대주택 건립사업 신축공사 ] | W1: 노임 계산 정보 | AA1: 부속재 및 손료
A2: 번호 | B2: 공종코드 | C2: 코드 | D2: 명 칭 | E2: 규 격 | F2: 단위 | G2: 수량 | H2: 재료비 | J2: 노무비 | M2: 경비 | P2: 계 | Q2: 비고 | W2: 노임계 | X2: 전체(%) | Y2: 공종별(%) | Z2: 노임 소수 | AA2: CD배관재 | AB2: 일반배관재 | AC2: 소모재 | AD2: 자재계 | AE2: 노임계
H3: 단가 | I3: 금액 | J3: 수량 | K3: 단가 | L3: 금액 | M3: 단가 | N3: 금액 | O3: 단가 | AD3: =IF(옵션!$C$11 =0, "1", 옵션!$C$11) -> 1 | AE3: =IF(옵션!$C$12 =0, "1", 옵션!$C$12) -> 1
B4: 공종줄 | D4: 1.전기공사::1-1.공동주택::1-1-1.전기단위세대공사::1-1-1-1.전기단위세대(52㎡-4세대)
A5: 59753A97002 | B5: 01010101 | C5: F59753097002 | D5: 합성수지제 가요전선관 | E5: CD-난연성 16㎜ | F5: M | G5: 589 | H5: =일대목차!I37 -> 449 | I5: =TRUNC(G5*H5) -> 264461 | J5: 589 | K5: =일대목차!L37 -> 9852 | L5: =TRUNC(G5*K5) -> 5802828 | M5: =일대목차!N37 -> 0 | N5: =TRUNC(G5*M5) -> 0 | O5: =IF((H5+K5+M5)=0, "", (H5+K5+M5)) -> 10301 | P5: =SUM(I5,L5,N5) -> 6067289 | Q5: 제 34호 | AA5: =I5 -> 264461 | AC5: =G5*H5 -> 264461 | AE5: =L5 -> 5802828
A6: 59753017043 | B6: 01010101 | C6: 3913170620174434 | D6: 1종금속제가요전선관 | E6: 커넥터, 16 mm 일반-비방수 | F6: 개 | G6: 120 | H6: =합산자재!H14 -> 340 | I6: =TRUNC(G6*H6) -> 40800 | J6: 120 | K6: =합산자재!I14 -> 0 | L6: =TRUNC(G6*K6) -> 0 | M6: =합산자재!J14 -> 0 | N6: =TRUNC(G6*M6) -> 0 | O6: =IF((H6+K6+M6)=0, "", (H6+K6+M6)) -> 340 | P6: =SUM(I6,L6,N6) -> 40800
A7: 56959000004 | B7: 01010101 | C7: F56959000004 | D7: 1종금속제가요전선관 | E7: 16 mm 고장력-비방수 | F7: M | G7: 34 | H7: =일대목차!I43 -> 691 | I7: =TRUNC(G7*H7) -> 23494 | J7: 34 | K7: =일대목차!L43 -> 10837 | L7: =TRUNC(G7*K7) -> 368458 | M7: =일대목차!N43 -> 0 | N7: =TRUNC(G7*M7) -> 0 | O7: =IF((H7+K7+M7)=0, "", (H7+K7+M7)) -> 11528 | P7: =SUM(I7,L7,N7) -> 391952 | Q7: 제 40호 | AC7: =G7*H7 -> 23494 | AE7: =L7 -> 368458
A8: 59753H67011 | B8: 01010101 | C8: F59753767011 | D8: 아우트렛박스 | E8: 8각 54㎜ | F8: 개 | G8: 44 | H8: =일대목차!I50 -> 1218 | I8: =TRUNC(G8*H8) -> 53592 | J8: 44 | K8: =일대목차!L50 -> 29557 | L8: =TRUNC(G8*K8) -> 1300508 | M8: =일대목차!N50 -> 0 | N8: =TRUNC(G8*M8) -> 0 | O8: =IF((H8+K8+M8)=0, "", (H8+K8+M8)) -> 30775 | P8: =SUM(I8,L8,N8) -> 1354100 | Q8: 제 47호 | AE8: =L8 -> 1300508
A9: 59753H77102 | B9: 01010101 | C9: F59753777102 | D9: 스위치박스 | E9: 1 개용 54 mm | F9: 개 | G9: 36 | H9: =일대목차!I52 -> 1577 | I9: =TRUNC(G9*H9) -> 56772 | J9: 36 | K9: =일대목차!L52 -> 49261 | L9: =TRUNC(G9*K9) -> 1773396 | M9: =일대목차!N52 -> 0 | N9: =TRUNC(G9*M9) -> 0 | O9: =IF((H9+K9+M9)=0, "", (H9+K9+M9)) -> 50838 | P9: =SUM(I9,L9,N9) -> 1830168 | Q9: 제 49호 | AE9: =L9 -> 1773396
A10: 59753H77111 | B10: 01010101 | C10: F59753777111 | D10: 스위치박스 | E10: 2 개용 54 mm | F10: 개 | G10: 28 | H10: =일대목차!I53 -> 1711 | I10: =TRUNC(G10*H10) -> 47908 | J10: 28 | K10: =일대목차!L53 -> 49261 | L10: =TRUNC(G10*K10) -> 1379308 | M10: =일대목차!N53 -> 0 | N10: =TRUNC(G10*M10) -> 0 | O10: =IF((H10+K10+M10)=0, "", (H10+K10+M10)) -> 50972 | P10: =SUM(I10,L10,N10) -> 1427216 | Q10: 제 50호 | AE10: =L10 -> 1379308
A11: 56959000016 | B11: 01010101 | C11: F56959000016 | D11: 연결박스 | E11: 4각 44㎜ | F11: 개 | G11: 36 | H11: =일대목차!I54 -> 921 | I11: =TRUNC(G11*H11) -> 33156 | J11: 36 | K11: =일대목차!L54 -> 9852 | L11: =TRUNC(G11*K11) -> 354672 | M11: =일대목차!N54 -> 0 | N11: =TRUNC(G11*M11) -> 0 | O11: =IF((H11+K11+M11)=0, "", (H11+K11+M11)) -> 10773 | P11: =SUM(I11,L11,N11) -> 387828 | Q11: 제 51호 | AE11: =L11 -> 354672
A12: 59753767221 | B12: 01010101 | C12: 3912130820174712 | D12: 아우트렛박스 커버 | E12: 커버, 8각, 둥근구멍(평) | F12: 개 | G12: 44 | H12: =합산자재!H45 -> 282 | I12: =TRUNC(G12*H12) -> 12408 | J12: 44 | K12: =합산자재!I45 -> 0 | L12: =TRUNC(G12*K12) -> 0 | M12: =합산자재!J45 -> 0 | N12: =TRUNC(G12*M12) -> 0 | O12: =IF((H12+K12+M12)=0, "", (H12+K12+M12)) -> 282 | P12: =SUM(I12,L12,N12) -> 12408
A13: 59753767281 | B13: 01010101 | C13: 3912130820174718 | D13: 아우트렛박스 커버 | E13: 커버, 4각,2개용S/W (오목) | F13: 개 | G13: 28 | H13: =합산자재!H47 -> 283 | I13: =TRUNC(G13*H13) -> 7924 | J13: 28 | K13: =합산자재!I47 -> 0 | L13: =TRUNC(G13*K13) -> 0 | M13: =합산자재!J47 -> 0 | N13: =TRUNC(G13*M13) -> 0 | O13: =IF((H13+K13+M13)=0, "", (H13+K13+M13)) -> 283 | P13: =SUM(I13,L13,N13) -> 7924
A14: 59753I57001 | B14: 01010101 | C14: F59753857001 | D14: 풀박스 | E14: 100×100×50 | F14: 개 | G14: 4 | H14: =일대목차!I57 -> 3121 | I14: =TRUNC(G14*H14) -> 12484 | J14: 4 | K14: =일대목차!L57 -> 41872 | L14: =TRUNC(G14*K14) -> 167488 | M14: =일대목차!N57 -> 0 | N14: =TRUNC(G14*M14) -> 0 | O14: =IF((H14+K14+M14)=0, "", (H14+K14+M14)) -> 44993 | P14: =SUM(I14,L14,N14) -> 179972 | Q14: 제 54호 | AE14: =L14 -> 167488
A15: 56959000020 | B15: 01010101 | C15: F56959000020 | D15: 450/750V 내열비닐절연전선 | E15: HFIX 1.78mm(2.5㎟) | F15: M | G15: 2238 | H15: =일대목차!I73 -> 590 | I15: =TRUNC(G15*H15) -> 1320420 | J15: 2238 | K15: =일대목차!L73 -> 2353 | L15: =TRUNC(G15*K15) -> 5266014 | M15: =일대목차!N73 -> 0 | N15: =TRUNC(G15*M15) -> 0 | O15: =IF((H15+K15+M15)=0, "", (H15+K15+M15)) -> 2943 | P15: =SUM(I15,L15,N15) -> 6586434 | Q15: 제 70호 | AC15: =G15*H15 -> 1320420 | AE15: =L15 -> 5266014
A16: 59301F17001 | B16: 01010101 | C16: F59301517001 | D16: 매입스위치 | E16: 250V 1로1구 | F16: 개 | G16: 16 | H16: =일대목차!I111 -> 1789 | I16: =TRUNC(G16*H16) -> 28624 | J16: 16 | K16: =일대목차!L111 -> 23262 | L16: =TRUNC(G16*K16) -> 372192 | M16: =일대목차!N111 -> 0 | N16: =TRUNC(G16*M16) -> 0 | O16: =IF((H16+K16+M16)=0, "", (H16+K16+M16)) -> 25051 | P16: =SUM(I16,L16,N16) -> 400816 | Q16: 제 108호 | AE16: =L16 -> 372192
A17: 59301F17002 | B17: 01010101 | C17: F59301517002 | D17: 매입스위치 | E17: 250V 1로2구 | F17: 개 | G17: 4 | H17: =일대목차!I112 -> 2318 | I17: =TRUNC(G17*H17) -> 9272 | J17: 4 | K17: =일대목차!L112 -> 23262 | L17: =TRUNC(G17*K17) -> 93048 | M17: =일대목차!N112 -> 0 | N17: =TRUNC(G17*M17) -> 0 | O17: =IF((H17+K17+M17)=0, "", (H17+K17+M17)) -> 25580 | P17: =SUM(I17,L17,N17) -> 102320 | Q17: 제 109호 | AE17: =L17 -> 93048
A18: 59301F17003 | B18: 01010101 | C18: F59301517003 | D18: 매입스위치 | E18: 250V 1로3구 | F18: 개 | G18: 4 | H18: =일대목차!I113 -> 2860 | I18: =TRUNC(G18*H18) -> 11440 | J18: 4 | K18: =일대목차!L113 -> 23262 | L18: =TRUNC(G18*K18) -> 93048 | M18: =일대목차!N113 -> 0 | N18: =TRUNC(G18*M18) -> 0 | O18: =IF((H18+K18+M18)=0, "", (H18+K18+M18)) -> 26122 | P18: =SUM(I18,L18,N18) -> 104488 | Q18: 제 110호 | AE18: =L18 -> 93048
A19: 59350D17205 | B19: 01010101 | C19: F59350317205 | D19: 콘센트 | E19: 매입-접지형, 250V 1구 | F19: 개 | G19: 12 | H19: =일대목차!I116 -> 1372 | I19: =TRUNC(G19*H19) -> 16464 | J19: 12 | K19: =일대목차!L116 -> 21894 | L19: =TRUNC(G19*K19) -> 262728 | M19: =일대목차!N116 -> 0 | N19: =TRUNC(G19*M19) -> 0 | O19: =IF((H19+K19+M19)=0, "", (H19+K19+M19)) -> 23266 | P19: =SUM(I19,L19,N19) -> 279192 | Q19: 제 113호 | AE19: =L19 -> 262728
A20: 59350D17206 | B20: 01010101 | C20: F59350317206 | D20: 콘센트 | E20: 매입-접지형, 250V 2구 | F20: 개 | G20: 44 | H20: =일대목차!I117 -> 1822 | I20: =TRUNC(G20*H20) -> 80168 | J20: 44 | K20: =일대목차!L117 -> 21894 | L20: =TRUNC(G20*K20) -> 963336 | M20: =일대목차!N117 -> 0 | N20: =TRUNC(G20*M20) -> 0 | O20: =IF((H20+K20+M20)=0, "", (H20+K20+M20)) -> 23716 | P20: =SUM(I20,L20,N20) -> 1043504 | Q20: 제 114호 | AE20: =L20 -> 963336
A21: 59350D17207 | B21: 01010101 | C21: F59350317207 | D21: 방우콘센트 | E21: 매입-접지형, 250V 1구 | F21: 개 | G21: 8 | H21: =일대목차!I118 -> 2474 | I21: =TRUNC(G21*H21) -> 19792 | J21: 8 | K21: =일대목차!L118 -> 21894 | L21: =TRUNC(G21*K21) -> 175152 | M21: =일대목차!N118 -> 0 | N21: =TRUNC(G21*M21) -> 0 | O21: =IF((H21+K21+M21)=0, "", (H21+K21+M21)) -> 24368 | P21: =SUM(I21,L21,N21) -> 194944 | Q21: 제 115호 | AE21: =L21 -> 175152
A22: 59350D17208 | B22: 01010101 | C22: F59350317208 | D22: 방우콘센트 | E22: 매입-접지형, 250V 2구 | F22: 개 | G22: 4 | H22: =일대목차!I119 -> 2560 | I22: =TRUNC(G22*H22) -> 10240 | J22: 4 | K22: =일대목차!L119 -> 21894 | L22: =TRUNC(G22*K22) -> 87576 | M22: =일대목차!N119 -> 0 | N22: =TRUNC(G22*M22) -> 0 | O22: =IF((H22+K22+M22)=0, "", (H22+K22+M22)) -> 24454 | P22: =SUM(I22,L22,N22) -> 97816 | Q22: 제 116호 | AE22: =L22 -> 87576
A23: 56953100927 | B23: 01010101 | C23: EAB110540000 | D23: 석고따기 | E23: 측벽 | F23: 식 | G23: 36 | H23: =일대목차!I27 -> 224 | I23: =TRUNC(G23*H23) -> 8064 | J23: 36 | K23: =일대목차!L27 -> 11220 | L23: =TRUNC(G23*K23) -> 403920 | M23: =일대목차!N27 -> 0 | N23: =TRUNC(G23*M23) -> 0 | O23: =IF((H23+K23+M23)=0, "", (H23+K23+M23)) -> 11444 | P23: =SUM(I23,L23,N23) -> 411984 | Q23: 제 24호 | AE23: =L23 -> 403920
A24: 5695C100010 | B24: 01010101 | C24: F5695C100010 | D24: 다운라이트구멍따기 | F24: 개소 | G24: 8 | H24: =일대목차!I29 -> 224 | I24: =TRUNC(G24*H24) -> 1792 | J24: 8 | K24: =일대목차!L29 -> 11220 | L24: =TRUNC(G24*K24) -> 89760 | M24: =일대목차!N29 -> 0 | N24: =TRUNC(G24*M24) -> 0 | O24: =IF((H24+K24+M24)=0, "", (H24+K24+M24)) -> 11444 | P24: =SUM(I24,L24,N24) -> 91552 | Q24: 제 26호 | AE24: =L24 -> 89760
A25: 56959000048 | B25: 01010101 | C25: F56959000048 | D25: 통합콘센트 | E25: 일반4구/전화2/TV | F25: 개 | G25: 4 | H25: =일대목차!I150 -> 45437 | I25: =TRUNC(G25*H25) -> 181748 | J25: 4 | K25: =일대목차!L150 -> 21894 | L25: =TRUNC(G25*K25) -> 87576 | M25: =일대목차!N150 -> 0 | N25: =TRUNC(G25*M25) -> 0 | O25: =IF((H25+K25+M25)=0, "", (H25+K25+M25)) -> 67331 | P25: =SUM(I25,L25,N25) -> 269324 | Q25: 제 147호 | AE25: =L25 -> 87576
A26: 56959000052 | B26: 01010101 | C26: F56959000052 | D26: 통합콘센트 | E26: 일반2/전화2/TV | F26: 개 | G26: 8 | H26: =일대목차!I152 -> 35437 | I26: =TRUNC(G26*H26) -> 283496 | J26: 8 | K26: =일대목차!L152 -> 21894 | L26: =TRUNC(G26*K26) -> 175152 | M26: =일대목차!N152 -> 0 | N26: =TRUNC(G26*M26) -> 0 | O26: =IF((H26+K26+M26)=0, "", (H26+K26+M26)) -> 57331 | P26: =SUM(I26,L26,N26) -> 458648 | Q26: 제 149호 | AE26: =L26 -> 175152
A27: 56959000058 | B27: 01010101 | C27: F56959000058 | D27: 통합BOX | E27: 일반2/전화2/TV | F27: 개 | G27: 4 | H27: =일대목차!I155 -> 4985 | I27: =TRUNC(G27*H27) -> 19940 | J27: 4 | K27: =일대목차!L155 -> 49261 | L27: =TRUNC(G27*K27) -> 197044 | M27: =일대목차!N155 -> 0 | N27: =TRUNC(G27*M27) -> 0 | O27: =IF((H27+K27+M27)=0, "", (H27+K27+M27)) -> 54246 | P27: =SUM(I27,L27,N27) -> 216984 | Q27: 제 152호 | AE27: =L27 -> 197044
A28: 56959000060 | B28: 01010101 | C28: F56959000060 | D28: 결로 통합BOX | E28: 일반4구/전화2/TV | F28: 개 | G28: 4 | H28: =일대목차!I156 -> 2485 | I28: =TRUNC(G28*H28) -> 9940 | J28: 4 | K28: =일대목차!L156 -> 49261 | L28: =TRUNC(G28*K28) -> 197044 | M28: =일대목차!N156 -> 0 | N28: =TRUNC(G28*M28) -> 0 | O28: =IF((H28+K28+M28)=0, "", (H28+K28+M28)) -> 51746 | P28: =SUM(I28,L28,N28) -> 206984 | Q28: 제 153호 | AE28: =L28 -> 197044
A29: 56959000062 | B29: 01010101 | C29: F56959000062 | D29: 결로 통합BOX | E29: 일반2/전화2/TV | F29: 개 | G29: 4 | H29: =일대목차!I157 -> 2485 | I29: =TRUNC(G29*H29) -> 9940 | J29: 4 | K29: =일대목차!L157 -> 49261 | L29: =TRUNC(G29*K29) -> 197044 | M29: =일대목차!N157 -> 0 | N29: =TRUNC(G29*M29) -> 0 | O29: =IF((H29+K29+M29)=0, "", (H29+K29+M29)) -> 51746 | P29: =SUM(I29,L29,N29) -> 206984 | Q29: 제 154호 | AE29: =L29 -> 197044
A30: 56959000064 | B30: 01010101 | C30: F56959000064 | D30: 콘센트 | E30: 가로-접지형,15A 250V 2구 | F30: 개 | G30: 4 | H30: =일대목차!I158 -> 1782 | I30: =TRUNC(G30*H30) -> 7128 | J30: 4 | K30: =일대목차!L158 -> 21894 | L30: =TRUNC(G30*K30) -> 87576 | M30: =일대목차!N158 -> 0 | N30: =TRUNC(G30*M30) -> 0 | O30: =IF((H30+K30+M30)=0, "", (H30+K30+M30)) -> 23676 | P30: =SUM(I30,L30,N30) -> 94704 | Q30: 제 155호 | AE30: =L30 -> 87576
A31: 56959000066 | B31: 01010101 | C31: F56959000066 | D31: 결로BOX | E31: 1구 | F31: 개 | G31: 16 | H31: =일대목차!I159 -> 2285 | I31: =TRUNC(G31*H31) -> 36560 | J31: 16 | K31: =일대목차!L159 -> 49261 | L31: =TRUNC(G31*K31) -> 788176 | M31: =일대목차!N159 -> 0 | N31: =TRUNC(G31*M31) -> 0 | O31: =IF((H31+K31+M31)=0, "", (H31+K31+M31)) -> 51546 | P31: =SUM(I31,L31,N31) -> 824736 | Q31: 제 156호 | AE31: =L31 -> 788176
A32: 56959000068 | B32: 01010101 | C32: F56959000068 | D32: 결로BOX | E32: 2구 | F32: 개 | G32: 12 | H32: =일대목차!I160 -> 2485 | I32: =TRUNC(G32*H32) -> 29820 | J32: 12 | K32: =일대목차!L160 -> 49261 | L32: =TRUNC(G32*K32) -> 591132 | M32: =일대목차!N160 -> 0 | N32: =TRUNC(G32*M32) -> 0 | O32: =IF((H32+K32+M32)=0, "", (H32+K32+M32)) -> 51746 | P32: =SUM(I32,L32,N32) -> 620952 | Q32: 제 157호 | AE32: =L32 -> 591132
A33: MMH15519080 | B33: 01010101 | C33: InMastDBNonCode | D33: 실외기단자대 | F33: EA | G33: 4 | H33: =합산자재!H221 -> 50000 | I33: =TRUNC(G33*H33) -> 200000 | J33: 4 | K33: =합산자재!I221 -> 0 | L33: =TRUNC(G33*K33) -> 0 | M33: =합산자재!J221 -> 0 | N33: =TRUNC(G33*M33) -> 0 | O33: =IF((H33+K33+M33)=0, "", (H33+K33+M33)) -> 50000 | P33: =SUM(I33,L33,N33) -> 200000
A34: 56959000074 | B34: 01010101 | C34: F56959000074 | D34: 세대분전반 | E34: 8회로+APU | F34: 면 | G34: 4 | H34: =일대목차!I163 -> 205221 | I34: =TRUNC(G34*H34) -> 820884 | J34: 4 | K34: =일대목차!L163 -> 243571 | L34: =TRUNC(G34*K34) -> 974284 | M34: =일대목차!N163 -> 0 | N34: =TRUNC(G34*M34) -> 0 | O34: =IF((H34+K34+M34)=0, "", (H34+K34+M34)) -> 448792 | P34: =SUM(I34,L34,N34) -> 1795168 | Q34: 제 160호 | AE34: =L34 -> 974284
A35: 56959000178 | B35: 01010101 | C35: F56959000178 | D35: 조명기구 TYPE 세대-@관급자재 | E35: LED50W(침실직부) | F35: SET | G35: 12 | H35: =일대목차!I215 -> 1247 | I35: =TRUNC(G35*H35) -> 14964 | J35: 12 | K35: =일대목차!L215 -> 62398 | L35: =TRUNC(G35*K35) -> 748776 | M35: =일대목차!N215 -> 0 | N35: =TRUNC(G35*M35) -> 0 | O35: =IF((H35+K35+M35)=0, "", (H35+K35+M35)) -> 63645 | P35: =SUM(I35,L35,N35) -> 763740 | Q35: 제 212호 | AE35: =L35 -> 748776
A36: 56959000176 | B36: 01010101 | C36: F56959000176 | D36: 조명기구 TYPE 세대-@관급자재 | E36: LED40W(주방직부) | F36: SET | G36: 4 | H36: =일대목차!I214 -> 1083 | I36: =TRUNC(G36*H36) -> 4332 | J36: 4 | K36: =일대목차!L214 -> 54187 | L36: =TRUNC(G36*K36) -> 216748 | M36: =일대목차!N214 -> 0 | N36: =TRUNC(G36*M36) -> 0 | O36: =IF((H36+K36+M36)=0, "", (H36+K36+M36)) -> 55270 | P36: =SUM(I36,L36,N36) -> 221080 | Q36: 제 211호 | AE36: =L36 -> 216748
A37: 56959000174 | B37: 01010101 | C37: F56959000174 | D37: 조명기구 TYPE 세대-@관급자재 | E37: LED30W(욕실매입) | F37: SET | G37: 4 | H37: =일대목차!I213 -> 1187 | I37: =TRUNC(G37*H37) -> 4748 | J37: 4 | K37: =일대목차!L213 -> 59387 | L37: =TRUNC(G37*K37) -> 237548 | M37: =일대목차!N213 -> 0 | N37: =TRUNC(G37*M37) -> 0 | O37: =IF((H37+K37+M37)=0, "", (H37+K37+M37)) -> 60574 | P37: =SUM(I37,L37,N37) -> 242296 | Q37: 제 210호 | AE37: =L37 -> 237548
A38: 56959000172 | B38: 01010101 | C38: F56959000172 | D38: 조명기구 TYPE 세대-@관급자재 | E38: LED10W(현관센서) | F38: SET | G38: 4 | H38: =일대목차!I212 -> 574 | I38: =TRUNC(G38*H38) -> 2296 | J38: 4 | K38: =일대목차!L212 -> 28735 | L38: =TRUNC(G38*K38) -> 114940 | M38: =일대목차!N212 -> 0 | N38: =TRUNC(G38*M38) -> 0 | O38: =IF((H38+K38+M38)=0, "", (H38+K38+M38)) -> 29309 | P38: =SUM(I38,L38,N38) -> 117236 | Q38: 제 209호 | AE38: =L38 -> 114940
A39: 56959000168 | B39: 01010101 | C39: F56959000168 | D39: 조명기구 TYPE 세대-@관급자재 | E39: LED10W(세대직부) | F39: SET | G39: 8 | H39: =일대목차!I210 -> 574 | I39: =TRUNC(G39*H39) -> 4592 | J39: 8 | K39: =일대목차!L210 -> 28735 | L39: =TRUNC(G39*K39) -> 229880 | M39: =일대목차!N210 -> 0 | N39: =TRUNC(G39*M39) -> 0 | O39: =IF((H39+K39+M39)=0, "", (H39+K39+M39)) -> 29309 | P39: =SUM(I39,L39,N39) -> 234472 | Q39: 제 207호 | AE39: =L39 -> 229880
A40: 56959000166 | B40: 01010101 | C40: F56959000166 | D40: 조명기구 TYPE 세대-@관급자재 | E40: LED10W(세대D.L) | F40: SET | G40: 4 | H40: =일대목차!I209 -> 760 | I40: =TRUNC(G40*H40) -> 3040 | J40: 4 | K40: =일대목차!L209 -> 38040 | L40: =TRUNC(G40*K40) -> 152160 | M40: =일대목차!N209 -> 0 | N40: =TRUNC(G40*M40) -> 0 | O40: =IF((H40+K40+M40)=0, "", (H40+K40+M40)) -> 38800 | P40: =SUM(I40,L40,N40) -> 155200 | Q40: 제 206호 | AE40: =L40 -> 152160
...

Sheet 일대목차
B1: 237 | C1: [ 강릉시 입암동 통합공공임대주택 건립사업 신축공사 ] - 일위대가목차
A2: 번호 | B2: … | C2: 코드 | D2: 명 칭 | E2: 규 격 | F2: 단위 | G2: 수량 | H2: 재료비 | J2: 노무비 | M2: 경비 | O2: 계 | P2: 계 | Q2: 비고
H3: 단가 | I3: 금액 | J3: 수량 | K3: 단가 | L3: 금액 | M3: 단가 | N3: 금액 | O3: 단가
A4: 56930220020 | B4: ABB103200000 | C4: 제 1호 | D4: 터파기(기계80%,인력20%) | E4: 보통토사 | F4: ㎥ | H4: =일위대가!I7 -> 341 | I4: =H4 -> 341 | K4: =일위대가!L7 -> 7929 | L4: =K4 -> 7929 | M4: =일위대가!N7 -> 418 | N4: =M4 -> 418 | O4: =IF((H4+K4+M4)=0, "", (H4+K4+M4)) -> 8688 | P4: =SUM(I4,L4,N4) -> 8688
A5: 56930220052 | B5: ABB104200000 | C5: 제 2호 | D5: 되메우기(기계80%,인력20%) | E5: 보통토사 | F5: ㎥ | H5: =일위대가!I12 -> 341 | I5: =H5 -> 341 | K5: =일위대가!L12 -> 4488 | L5: =K5 -> 4488 | M5: =일위대가!N12 -> 418 | N5: =M5 -> 418 | O5: =IF((H5+K5+M5)=0, "", (H5+K5+M5)) -> 5247 | P5: =SUM(I5,L5,N5) -> 5247
A6: 56950120016 | B6: EAA110110000 | C6: 제 3호 | D6: 파이프행가 | E6: 16 C | F6: 식 | H6: =일위대가!I22 -> 19534 | I6: =H6 -> 19534 | K6: =일위대가!L22 -> 9852 | L6: =K6 -> 9852 | M6: =일위대가!N22 -> 0 | N6: =M6 -> 0 | O6: =IF((H6+K6+M6)=0, "", (H6+K6+M6)) -> 29386 | P6: =SUM(I6,L6,N6) -> 29386
A7: 56950120022 | B7: EAA110120000 | C7: 제 4호 | D7: 파이프행가 | E7: 22 C | F7: 식 | H7: =일위대가!I32 -> 19539 | I7: =H7 -> 19539 | K7: =일위대가!L32 -> 9852 | L7: =K7 -> 9852 | M7: =일위대가!N32 -> 0 | N7: =M7 -> 0 | O7: =IF((H7+K7+M7)=0, "", (H7+K7+M7)) -> 29391 | P7: =SUM(I7,L7,N7) -> 29391
A8: 56950120028 | B8: EAA110130000 | C8: 제 5호 | D8: 파이프행가 | E8: 28 C | F8: 식 | H8: =일위대가!I42 -> 19561 | I8: =H8 -> 19561 | K8: =일위대가!L42 -> 9852 | L8: =K8 -> 9852 | M8: =일위대가!N42 -> 0 | N8: =M8 -> 0 | O8: =IF((H8+K8+M8)=0, "", (H8+K8+M8)) -> 29413 | P8: =SUM(I8,L8,N8) -> 29413
A9: 56950120036 | B9: EAA110140000 | C9: 제 6호 | D9: 파이프행가 | E9: 36 C | F9: 식 | H9: =일위대가!I52 -> 19585 | I9: =H9 -> 19585 | K9: =일위대가!L52 -> 9852 | L9: =K9 -> 9852 | M9: =일위대가!N52 -> 0 | N9: =M9 -> 0 | O9: =IF((H9+K9+M9)=0, "", (H9+K9+M9)) -> 29437 | P9: =SUM(I9,L9,N9) -> 29437
A10: 56950120042 | B10: EAA110150000 | C10: 제 7호 | D10: 파이프행가 | E10: 42 C | F10: 식 | H10: =일위대가!I62 -> 19622 | I10: =H10 -> 19622 | K10: =일위대가!L62 -> 9852 | L10: =K10 -> 9852 | M10: =일위대가!N62 -> 0 | N10: =M10 -> 0 | O10: =IF((H10+K10+M10)=0, "", (H10+K10+M10)) -> 29474 | P10: =SUM(I10,L10,N10) -> 29474
A11: 56950120054 | B11: EAA110160000 | C11: 제 8호 | D11: 파이프행가 | E11: 54 C | F11: 식 | H11: =일위대가!I72 -> 19816 | I11: =H11 -> 19816 | K11: =일위대가!L72 -> 9852 | L11: =K11 -> 9852 | M11: =일위대가!N72 -> 0 | N11: =M11 -> 0 | O11: =IF((H11+K11+M11)=0, "", (H11+K11+M11)) -> 29668 | P11: =SUM(I11,L11,N11) -> 29668
A12: 56950120070 | B12: EAA110170000 | C12: 제 9호 | D12: 파이프행가 | E12: 70 C | F12: 식 | H12: =일위대가!I82 -> 19866 | I12: =H12 -> 19866 | K12: =일위대가!L82 -> 9852 | L12: =K12 -> 9852 | M12: =일위대가!N82 -> 0 | N12: =M12 -> 0 | O12: =IF((H12+K12+M12)=0, "", (H12+K12+M12)) -> 29718 | P12: =SUM(I12,L12,N12) -> 29718
A13: 56950160200 | B13: EAA110420000 | C13: 제 10호 | D13: 케이블트레이지지대 | E13: W200-1단 | F13: 식 | H13: =일위대가!I93 -> 40646 | I13: =H13 -> 40646 | K13: =일위대가!L93 -> 19704 | L13: =K13 -> 19704 | M13: =일위대가!N93 -> 0 | N13: =M13 -> 0 | O13: =IF((H13+K13+M13)=0, "", (H13+K13+M13)) -> 60350 | P13: =SUM(I13,L13,N13) -> 60350
A14: 56950160300 | B14: EAA110430000 | C14: 제 11호 | D14: 케이블트레이지지대 | E14: W300-1단 | F14: 식 | H14: =일위대가!I104 -> 41036 | I14: =H14 -> 41036 | K14: =일위대가!L104 -> 19704 | L14: =K14 -> 19704 | M14: =일위대가!N104 -> 0 | N14: =M14 -> 0 | O14: =IF((H14+K14+M14)=0, "", (H14+K14+M14)) -> 60740 | P14: =SUM(I14,L14,N14) -> 60740
A15: 56950160800 | B15: EAA110478000 | C15: 제 12호 | D15: 케이블트레이지지대 | E15: W800-1단 | F15: 식 | H15: =일위대가!I115 -> 42986 | I15: =H15 -> 42986 | K15: =일위대가!L115 -> 19704 | L15: =K15 -> 19704 | M15: =일위대가!N115 -> 0 | N15: =M15 -> 0 | O15: =IF((H15+K15+M15)=0, "", (H15+K15+M15)) -> 62690 | P15: =SUM(I15,L15,N15) -> 62690
A16: 56950170119 | B16: EAA110690000 | C16: 제 13호 | D16: EPS SUPPORT | E16: W800-1단 | F16: 식 | H16: =일위대가!I126 -> 41332 | I16: =H16 -> 41332 | K16: =일위대가!L126 -> 19704 | L16: =K16 -> 19704 | M16: =일위대가!N126 -> 0 | N16: =M16 -> 0 | O16: =IF((H16+K16+M16)=0, "", (H16+K16+M16)) -> 61036 | P16: =SUM(I16,L16,N16) -> 61036
A17: 56950180028 | B17: EAA110830000 | C17: 제 14호 | D17: 동력배관지지가대 | E17: 28C | F17: 식 | H17: =일위대가!I138 -> 41309 | I17: =H17 -> 41309 | K17: =일위대가!L138 -> 251781 | L17: =K17 -> 251781 | M17: =일위대가!N138 -> 0 | N17: =M17 -> 0 | O17: =IF((H17+K17+M17)=0, "", (H17+K17+M17)) -> 293090 | P17: =SUM(I17,L17,N17) -> 293090
A18: 56950180036 | B18: EAA110840000 | C18: 제 15호 | D18: 동력배관지지가대 | E18: 36C | F18: 식 | H18: =일위대가!I150 -> 41357 | I18: =H18 -> 41357 | K18: =일위대가!L150 -> 251781 | L18: =K18 -> 251781 | M18: =일위대가!N150 -> 0 | N18: =M18 -> 0 | O18: =IF((H18+K18+M18)=0, "", (H18+K18+M18)) -> 293138 | P18: =SUM(I18,L18,N18) -> 293138
A19: 56950180042 | B19: EAA110850000 | C19: 제 16호 | D19: 동력배관지지가대 | E19: 42C | F19: 식 | H19: =일위대가!I162 -> 41395 | I19: =H19 -> 41395 | K19: =일위대가!L162 -> 251781 | L19: =K19 -> 251781 | M19: =일위대가!N162 -> 0 | N19: =M19 -> 0 | O19: =IF((H19+K19+M19)=0, "", (H19+K19+M19)) -> 293176 | P19: =SUM(I19,L19,N19) -> 293176
A20: 56950180054 | B20: EAA110860000 | C20: 제 17호 | D20: 동력배관지지가대 | E20: 54C | F20: 식 | H20: =일위대가!I174 -> 41422 | I20: =H20 -> 41422 | K20: =일위대가!L174 -> 251781 | L20: =K20 -> 251781 | M20: =일위대가!N174 -> 0 | N20: =M20 -> 0 | O20: =IF((H20+K20+M20)=0, "", (H20+K20+M20)) -> 293203 | P20: =SUM(I20,L20,N20) -> 293203
A21: 56950200520 | B21: EAC110160000 | C21: 제 18호 | D21: 맨 홀 | E21: 1000x1000x1000 | F21: 식 | H21: =일위대가!I198 -> 785665 | I21: =H21 -> 785665 | K21: =일위대가!L198 -> 1574291 | L21: =K21 -> 1574291 | M21: =일위대가!N198 -> 54822 | N21: =M21 -> 54822 | O21: =IF((H21+K21+M21)=0, "", (H21+K21+M21)) -> 2414778 | P21: =SUM(I21,L21,N21) -> 2414778
A22: 56950200530 | B22: EAC110170000 | C22: 제 19호 | D22: 맨 홀 | E22: 1500x1500x1500 | F22: 식 | H22: =일위대가!I217 -> 922035 | I22: =H22 -> 922035 | K22: =일위대가!L217 -> 1843024 | L22: =K22 -> 1843024 | M22: =일위대가!N217 -> 59838 | N22: =M22 -> 59838 | O22: =IF((H22+K22+M22)=0, "", (H22+K22+M22)) -> 2824897 | P22: =SUM(I22,L22,N22) -> 2824897
A23: 56950220302 | B23: EAD110121000 | C23: 제 20호 | D23: 접지공사 | E23: TEST | F23: 식 | H23: =일위대가!I229 -> 32327 | I23: =H23 -> 32327 | K23: =일위대가!L229 -> 125021 | L23: =K23 -> 125021 | M23: =일위대가!N229 -> 1254 | N23: =M23 -> 1254 | O23: =IF((H23+K23+M23)=0, "", (H23+K23+M23)) -> 158602 | P23: =SUM(I23,L23,N23) -> 158602
A24: 56950240050 | B24: EAF110120000 | C24: 제 21호 | D24: 관로구방수 | E24: D50 | F24: 식 | H24: =일위대가!I239 -> 36750 | I24: =H24 -> 36750 | K24: =일위대가!L239 -> 80874 | L24: =K24 -> 80874 | M24: =일위대가!N239 -> 0 | N24: =M24 -> 0 | O24: =IF((H24+K24+M24)=0, "", (H24+K24+M24)) -> 117624 | P24: =SUM(I24,L24,N24) -> 117624
A25: 56950240065 | B25: EAF110130000 | C25: 제 22호 | D25: 관로구방수 | E25: D65 | F25: 식 | H25: =일위대가!I249 -> 38656 | I25: =H25 -> 38656 | K25: =일위대가!L249 -> 80874 | L25: =K25 -> 80874 | M25: =일위대가!N249 -> 0 | N25: =M25 -> 0 | O25: =IF((H25+K25+M25)=0, "", (H25+K25+M25)) -> 119530 | P25: =SUM(I25,L25,N25) -> 119530
A26: 56950240150 | B26: EAF110170000 | C26: 제 23호 | D26: 관로구방수 | E26: D150 | F26: 식 | H26: =일위대가!I259 -> 68241 | I26: =H26 -> 68241 | K26: =일위대가!L259 -> 80874 | L26: =K26 -> 80874 | M26: =일위대가!N259 -> 0 | N26: =M26 -> 0 | O26: =IF((H26+K26+M26)=0, "", (H26+K26+M26)) -> 149115 | P26: =SUM(I26,L26,N26) -> 149115
A27: 56953100927 | B27: EAB110540000 | C27: 제 24호 | D27: 석고따기 | E27: 측벽 | F27: 식 | H27: =일위대가!I264 -> 224 | I27: =H27 -> 224 | K27: =일위대가!L264 -> 11220 | L27: =K27 -> 11220 | M27: =일위대가!N264 -> 0 | N27: =M27 -> 0 | O27: =IF((H27+K27+M27)=0, "", (H27+K27+M27)) -> 11444 | P27: =SUM(I27,L27,N27) -> 11444
A28: 56959J99110 | B28: 56959J991100 | C28: 제 25호 | D28: 조명기구 설치(POLE LIGHT)-강관,AL | E28: 5m-7m 이하(기계화시공) | F28: 개소 | H28: =일위대가!I270 -> 1696 | I28: =H28 -> 1696 | K28: =일위대가!L270 -> 84839 | L28: =K28 -> 84839 | M28: =일위대가!N270 -> 37543 | N28: =M28 -> 37543 | O28: =IF((H28+K28+M28)=0, "", (H28+K28+M28)) -> 124078 | P28: =SUM(I28,L28,N28) -> 124078
A29: 5695C100010 | B29: F5695C100010 | C29: 제 26호 | D29: 다운라이트구멍따기 | F29: 개소 | H29: =일위대가!I275 -> 224 | I29: =H29 -> 224 | K29: =일위대가!L275 -> 11220 | L29: =K29 -> 11220 | M29: =일위대가!N275 -> 0 | N29: =M29 -> 0 | O29: =IF((H29+K29+M29)=0, "", (H29+K29+M29)) -> 11444 | P29: =SUM(I29,L29,N29) -> 11444
A30: 5695FIR0200 | B30: F5695F8R0200 | C30: 제 27호 | D30: 방화구획(내화충전) | E30: W 200 | F30: 개소 | H30: =일위대가!I281 -> 20109 | I30: =H30 -> 20109 | K30: =일위대가!L281 -> 42187 | L30: =K30 -> 42187 | M30: =일위대가!N281 -> 0 | N30: =M30 -> 0 | O30: =IF((H30+K30+M30)=0, "", (H30+K30+M30)) -> 62296 | P30: =SUM(I30,L30,N30) -> 62296
A31: 5695FIR0300 | B31: F5695F8R0300 | C31: 제 28호 | D31: 방화구획(내화충전) | E31: W 300 | F31: 개소 | H31: =일위대가!I287 -> 30034 | I31: =H31 -> 30034 | K31: =일위대가!L287 -> 63006 | L31: =K31 -> 63006 | M31: =일위대가!N287 -> 0 | N31: =M31 -> 0 | O31: =IF((H31+K31+M31)=0, "", (H31+K31+M31)) -> 93040 | P31: =SUM(I31,L31,N31) -> 93040
A32: 5695FIR0800 | B32: F5695F8R0800 | C32: 제 29호 | D32: 방화구획(내화충전) | E32: W 800 | F32: 개소 | H32: =일위대가!I293 -> 80178 | I32: =H32 -> 80178 | K32: =일위대가!L293 -> 168201 | L32: =K32 -> 168201 | M32: =일위대가!N293 -> 0 | N32: =M32 -> 0 | O32: =IF((H32+K32+M32)=0, "", (H32+K32+M32)) -> 248379 | P32: =SUM(I32,L32,N32) -> 248379
A33: 59751E67012 | B33: F59751467012 | C33: 제 30호 | D33: 경질비닐전선관 | E33: HI 16 mm | F33: M | H33: =일위대가!I301 -> 613 | I33: =H33 -> 613 | K33: =일위대가!L301 -> 12315 | L33: =K33 -> 12315 | M33: =일위대가!N301 -> 0 | N33: =M33 -> 0 | O33: =IF((H33+K33+M33)=0, "", (H33+K33+M33)) -> 12928 | P33: =SUM(I33,L33,N33) -> 12928
A34: 59751E67014 | B34: F59751467014 | C34: 제 31호 | D34: 경질비닐전선관 | E34: HI 28 mm | F34: M | H34: =일위대가!I309 -> 1269 | I34: =H34 -> 1269 | K34: =일위대가!L309 -> 19704 | L34: =K34 -> 19704 | M34: =일위대가!N309 -> 0 | N34: =M34 -> 0 | O34: =IF((H34+K34+M34)=0, "", (H34+K34+M34)) -> 20973 | P34: =SUM(I34,L34,N34) -> 20973
A35: 59751E67015 | B35: F59751467015 | C35: 제 32호 | D35: 경질비닐전선관 | E35: HI 36 mm | F35: M | H35: =일위대가!I317 -> 1751 | I35: =H35 -> 1751 | K35: =일위대가!L317 -> 24630 | L35: =K35 -> 24630 | M35: =일위대가!N317 -> 0 | N35: =M35 -> 0 | O35: =IF((H35+K35+M35)=0, "", (H35+K35+M35)) -> 26381 | P35: =SUM(I35,L35,N35) -> 26381
A36: 59751E67016 | B36: F59751467016 | C36: 제 33호 | D36: 경질비닐전선관 | E36: HI 42 mm | F36: M | H36: =일위대가!I325 -> 2196 | I36: =H36 -> 2196 | K36: =일위대가!L325 -> 32020 | L36: =K36 -> 32020 | M36: =일위대가!N325 -> 0 | N36: =M36 -> 0 | O36: =IF((H36+K36+M36)=0, "", (H36+K36+M36)) -> 34216 | P36: =SUM(I36,L36,N36) -> 34216
A37: 59753A97002 | B37: F59753097002 | C37: 제 34호 | D37: 합성수지제 가요전선관 | E37: CD-난연성 16㎜ | F37: M.. | H37: =일위대가!I333 -> 449 | I37: =H37 -> 449 | K37: =일위대가!L333 -> 9852 | L37: =K37 -> 9852 | M37: =일위대가!N333 -> 0 | N37: =M37 -> 0 | O37: =IF((H37+K37+M37)=0, "", (H37+K37+M37)) -> 10301 | P37: =SUM(I37,L37,N37) -> 10301
A38: 59753A97003 | B38: F59753097003 | C38: 제 35호 | D38: 합성수지제 가요전선관 | E38: CD-난연성 22㎜ | F38: M.. | H38: =일위대가!I341 -> 615 | I38: =H38 -> 615 | K38: =일위대가!L341 -> 11822 | L38: =K38 -> 11822 | M38: =일위대가!N341 -> 0 | N38: =M38 -> 0 | O38: =IF((H38+K38+M38)=0, "", (H38+K38+M38)) -> 12437 | P38: =SUM(I38,L38,N38) -> 12437
A39: 59753B78001 | B39: F59753178001 | C39: 제 36호 | D39: 파상형 폴리에틸렌 전선관 | E39: 30㎜ | F39: M | H39: =일위대가!I350 -> 502 | I39: =H39 -> 502 | K39: =일위대가!L350 -> 4898 | L39: =K39 -> 4898 | M39: =일위대가!N350 -> 0 | N39: =M39 -> 0 | O39: =IF((H39+K39+M39)=0, "", (H39+K39+M39)) -> 5400 | P39: =SUM(I39,L39,N39) -> 5400
A40: 59753B78002 | B40: F59753178002 | C40: 제 37호 | D40: 파상형 폴리에틸렌 전선관 | E40: 40㎜ | F40: M | H40: =일위대가!I359 -> 737 | I40: =H40 -> 737 | K40: =일위대가!L359 -> 6001 | L40: =K40 -> 6001 | M40: =일위대가!N359 -> 0 | N40: =M40 -> 0 | O40: =IF((H40+K40+M40)=0, "", (H40+K40+M40)) -> 6738 | P40: =SUM(I40,L40,N40) -> 6738
...

Sheet 일위대가
B1: 1511 | D1: [ 강릉시 입암동 통합공공임대주택 건립사업 신축공사 ] - 일위대가표 | W1: 노임 계산 정보 | AA1: 부속재 및 손료
A2: 번호 | B2: 목차코드 | C2: 코드 | D2: 명 칭 | E2: 규 격 | F2: 단위 | G2: 수량 | H2: 재료비 | J2: 노무비 | M2: 경비 | P2: 계 | Q2: 비고 | W2: 노임계 | X2: 전체(%) | Y2: 공종별(%) | Z2: 노임 소수 | AA2: CD배관재 | AB2: 일반배관재 | AC2: 소모재 | AD2: 자재계 | AE2: 노임계
H3: 단가 | I3: 금액 | J3: 수량 | K3: 단가 | L3: 금액 | M3: 단가 | N3: 금액 | O3: 단가 | AD3: 1 | AE3: 1
A4: 56930220020 | B4: 일목줄 | C4: ABB103200000 | D4: [제 1호] 터파기(기계80%,인력20%) 보통토사 [㎥]
A5: 56930210010 | B5: 제 1호 | C5: ABB111100000 | D5: 인력터파기 | E5: 보통토사0-1m | F5: ㎥_ | G5: 0.2 | H5: =일대목차!H216 -> 0 | I5: =IF(G5*H5<>0, TRUNC(G5*H5, 1), "") | J5: 0.2 | K5: =일대목차!K216 -> 34413 | L5: =IF(G5*K5<>0, TRUNC(G5*K5, 1), "") -> 6882.6 | M5: =일대목차!M216 -> 0 | N5: =IF(G5*M5<>0, TRUNC(G5*M5, 1), "") | O5: =IF((H5+K5+M5)=0, "", (H5+K5+M5)) -> 34413 | P5: =IF(SUM(I5,L5,N5)<>0,SUM(I5,L5,N5),"") -> 6882.6 | Q5: 제 213호 | R5: ILD
A6: CA565826042 | B6: 제 1호 | C6: ECA565826042 | D6: 기계터파기 | E6: 보통토사(0.6㎥/43.6) | F6: ㎥ | G6: 0.8 | H6: =합산자재!H338 -> 427 | I6: =IF(G6*H6<>0, TRUNC(G6*H6, 1), "") -> 341.6 | J6: 0.8 | K6: =합산자재!I338 -> 1309 | L6: =IF(G6*K6<>0, TRUNC(G6*K6, 1), "") -> 1047.2 | M6: =합산자재!J338 -> 523 | N6: =IF(G6*M6<>0, TRUNC(G6*M6, 1), "") -> 418.4 | O6: =IF((H6+K6+M6)=0, "", (H6+K6+M6)) -> 2259 | P6: =IF(SUM(I6,L6,N6)<>0,SUM(I6,L6,N6),"") -> 1807.2 | Q6: 182-하 | R6: ILD
B7: 합계줄 | D7: ( 합 계 ) | I7: =TRUNC(SUM(I4:I6)) -> 341 | L7: =TRUNC(SUM(L4:L6)) -> 7929 | N7: =TRUNC(SUM(N4:N6)) -> 418 | O7: =IF((H7+K7+M7)=0, "", (H7+K7+M7)) | P7: =IF(SUM(I7,L7,N7)<>0,SUM(I7,L7,N7),"") -> 8688
A9: 56930220052 | B9: 일목줄 | C9: ABB104200000 | D9: [제 2호] 되메우기(기계80%,인력20%) 보통토사 [㎥]
A10: 56930210021 | B10: 제 2호 | C10: ABD100001000 | D10: 인력되메우기 | E10: 보통토사0-1m | F10: ㎥_ | G10: 0.2 | H10: =일대목차!H217 -> 0 | I10: =IF(G10*H10<>0, TRUNC(G10*H10, 1), "") | J10: 0.2 | K10: =일대목차!K217 -> 17206 | L10: =IF(G10*K10<>0, TRUNC(G10*K10, 1), "") -> 3441.2 | M10: =일대목차!M217 -> 0 | N10: =IF(G10*M10<>0, TRUNC(G10*M10, 1), "") | O10: =IF((H10+K10+M10)=0, "", (H10+K10+M10)) -> 17206 | P10: =IF(SUM(I10,L10,N10)<>0,SUM(I10,L10,N10),"") -> 3441.2 | Q10: 제 214호 | R10: ILD
A11: CA565826051 | B11: 제 2호 | C11: ECA565826051 | D11: 기계되메우기 | E11: 보통토사(0.6㎥/43.6) | F11: ㎥ | G11: 0.8 | H11: =합산자재!H339 -> 427 | I11: =IF(G11*H11<>0, TRUNC(G11*H11, 1), "") -> 341.6 | J11: 0.8 | K11: =합산자재!I339 -> 1309 | L11: =IF(G11*K11<>0, TRUNC(G11*K11, 1), "") -> 1047.2 | M11: =합산자재!J339 -> 523 | N11: =IF(G11*M11<>0, TRUNC(G11*M11, 1), "") -> 418.4 | O11: =IF((H11+K11+M11)=0, "", (H11+K11+M11)) -> 2259 | P11: =IF(SUM(I11,L11,N11)<>0,SUM(I11,L11,N11),"") -> 1807.2 | Q11: 187-하 | R11: ILD
B12: 합계줄 | D12: ( 합 계 ) | I12: =TRUNC(SUM(I9:I11)) -> 341 | L12: =TRUNC(SUM(L9:L11)) -> 4488 | N12: =TRUNC(SUM(N9:N11)) -> 418 | O12: =IF((H12+K12+M12)=0, "", (H12+K12+M12)) | P12: =IF(SUM(I12,L12,N12)<>0,SUM(I12,L12,N12),"") -> 5247
A14: 56950120016 | B14: 일목줄 | C14: EAA110110000 | D14: [제 3호] 파이프행가 16 C [식]
A15: 59759017111 | B15: 제 3호 | C15: 3913170810036357 | D15: 강재전선관용 부품 | E15: 파이프행거, 16 C | F15: 개 | G15: 1 | H15: =합산자재!H82 -> 343 | I15: =IF(G15*H15<>0, TRUNC(G15*H15, 1), "") -> 343 | J15: 1 | K15: =합산자재!I82 -> 0 | L15: =IF(G15*K15<>0, TRUNC(G15*K15, 1), "") | M15: =합산자재!J82 -> 0 | N15: =IF(G15*M15<>0, TRUNC(G15*M15, 1), "") | O15: =IF((H15+K15+M15)=0, "", (H15+K15+M15)) -> 343 | P15: =IF(SUM(I15,L15,N15)<>0,SUM(I15,L15,N15),"") -> 343
A16: 53060327011 | B16: 제 3호 | C16: 3116169820135160 | D16: 행거볼트 | E16: M10×1000㎜ | F16: 개 | G16: 1 | H16: =합산자재!H91 -> 920 | I16: =IF(G16*H16<>0, TRUNC(G16*H16, 1), "") -> 920 | J16: 1 | K16: =합산자재!I91 -> 0 | L16: =IF(G16*K16<>0, TRUNC(G16*K16, 1), "") | M16: =합산자재!J91 -> 0 | N16: =IF(G16*M16<>0, TRUNC(G16*M16, 1), "") | O16: =IF((H16+K16+M16)=0, "", (H16+K16+M16)) -> 920 | P16: =IF(SUM(I16,L16,N16)<>0,SUM(I16,L16,N16),"") -> 920
A17: 53060807001 | B17: 제 3호 | C17: 3116210220135769 | D17: 스트롱앵커(내진) | E17: 3/8 | F17: 개 | G17: 1 | H17: =합산자재!H90 -> 18000 | I17: =IF(G17*H17<>0, TRUNC(G17*H17, 1), "") -> 18000 | J17: 1 | K17: =합산자재!I90 -> 0 | L17: =IF(G17*K17<>0, TRUNC(G17*K17, 1), "") | M17: =합산자재!J90 -> 0 | N17: =IF(G17*M17<>0, TRUNC(G17*M17, 1), "") | O17: =IF((H17+K17+M17)=0, "", (H17+K17+M17)) -> 18000 | P17: =IF(SUM(I17,L17,N17)<>0,SUM(I17,L17,N17),"") -> 18000
A18: 53100028501 | B18: 제 3호 | C18: 3116172710023970 | D18: 6각너트 | E18: 3/8,M10 | F18: EA | G18: 2 | H18: =합산자재!H173 -> 28 | I18: =IF(G18*H18<>0, TRUNC(G18*H18, 1), "") -> 56 | J18: 2 | K18: =합산자재!I173 -> 0 | L18: =IF(G18*K18<>0, TRUNC(G18*K18, 1), "") | M18: =합산자재!J173 -> 0 | N18: =IF(G18*M18<>0, TRUNC(G18*M18, 1), "") | O18: =IF((H18+K18+M18)=0, "", (H18+K18+M18)) -> 28 | P18: =IF(SUM(I18,L18,N18)<>0,SUM(I18,L18,N18),"") -> 56
A19: 52100327001 | B19: 제 3호 | C19: 3116181120136195 | D19: 스프링와샤 | E19: D10 | F19: EA | G19: 2 | H19: =합산자재!H174 -> 9 | I19: =IF(G19*H19<>0, TRUNC(G19*H19, 1), "") -> 18 | J19: 2 | K19: =합산자재!I174 -> 0 | L19: =IF(G19*K19<>0, TRUNC(G19*K19, 1), "") | M19: =합산자재!J174 -> 0 | N19: =IF(G19*M19<>0, TRUNC(G19*M19, 1), "") | O19: =IF((H19+K19+M19)=0, "", (H19+K19+M19)) -> 9 | P19: =IF(SUM(I19,L19,N19)<>0,SUM(I19,L19,N19),"") -> 18
A20: 56900017016 | B20: 제 3호 | C20: L001010101000075 | D20: 노 무 비 | E20: 내선전공 | F20: 인 | G20: =일위노임!G6 -> 0.036 | H20: =합산자재!H345 -> 0 | I20: =IF(G20*H20<>0, TRUNC(G20*H20, 1), "") | J20: 0.036 | K20: =합산자재!I345 -> 273676 | L20: =IF(G20*K20<>0, TRUNC(G20*K20, 1), "") -> 9852.3 | M20: =합산자재!J345 -> 0 | N20: =IF(G20*M20<>0, TRUNC(G20*M20, 1), "") | O20: =IF((H20+K20+M20)=0, "", (H20+K20+M20)) -> 273676 | P20: =IF(SUM(I20,L20,N20)<>0,SUM(I20,L20,N20),"") -> 9852.3
A21: A0300000000 | B21: 제 3호 | C21: RENT000000000006 | D21: [ 공 구 손 료 ] | E21: 노무비의 2 % | F21: 식 | G21: 1 | H21: 197 | I21: =IF(G21*H21<>0, TRUNC(G21*H21, 1), "") -> 197 | J21: 1 | L21: =IF(G21*K21<>0, TRUNC(G21*K21, 1), "") | N21: =IF(G21*M21<>0, TRUNC(G21*M21, 1), "") | O21: =IF((H21+K21+M21)=0, "", (H21+K21+M21)) -> 197 | P21: =IF(SUM(I21,L21,N21)<>0,SUM(I21,L21,N21),"") -> 197
B22: 합계줄 | D22: ( 합 계 ) | I22: =TRUNC(SUM(I14:I21)) -> 19534 | L22: =TRUNC(SUM(L14:L21)) -> 9852 | N22: =TRUNC(SUM(N14:N21)) -> 0 | O22: =IF((H22+K22+M22)=0, "", (H22+K22+M22)) | P22: =IF(SUM(I22,L22,N22)<>0,SUM(I22,L22,N22),"") -> 29386
A24: 56950120022 | B24: 일목줄 | C24: EAA110120000 | D24: [제 4호] 파이프행가 22 C [식]
A25: 59759017112 | B25: 제 4호 | C25: 3913170810036358 | D25: 강재전선관용 부품 | E25: 파이프행거, 22 C | F25: 개 | G25: 1 | H25: =합산자재!H83 -> 348 | I25: =IF(G25*H25<>0, TRUNC(G25*H25, 1), "") -> 348 | J25: 1 | K25: =합산자재!I83 -> 0 | L25: =IF(G25*K25<>0, TRUNC(G25*K25, 1), "") | M25: =합산자재!J83 -> 0 | N25: =IF(G25*M25<>0, TRUNC(G25*M25, 1), "") | O25: =IF((H25+K25+M25)=0, "", (H25+K25+M25)) -> 348 | P25: =IF(SUM(I25,L25,N25)<>0,SUM(I25,L25,N25),"") -> 348
A26: 53060327011 | B26: 제 4호 | C26: 3116169820135160 | D26: 행거볼트 | E26: M10×1000㎜ | F26: 개 | G26: 1 | H26: =합산자재!H91 -> 920 | I26: =IF(G26*H26<>0, TRUNC(G26*H26, 1), "") -> 920 | J26: 1 | K26: =합산자재!I91 -> 0 | L26: =IF(G26*K26<>0, TRUNC(G26*K26, 1), "") | M26: =합산자재!J91 -> 0 | N26: =IF(G26*M26<>0, TRUNC(G26*M26, 1), "") | O26: =IF((H26+K26+M26)=0, "", (H26+K26+M26)) -> 920 | P26: =IF(SUM(I26,L26,N26)<>0,SUM(I26,L26,N26),"") -> 920
A27: 53060807001 | B27: 제 4호 | C27: 3116210220135769 | D27: 스트롱앵커(내진) | E27: 3/8 | F27: 개 | G27: 1 | H27: =합산자재!H90 -> 18000 | I27: =IF(G27*H27<>0, TRUNC(G27*H27, 1), "") -> 18000 | J27: 1 | K27: =합산자재!I90 -> 0 | L27: =IF(G27*K27<>0, TRUNC(G27*K27, 1), "") | M27: =합산자재!J90 -> 0 | N27: =IF(G27*M27<>0, TRUNC(G27*M27, 1), "") | O27: =IF((H27+K27+M27)=0, "", (H27+K27+M27)) -> 18000 | P27: =IF(SUM(I27,L27,N27)<>0,SUM(I27,L27,N27),"") -> 18000
A28: 53100028501 | B28: 제 4호 | C28: 3116172710023970 | D28: 6각너트 | E28: 3/8,M10 | F28: EA | G28: 2 | H28: =합산자재!H173 -> 28 | I28: =IF(G28*H28<>0, TRUNC(G28*H28, 1), "") -> 56 | J28: 2 | K28: =합산자재!I173 -> 0 | L28: =IF(G28*K28<>0, TRUNC(G28*K28, 1), "") | M28: =합산자재!J173 -> 0 | N28: =IF(G28*M28<>0, TRUNC(G28*M28, 1), "") | O28: =IF((H28+K28+M28)=0, "", (H28+K28+M28)) -> 28 | P28: =IF(SUM(I28,L28,N28)<>0,SUM(I28,L28,N28),"") -> 56
A29: 52100327001 | B29: 제 4호 | C29: 3116181120136195 | D29: 스프링와샤 | E29: D10 | F29: EA | G29: 2 | H29: =합산자재!H174 -> 9 | I29: =IF(G29*H29<>0, TRUNC(G29*H29, 1), "") -> 18 | J29: 2 | K29: =합산자재!I174 -> 0 | L29: =IF(G29*K29<>0, TRUNC(G29*K29, 1), "") | M29: =합산자재!J174 -> 0 | N29: =IF(G29*M29<>0, TRUNC(G29*M29, 1), "") | O29: =IF((H29+K29+M29)=0, "", (H29+K29+M29)) -> 9 | P29: =IF(SUM(I29,L29,N29)<>0,SUM(I29,L29,N29),"") -> 18
A30: 56900017016 | B30: 제 4호 | C30: L001010101000075 | D30: 노 무 비 | E30: 내선전공 | F30: 인 | G30: =일위노임!G9 -> 0.036 | H30: =합산자재!H345 -> 0 | I30: =IF(G30*H30<>0, TRUNC(G30*H30, 1), "") | J30: 0.036 | K30: =합산자재!I345 -> 273676 | L30: =IF(G30*K30<>0, TRUNC(G30*K30, 1), "") -> 9852.3 | M30: =합산자재!J345 -> 0 | N30: =IF(G30*M30<>0, TRUNC(G30*M30, 1), "") | O30: =IF((H30+K30+M30)=0, "", (H30+K30+M30)) -> 273676 | P30: =IF(SUM(I30,L30,N30)<>0,SUM(I30,L30,N30),"") -> 9852.3
A31: A0300000000 | B31: 제 4호 | C31: RENT000000000006 | D31: [ 공 구 손 료 ] | E31: 노무비의 2 % | F31: 식 | G31: 1 | H31: 197 | I31: =IF(G31*H31<>0, TRUNC(G31*H31, 1), "") -> 197 | J31: 1 | L31: =IF(G31*K31<>0, TRUNC(G31*K31, 1), "") | N31: =IF(G31*M31<>0, TRUNC(G31*M31, 1), "") | O31: =IF((H31+K31+M31)=0, "", (H31+K31+M31)) -> 197 | P31: =IF(SUM(I31,L31,N31)<>0,SUM(I31,L31,N31),"") -> 197
B32: 합계줄 | D32: ( 합 계 ) | I32: =TRUNC(SUM(I24:I31)) -> 19539 | L32: =TRUNC(SUM(L24:L31)) -> 9852 | N32: =TRUNC(SUM(N24:N31)) -> 0 | O32: =IF((H32+K32+M32)=0, "", (H32+K32+M32)) | P32: =IF(SUM(I32,L32,N32)<>0,SUM(I32,L32,N32),"") -> 29391
A34: 56950120028 | B34: 일목줄 | C34: EAA110130000 | D34: [제 5호] 파이프행가 28 C [식]
A35: 59759017113 | B35: 제 5호 | C35: 3913170810036359 | D35: 강재전선관용 부품 | E35: 파이프행거, 28 C | F35: 개 | G35: 1 | H35: =합산자재!H84 -> 370 | I35: =IF(G35*H35<>0, TRUNC(G35*H35, 1), "") -> 370 | J35: 1 | K35: =합산자재!I84 -> 0 | L35: =IF(G35*K35<>0, TRUNC(G35*K35, 1), "") | M35: =합산자재!J84 -> 0 | N35: =IF(G35*M35<>0, TRUNC(G35*M35, 1), "") | O35: =IF((H35+K35+M35)=0, "", (H35+K35+M35)) -> 370 | P35: =IF(SUM(I35,L35,N35)<>0,SUM(I35,L35,N35),"") -> 370
A36: 53060327011 | B36: 제 5호 | C36: 3116169820135160 | D36: 행거볼트 | E36: M10×1000㎜ | F36: 개 | G36: 1 | H36: =합산자재!H91 -> 920 | I36: =IF(G36*H36<>0, TRUNC(G36*H36, 1), "") -> 920 | J36: 1 | K36: =합산자재!I91 -> 0 | L36: =IF(G36*K36<>0, TRUNC(G36*K36, 1), "") | M36: =합산자재!J91 -> 0 | N36: =IF(G36*M36<>0, TRUNC(G36*M36, 1), "") | O36: =IF((H36+K36+M36)=0, "", (H36+K36+M36)) -> 920 | P36: =IF(SUM(I36,L36,N36)<>0,SUM(I36,L36,N36),"") -> 920
A37: 53060807001 | B37: 제 5호 | C37: 3116210220135769 | D37: 스트롱앵커(내진) | E37: 3/8 | F37: 개 | G37: 1 | H37: =합산자재!H90 -> 18000 | I37: =IF(G37*H37<>0, TRUNC(G37*H37, 1), "") -> 18000 | J37: 1 | K37: =합산자재!I90 -> 0 | L37: =IF(G37*K37<>0, TRUNC(G37*K37, 1), "") | M37: =합산자재!J90 -> 0 | N37: =IF(G37*M37<>0, TRUNC(G37*M37, 1), "") | O37: =IF((H37+K37+M37)=0, "", (H37+K37+M37)) -> 18000 | P37: =IF(SUM(I37,L37,N37)<>0,SUM(I37,L37,N37),"") -> 18000
A38: 53100028501 | B38: 제 5호 | C38: 3116172710023970 | D38: 6각너트 | E38: 3/8,M10 | F38: EA | G38: 2 | H38: =합산자재!H173 -> 28 | I38: =IF(G38*H38<>0, TRUNC(G38*H38, 1), "") -> 56 | J38: 2 | K38: =합산자재!I173 -> 0 | L38: =IF(G38*K38<>0, TRUNC(G38*K38, 1), "") | M38: =합산자재!J173 -> 0 | N38: =IF(G38*M38<>0, TRUNC(G38*M38, 1), "") | O38: =IF((H38+K38+M38)=0, "", (H38+K38+M38)) -> 28 | P38: =IF(SUM(I38,L38,N38)<>0,SUM(I38,L38,N38),"") -> 56
A39: 52100327001 | B39: 제 5호 | C39: 3116181120136195 | D39: 스프링와샤 | E39: D10 | F39: EA | G39: 2 | H39: =합산자재!H174 -> 9 | I39: =IF(G39*H39<>0, TRUNC(G39*H39, 1), "") -> 18 | J39: 2 | K39: =합산자재!I174 -> 0 | L39: =IF(G39*K39<>0, TRUNC(G39*K39, 1), "") | M39: =합산자재!J174 -> 0 | N39: =IF(G39*M39<>0, TRUNC(G39*M39, 1), "") | O39: =IF((H39+K39+M39)=0, "", (H39+K39+M39)) -> 9 | P39: =IF(SUM(I39,L39,N39)<>0,SUM(I39,L39,N39),"") -> 18
A40: 56900017016 | B40: 제 5호 | C40: L001010101000075 | D40: 노 무 비 | E40: 내선전공 | F40: 인 | G40: =일위노임!G12 -> 0.036 | H40: =합산자재!H345 -> 0 | I40: =IF(G40*H40<>0, TRUNC(G40*H40, 1), "") | J40: 0.036 | K40: =합산자재!I345 -> 273676 | L40: =IF(G40*K40<>0, TRUNC(G40*K40, 1), "") -> 9852.3 | M40: =합산자재!J345 -> 0 | N40: =IF(G40*M40<>0, TRUNC(G40*M40, 1), "") | O40: =IF((H40+K40+M40)=0, "", (H40+K40+M40)) -> 273676 | P40: =IF(SUM(I40,L40,N40)<>0,SUM(I40,L40,N40),"") -> 9852.3
A41: A0300000000 | B41: 제 5호 | C41: RENT000000000006 | D41: [ 공 구 손 료 ] | E41: 노무비의 2 % | F41: 식 | G41: 1 | H41: 197 | I41: =IF(G41*H41<>0, TRUNC(G41*H41, 1), "") -> 197 | J41: 1 | L41: =IF(G41*K41<>0, TRUNC(G41*K41, 1), "") | N41: =IF(G41*M41<>0, TRUNC(G41*M41, 1), "") | O41: =IF((H41+K41+M41)=0, "", (H41+K41+M41)) -> 197 | P41: =IF(SUM(I41,L41,N41)<>0,SUM(I41,L41,N41),"") -> 197
B42: 합계줄 | D42: ( 합 계 ) | I42: =TRUNC(SUM(I34:I41)) -> 19561 | L42: =TRUNC(SUM(L34:L41)) -> 9852 | N42: =TRUNC(SUM(N34:N41)) -> 0 | O42: =IF((H42+K42+M42)=0, "", (H42+K42+M42)) | P42: =IF(SUM(I42,L42,N42)<>0,SUM(I42,L42,N42),"") -> 29413
A44: 56950120036 | B44: 일목줄 | C44: EAA110140000 | D44: [제 6호] 파이프행가 36 C [식]
A45: 59759017114 | B45: 제 6호 | C45: 3913170810036360 | D45: 강재전선관용 부품 | E45: 파이프행거, 36 C | F45: 개 | G45: 1 | H45: =합산자재!H85 -> 394 | I45: =IF(G45*H45<>0, TRUNC(G45*H45, 1), "") -> 394 | J45: 1 | K45: =합산자재!I85 -> 0 | L45: =IF(G45*K45<>0, TRUNC(G45*K45, 1), "") | M45: =합산자재!J85 -> 0 | N45: =IF(G45*M45<>0, TRUNC(G45*M45, 1), "") | O45: =IF((H45+K45+M45)=0, "", (H45+K45+M45)) -> 394 | P45: =IF(SUM(I45,L45,N45)<>0,SUM(I45,L45,N45),"") -> 394
...

Sheet 일위노임
B1: 705 | D1: [ 강릉시 입암동 통합공공임대주택 건립사업 신축공사 ] - 일위노임 산출근거(202601-노임) | AA1: 내선전공 | AB1: 저압케이블전공 | AC1: 고압케이블전공 | AD1: 특고압케이블전공 | AE1: 배전전공 | AF1: 통신케이블공 | AG1: 통신외선공 | AH1: 보통인부 | AI1: 특별인부 | AJ1: 방수공 | AK1: 줄눈공 | AL1: 작업반장
A2: 번호 | B2: 공종코드 | C2: 코드 | D2: 명 칭 | E2: 규 격 | F2: 단위 | G2: 수량 | K2: 코드 | L2: 공량산출 | P2: 단 위 단 가 산 출 | S2: 품셈근거 | T2: 비고
G3: 결정수량 | H3: 할증 | I3: 산출수량 | J3: 재할% | L3: 명칭 | M3: 품셈 | N3: 할증% | O3: 공량 | P3: 단가 | Q3: 단위단가 | R3: 단위계
B4: 공종줄 | D4: [ 제 3호 ] 파이프행가 16 C [식]
B5: 800 | C5: 3116210220135769 | D5: 스트롱앵커(내진) | E5: 3/8 | F5: 개 | G5: 1 | H5: =IF(I5<>0, G5-I5, "") -> 0 | I5: 1 | K5: 56900017016 | L5: 내선전공 | M5: 0.036 | N5: 100 | O5: =IF(I5*M5=0, "", I5*M5*(N5/100)) -> 0.036 | Q5: =TRUNC(P5*M5*N5/100) -> 0 | S5: 전기5-29 | AA5: =O5 -> 0.036
B6: 800 | C6: L001010101000075 | D6: 노 무 비 | E6: 내선전공 | F6: 인 | G6: =IF(H6*I6/100+0.000005 <1, TRUNC(H6*I6/100+0.000005, 옵션!$E$13), TRUNC(H6*I6/100+0.000005, 옵션!$E$13)) -> 0.036 | H6: =옵션!$B$13 -> 100 | I6: =SUM(AA5:AA5) -> 0.036 | O6: =IF(I6*M6=0, "", I6*M6*(N6/100)) | Q6: =TRUNC(P6*M6*N6/100) -> 0 | Z6: 노임계 | AA6: =SUM(AA5:AA5) -> 0.036
B7: 공종줄 | D7: [ 제 4호 ] 파이프행가 22 C [식]
B8: 800 | C8: 3116210220135769 | D8: 스트롱앵커(내진) | E8: 3/8 | F8: 개 | G8: 1 | H8: =IF(I8<>0, G8-I8, "") -> 0 | I8: 1 | K8: 56900017016 | L8: 내선전공 | M8: 0.036 | N8: 100 | O8: =IF(I8*M8=0, "", I8*M8*(N8/100)) -> 0.036 | Q8: =TRUNC(P8*M8*N8/100) -> 0 | S8: 전기5-29 | AA8: =O8 -> 0.036
B9: 800 | C9: L001010101000075 | D9: 노 무 비 | E9: 내선전공 | F9: 인 | G9: =IF(H9*I9/100+0.000005 <1, TRUNC(H9*I9/100+0.000005, 옵션!$E$13), TRUNC(H9*I9/100+0.000005, 옵션!$E$13)) -> 0.036 | H9: =옵션!$B$13 -> 100 | I9: =SUM(AA8:AA8) -> 0.036 | O9: =IF(I9*M9=0, "", I9*M9*(N9/100)) | Q9: =TRUNC(P9*M9*N9/100) -> 0 | Z9: 노임계 | AA9: =SUM(AA8:AA8) -> 0.036
B10: 공종줄 | D10: [ 제 5호 ] 파이프행가 28 C [식]
B11: 800 | C11: 3116210220135769 | D11: 스트롱앵커(내진) | E11: 3/8 | F11: 개 | G11: 1 | H11: =IF(I11<>0, G11-I11, "") -> 0 | I11: 1 | K11: 56900017016 | L11: 내선전공 | M11: 0.036 | N11: 100 | O11: =IF(I11*M11=0, "", I11*M11*(N11/100)) -> 0.036 | Q11: =TRUNC(P11*M11*N11/100) -> 0 | S11: 전기5-29 | AA11: =O11 -> 0.036
B12: 800 | C12: L001010101000075 | D12: 노 무 비 | E12: 내선전공 | F12: 인 | G12: =IF(H12*I12/100+0.000005 <1, TRUNC(H12*I12/100+0.000005, 옵션!$E$13), TRUNC(H12*I12/100+0.000005, 옵션!$E$13)) -> 0.036 | H12: =옵션!$B$13 -> 100 | I12: =SUM(AA11:AA11) -> 0.036 | O12: =IF(I12*M12=0, "", I12*M12*(N12/100)) | Q12: =TRUNC(P12*M12*N12/100) -> 0 | Z12: 노임계 | AA12: =SUM(AA11:AA11) -> 0.036
B13: 공종줄 | D13: [ 제 6호 ] 파이프행가 36 C [식]
B14: 800 | C14: 3116210220135769 | D14: 스트롱앵커(내진) | E14: 3/8 | F14: 개 | G14: 1 | H14: =IF(I14<>0, G14-I14, "") -> 0 | I14: 1 | K14: 56900017016 | L14: 내선전공 | M14: 0.036 | N14: 100 | O14: =IF(I14*M14=0, "", I14*M14*(N14/100)) -> 0.036 | Q14: =TRUNC(P14*M14*N14/100) -> 0 | S14: 전기5-29 | AA14: =O14 -> 0.036
B15: 800 | C15: L001010101000075 | D15: 노 무 비 | E15: 내선전공 | F15: 인 | G15: =IF(H15*I15/100+0.000005 <1, TRUNC(H15*I15/100+0.000005, 옵션!$E$13), TRUNC(H15*I15/100+0.000005, 옵션!$E$13)) -> 0.036 | H15: =옵션!$B$13 -> 100 | I15: =SUM(AA14:AA14) -> 0.036 | O15: =IF(I15*M15=0, "", I15*M15*(N15/100)) | Q15: =TRUNC(P15*M15*N15/100) -> 0 | Z15: 노임계 | AA15: =SUM(AA14:AA14) -> 0.036
B16: 공종줄 | D16: [ 제 7호 ] 파이프행가 42 C [식]
B17: 800 | C17: 3116210220135769 | D17: 스트롱앵커(내진) | E17: 3/8 | F17: 개 | G17: 1 | H17: =IF(I17<>0, G17-I17, "") -> 0 | I17: 1 | K17: 56900017016 | L17: 내선전공 | M17: 0.036 | N17: 100 | O17: =IF(I17*M17=0, "", I17*M17*(N17/100)) -> 0.036 | Q17: =TRUNC(P17*M17*N17/100) -> 0 | S17: 전기5-29 | AA17: =O17 -> 0.036
B18: 800 | C18: L001010101000075 | D18: 노 무 비 | E18: 내선전공 | F18: 인 | G18: =IF(H18*I18/100+0.000005 <1, TRUNC(H18*I18/100+0.000005, 옵션!$E$13), TRUNC(H18*I18/100+0.000005, 옵션!$E$13)) -> 0.036 | H18: =옵션!$B$13 -> 100 | I18: =SUM(AA17:AA17) -> 0.036 | O18: =IF(I18*M18=0, "", I18*M18*(N18/100)) | Q18: =TRUNC(P18*M18*N18/100) -> 0 | Z18: 노임계 | AA18: =SUM(AA17:AA17) -> 0.036
B19: 공종줄 | D19: [ 제 8호 ] 파이프행가 54 C [식]
B20: 800 | C20: 3116210220135769 | D20: 스트롱앵커(내진) | E20: 3/8 | F20: 개 | G20: 1 | H20: =IF(I20<>0, G20-I20, "") -> 0 | I20: 1 | K20: 56900017016 | L20: 내선전공 | M20: 0.036 | N20: 100 | O20: =IF(I20*M20=0, "", I20*M20*(N20/100)) -> 0.036 | Q20: =TRUNC(P20*M20*N20/100) -> 0 | S20: 전기5-29 | AA20: =O20 -> 0.036
B21: 800 | C21: L001010101000075 | D21: 노 무 비 | E21: 내선전공 | F21: 인 | G21: =IF(H21*I21/100+0.000005 <1, TRUNC(H21*I21/100+0.000005, 옵션!$E$13), TRUNC(H21*I21/100+0.000005, 옵션!$E$13)) -> 0.036 | H21: =옵션!$B$13 -> 100 | I21: =SUM(AA20:AA20) -> 0.036 | O21: =IF(I21*M21=0, "", I21*M21*(N21/100)) | Q21: =TRUNC(P21*M21*N21/100) -> 0 | Z21: 노임계 | AA21: =SUM(AA20:AA20) -> 0.036
B22: 공종줄 | D22: [ 제 9호 ] 파이프행가 70 C [식]
B23: 800 | C23: 3116210220135769 | D23: 스트롱앵커(내진) | E23: 3/8 | F23: 개 | G23: 1 | H23: =IF(I23<>0, G23-I23, "") -> 0 | I23: 1 | K23: 56900017016 | L23: 내선전공 | M23: 0.036 | N23: 100 | O23: =IF(I23*M23=0, "", I23*M23*(N23/100)) -> 0.036 | Q23: =TRUNC(P23*M23*N23/100) -> 0 | S23: 전기5-29 | AA23: =O23 -> 0.036
B24: 800 | C24: L001010101000075 | D24: 노 무 비 | E24: 내선전공 | F24: 인 | G24: =IF(H24*I24/100+0.000005 <1, TRUNC(H24*I24/100+0.000005, 옵션!$E$13), TRUNC(H24*I24/100+0.000005, 옵션!$E$13)) -> 0.036 | H24: =옵션!$B$13 -> 100 | I24: =SUM(AA23:AA23) -> 0.036 | O24: =IF(I24*M24=0, "", I24*M24*(N24/100)) | Q24: =TRUNC(P24*M24*N24/100) -> 0 | Z24: 노임계 | AA24: =SUM(AA23:AA23) -> 0.036
B25: 공종줄 | D25: [ 제 10호 ] 케이블트레이지지대 W200-1단 [식]
B26: 800 | C26: 3116210220135769 | D26: 스트롱앵커(내진) | E26: 3/8 | F26: 개 | G26: 2 | H26: =IF(I26<>0, G26-I26, "") -> 0 | I26: 2 | K26: 56900017016 | L26: 내선전공 | M26: 0.036 | N26: 100 | O26: =IF(I26*M26=0, "", I26*M26*(N26/100)) -> 0.072 | Q26: =TRUNC(P26*M26*N26/100) -> 0 | S26: 전기5-29 | AA26: =O26 -> 0.072
B27: 800 | C27: L001010101000075 | D27: 노 무 비 | E27: 내선전공 | F27: 인 | G27: =IF(H27*I27/100+0.000005 <1, TRUNC(H27*I27/100+0.000005, 옵션!$E$13), TRUNC(H27*I27/100+0.000005, 옵션!$E$13)) -> 0.072 | H27: =옵션!$B$13 -> 100 | I27: =SUM(AA26:AA26) -> 0.072 | O27: =IF(I27*M27=0, "", I27*M27*(N27/100)) | Q27: =TRUNC(P27*M27*N27/100) -> 0 | Z27: 노임계 | AA27: =SUM(AA26:AA26) -> 0.072
B28: 공종줄 | D28: [ 제 11호 ] 케이블트레이지지대 W300-1단 [식]
