Workbook
Name _: #REF!
Name __________________q45: {"'용역비'!$A$4:$C$8"}
Name __________________q45: {"'용역비'!$A$4:$C$8"}
Name __________________q45: {"'용역비'!$A$4:$C$8"}
Name __________________q45: {"'용역비'!$A$4:$C$8"}
Name _________________q45: {"'용역비'!$A$4:$C$8"}
Name _________________q45: {"'용역비'!$A$4:$C$8"}
Name _________________q45: {"'용역비'!$A$4:$C$8"}
Name _________________q45: {"'용역비'!$A$4:$C$8"}
Name ________________q45: {"'용역비'!$A$4:$C$8"}
Name ________________q45: {"'용역비'!$A$4:$C$8"}
Name ________________q45: {"'용역비'!$A$4:$C$8"}
Name ________________q45: {"'용역비'!$A$4:$C$8"}
Name _______________q45: {"'용역비'!$A$4:$C$8"}
Name _______________q45: {"'용역비'!$A$4:$C$8"}
Name _______________q45: {"'용역비'!$A$4:$C$8"}
Name _______________q45: {"'용역비'!$A$4:$C$8"}
Name ______________q45: {"'용역비'!$A$4:$C$8"}
Name ______________q45: {"'용역비'!$A$4:$C$8"}
Name ______________q45: {"'용역비'!$A$4:$C$8"}
Name ______________q45: {"'용역비'!$A$4:$C$8"}
Name _____________q45: {"'용역비'!$A$4:$C$8"}
Name _________a32767: #REF!
Name _________cbl2: #REF!
Name _________cbl3: #REF!
Name _________cbl4: #REF!
Name _________cbl5: #REF!
Name _________CSU2: #REF!
Name _________CSU3: #REF!
Name _________FDM2: #REF!
Name _________FDM4: #REF!
Name _________FDM6: #REF!
Name _________FDM8: #REF!
Name _________fkn1: #REF!
Name _________fkn2: #REF!
Name _________fks1: #REF!
Name _________fks2: #REF!
Name _________gbi1: #REF!
Name _________gbi2: #REF!
Name _________gbi3: #REF!
Name _________gbi4: #REF!
Name _________gbi5: #REF!
Name _________gbi6: #REF!
Name _________gbi7: #REF!
Name _________gbi8: #REF!
Name _________gbi9: #REF!
Name _________IDF1: #REF!
Name _________ind1: #REF!
Name _________ind11: #REF!
Name _________ind12: #REF!
Name _________ind13: #REF!
Name _________ind14: #REF!
Name _________ind15: #REF!
Name _________ind16: #REF!
Name _________ind17: #REF!
Name _________ind18: #REF!
Name _________ind19: #REF!
Name _________ind2: #REF!
Name _________ind21: #REF!
Name _________ind23: #REF!

Sheet 표지
A13: ='3.공사비총괄표'!A4 -> 공사명 : 동해안#1 변환소 전력통신설비 시설공사
A24: 2025. 09
C29: 결 재 | D29: 담 당 | E29: 차 장 | F29: 부 장
A42: HVDC건설본부 전자통신부

Sheet 목차
B7: ='1.공사계획서'!A2 -> 1. 공 사 계 획 서
B9: ='2.공사설명서'!A2 -> 2. 공 사 설 명 서
B11: ='3.공사비총괄표'!A2 -> 3. 공 사 비 총 괄 표
B13: ='4.자금계획서'!A2 -> 4. 자 금 계 획 서
B15: ='5.예정공정표'!A2 -> 5. 예 정 공 정 표
B17: ='6.공사비예산서'!B2 -> 6. 공 사 비 예 산 서
B19: ='7.설계명세서'!A2 -> 7. 설 계 명 세 서
B21: 8. 설 비 자 재 산 출
B23: ='9.시방서표지'!A3 -> 9. 공 사 시 방 서
B25: ='10.시설도면'!A3 -> 10. 시 설 도 면

Sheet 1.공사계획서
A2: 1. 공 사 계 획 서
A4: 공 사 명 | B4: 동해안#1 변환소 전력통신설비 시설공사
A5: 총 공 사 비 | B5: =C9+C10 -> 1.5598031e+09 | C5: (a+b, VAT제외)
A6: 추 정 금 액 | B6: =ROUND((C9+C10)*1.1,1) -> 1.7157835e+09 | C6: [(a+b)*1.1, VAT포함]
A7: 추 정 가 격 | B7: ='6.공사비예산서'!$E9 -> 5.0284409e+08 | C7: (VAT제외)
A8: 내 역 | D8: ○ 재 료 비 : | E8: ='6.공사비예산서'!$E14 -> 1.1252955e+09
B9: ○ 회 사 분 [a] : | C9: ='6.공사비예산서'!$E8 -> 1056959053 | D9: ○ 노 무 비 : | E9: ='6.공사비예산서'!$E30 -> 276203502
B10: ○ 추 정 가 격 [b] : | C10: ='6.공사비예산서'!$E9 -> 5.0284409e+08 | D10: ○ 경 비 : | E10: ='6.공사비예산서'!$J14 -> 73421721
B11: ○ 추정가격VAT [c] : | C11: ='6.공사비예산서'!$E10 -> 50284409 | D11: ○ 일 반 관 리 비 : | E11: ='6.공사비예산서'!$J30 -> 33436936
D12: ○ 이 윤 : | E12: ='6.공사비예산서'!$J32 -> 51445446
A13: 예산과목 | B13: ○ 광단말장치 (411200102250011)
B14: ○ LAN설비 (421100101250010)
B15: ○ 급전전화 (421100105250004)
B16: ○ 전원설비 (421300103250036)
B17: ○ 시설보안 (421300102250021)
A18: 자 금 구 분
A19: 공 사 기 간 | B19: 착 공 : 2025년 11월
D20: 착공후 390일
B21: 준 공 : 2026년 12월
A22: 공 사 방 법 | B22: 도 급 공 사
A23: 공사책임자 | B23: HVDC건설본부 전자통신부장
A24: 공사감독자 | B24: HVDC건설본부 전자통신부장이 임명한 자
A25: 준공검사자 | B25: HVDC건설본부 전자통신부장이 임명한 자
A26: 공사인수자 | B26: 경북본부/강원본부 전자제어부장
A27: 첨 부 서 류 | B27: ○ 공사설명서 ○ 공사비총괄표 ○ 자금계획서 ○ 예정공정표 ○ 공사비예산서 ○ 설계명세서 ○ 공사비산출자료 ○ 시방서 ○ 시설도면
A28: 비 고

Sheet 2.공사설명서
A2: 2. 공 사 설 명 서
B4: 1. 공 사 명 : | D4: ='1.공사계획서'!B4 -> 동해안#1 변환소 전력통신설비 시설공사
B6: 2. 공 사 목 적
C7: 가. 500kV HVDC 동해안-신가평 건설 계획과 연계한 전력통신망 제공
C8: 나. 동해안#1 변환소 무인보안감시설비 등 전력통신설비 적기 구축
B10: 3. 공 사 개 요
C11: 가. 공사장소 : 울진군 덕천리 600번지 일원(동해안#1변환소 부지 내)
C12: 나. 시설내역
C13: 1) 송변전용 광단말장치 3식, PtoP 2식 시설((동해안#1, 동강C/H, 신태백S/S))
C14: 2) 전원설비 2식(동해안#1, 동강C/T) 및 LAN설비 · IP계통운영통신시스템 각 1식
C15: 3) 무인보안시스템 1식(카메라 128대, 출입관리)
C16: 4) 기타설비 1식
B18: 4. 재 원
C19: ='1.공사계획서'!B13 -> ○ 광단말장치 (411200102250011)
C20: ='1.공사계획서'!B14 -> ○ LAN설비 (421100101250010)
C21: ='1.공사계획서'!B15 -> ○ 급전전화 (421100105250004)
C22: ='1.공사계획서'!B16 -> ○ 전원설비 (421300103250036)
C23: ='1.공사계획서'!B17 -> ○ 시설보안 (421300102250021)
B25: 5. 공 사 방 법 : | D25: 사업소 도급공사
B27: 6. 총 공 사 비 : | E27: =SUM(F29:F30) -> 1.5598031e+09
B28: 가. 추정금액[(a+b)*1.1] : | F28: =ROUND((F29+F30)*1.1,1) -> 1.7157835e+09
B29: 나. 회 사 분 [a] : | F29: ='6.공사비예산서'!E8 -> 1056959053
B30: 다. 추정가격 [b] : | F30: ='6.공사비예산서'!E9 -> 5.0284409e+08
B31: 라. 추정가격VAT [c] : | F31: ='6.공사비예산서'!E10 -> 50284409
B33: 7. 공 사 기 간 : | D33: 착공 후 390일간
B35: 8. 하 자 기 간 : | D35: 준공검사 완료일로부터 3년(2%) | K35: 관련근거 : 국가를 당사자로 하는 계약에관한 법률 시행규칙[70조(하자담보책임기간) ① 5.정보통신공사업법 시행령 제37조(공사의 하자담조책임)
K36: 관련근거 : 국가를 당사자로 하는 계약에관한 법률 시행규칙[72조(하자보수보증금률) ①항4. 제1호 내지 제3호외의 공사 : 100분의 2]
B37: 9. 시설계통도 : | D37: 붙임참조

Sheet 2-1.계통도(전력통신)
A4: 1. 송변전용 광단말장치 | J4: 3. 계통보호회선유니트(PIU)
A5: 구 분 | B5: 계 통 도 | H5: 비고 | J5: 구 분 | K5: 계 통 도 | Q5: 시설내용
A6: 현 재 | J6: 현 재
A16: 공사후
J17: 공사후 | Q17: ㅇ 세교S/S
Q18: - PIU 8유니트 신설
Q20: ㅇ 금암S/S
Q21: - PIU 8유니트 신설
A27: 비 고 | B27: ㅇ 문서번호 HD(전자)-5054 "500kV HVDC 동해안-신가평 건설사업 광통신설비 구성 알림" 관련 | J27: 비 고 | K27: ㅇ 변전 인터락 접점 수용예정
B28: - (주회선) 송광치, (예비회선) PTP구성 | K28: - 각 T/L별 송신2, 수신2
B29: - 신가평 변환소 ~ 신태백S/S, 신가평 변환소 ~ 동강C/H 구간 장경간으로 광 증폭기 추가 시설

Sheet 2-2.계통도(무인보안)
B2: 2-2. 무인보안시스템 계통도

Sheet 3.공사비총괄표
A2: 3. 공 사 비 총 괄 표
A4: 공사명 : 동해안#1 변환소 전력통신설비 시설공사
A6: =CONCATENATE(" ○ 총 공 사 비 "," : ",TEXT('7.설계명세서'!$G583,"₩##,###,###")) -> ○ 총 공 사 비 : ₩502,844,091 | C6: =CONCATENATE(" ○ 추 정 가 격 "," : ",TEXT('7.설계명세서'!$G600,"₩##,###,###")) -> ○ 추 정 가 격 : ₩502,844,091
A7: =CONCATENATE(" ○ 추 정 금 액 "," : ",TEXT('7.설계명세서'!$G598,"₩##,###,###")) -> ○ 추 정 금 액 : ₩553,128,500 | C7: =CONCATENATE(" ○ 추정가격 VAT "," : ",TEXT('7.설계명세서'!$G601,"₩##,###,###")) -> ○ 추정가격 VAT : ₩50,284,409
A8: 항 목 별 | B8: 취 급 별 | C8: 합 계 | D8: 비 고
A9: 총 공사비 | B9: ( 합 계 ) | C9: =SUM(C10:C13) -> 1.5598031e+09
B10: 본 사 | C10: 0
B11: 사 업 소 | C11: =C19 -> 1056959053
B12: 도 급 | C12: =C20+C25+C26+C21+C27 -> 5.0284409e+08
B13: 비용배분비
A14: 외 자 비 | B14: -
A15: 출고재료비 | B15: 본 사 | C15: 0
B16: 사 업 소
A17: 구입재료비 | B17: ( 소 계 ) | C17: =SUM(C18:C20) -> 1.1252955e+09
B18: 본 사
B19: 사 업 소 | C19: ='6.공사비예산서'!$E15 -> 1056959053
B20: 도 급 | C20: ='6.공사비예산서'!$E16 -> 68336486
A21: 노 무 비 | B21: 도 급 | C21: ='6.공사비예산서'!E30 -> 276203502
A22: 경 비 | B22: ( 소 계 ) | C22: =SUM(C23:C25) -> 73421721
B23: 본 사
B24: 사 업 소
B25: 도 급 | C25: ='6.공사비예산서'!$J16 -> 73421721
A26: 일반관리비 | B26: 도 급 | C26: ='6.공사비예산서'!$J30 -> 33436936
A27: 이 윤 | B27: 도 급 | C27: ='6.공사비예산서'!$J32 -> 51445446
A28: 비용배분비 | B28: -

Sheet 4.자금계획서
A2: 4. 자 금 계 획 서
A3: ='3.공사비총괄표'!A4 -> 공사명 : 동해안#1 변환소 전력통신설비 시설공사
A4: 항 목 별 | B4: 취 급 별 | C4: 2025년 | D4: 2026년 | E4: 계
A5: 재 료 비 | B5: 본 사 | E5: =SUM(C5:D5) -> 0
B6: 사 업 소 | D6: ='6.공사비예산서'!E15 -> 1056959053 | E6: =SUM(C6:D6) -> 1056959053
B7: 도 급 | D7: ='6.공사비예산서'!E16 -> 68336486 | E7: =SUM(C7:D7) -> 68336486
A8: 노 무 비 | B8: 본 사 | E8: =SUM(C8:D8) -> 0
B9: 사 업 소 | E9: =SUM(C9:D9) -> 0
B10: 도 급 | D10: ='6.공사비예산서'!E32 -> 276203502 | E10: =SUM(C10:D10) -> 276203502
A11: 경 비 | B11: 본 사 | E11: =SUM(C11:D11) -> 0
B12: 사 업 소 | E12: =SUM(C12:D12) -> 0
B13: 도 급 | D13: ='6.공사비예산서'!J14 -> 73421721 | E13: =SUM(C13:D13) -> 73421721
A14: 일 반 관 리 비 | B14: 본 사 | E14: =SUM(C14:D14) -> 0
B15: 사 업 소 | E15: =SUM(C15:D15) -> 0
B16: 도 급 | D16: ='6.공사비예산서'!J30 -> 33436936 | E16: =SUM(C16:D16) -> 33436936
A17: 이 윤 | B17: 본 사 | E17: =SUM(C17:D17) -> 0
B18: 사 업 소 | E18: =SUM(C18:D18) -> 0
B19: 도 급 | D19: ='6.공사비예산서'!J32 -> 51445446 | E19: =SUM(C19:D19) -> 51445446
A20: 저 장 관 리 비 | B20: 본 사 | E20: =SUM(C20:D20) -> 0
B21: 사 업 소 | E21: =SUM(C21:D21) -> 0
A22: 계 | B22: 본 사 | E22: =SUM(C22:D22) -> 0
B23: 사 업 소 | D23: =SUM(D6,D9,D12,D15,D18,D21) -> 1056959053 | E23: =SUM(C23:D23) -> 1056959053
B24: 도 급 | D24: =SUM(D7,D10,D13,D16,D19) -> 5.0284409e+08 | E24: =SUM(C24:D24) -> 5.0284409e+08

Sheet 5.예정공정표
A2: 5. 예 정 공 정 표
B4: ='3.공사비총괄표'!A4 -> 공사명 : 동해안#1 변환소 전력통신설비 시설공사
B5: 기 간 공 정
D6: 10 | E6: 20 | F6: =E6+10 -> 30 | G6: =F6+10 -> 40 | H6: =G6+10 -> 50 | I6: =H6+10 -> 60 | J6: =I6+10 -> 70 | K6: =J6+10 -> 80 | L6: =K6+10 -> 90 | M6: =L6+10 -> 100 | ... AP6: =AO6+10 -> 390
B7: 자재검수 및 작업준비
C8: 케이블 금구류(행거,홀더) 철거
B9: 광전송 (단말) 장치 | C9: 랙 설치 및 케이블 포설
C10: 케이블 심선성단 및 수용
C11: 장비SETUP 및 종합시험
B12: 전원설비 네트워크 IPT | C12: 랙 설치 및 케이블 포설
C13: 케이블 결선
C14: 장비SETUP, 자체시험 및 연동시험
B15: 보안시스템 | C15: 장비 및 배관 설치
C16: 케이블 포설
C17: 장비SETUP, 자체시험 및 연동시험
B18: 준공 전 인수점검
B19: 지적사항 보완, 현장정리 및 준공

Sheet 6.공사비예산서
B2: 6. 공 사 비 예 산 서
B5: ○ 공 사 명 : | D5: ='1.공사계획서'!B4 -> 동해안#1 변환소 전력통신설비 시설공사
J6: 2025. 09. 29.
B7: 추정금액[(a+b)*1.1] | E7: =ROUND((E8+E9)*1.1,1) -> 1.7157835e+09 | H7: 검 토 자 | I7: : | J7: 오 승 조 (인)
B8: 회사취급비[a] | E8: =E15+J15 -> 1056959053 | H8: 작 성 자 | I8: : | J8: 이 주 신 (인)
B9: 추 정 가 격[b] | E9: =E16+E32+J16+J30+J32 -> 5.0284409e+08
B10: 추정가격VAT[c] | E10: =ROUND((E9*10%),0) -> 50284409
B12: 1. 총 공 사 비 | E12: =E14+E30+J14+J30+J32 -> 1.5598031e+09
B14: 가. 재 료 비 | E14: =E15+E16 -> 1.1252955e+09 | G14: 다. 경 비 | J14: =J16+J15 -> 73421721
C15: 회 사 분 | E15: =E18+E21 -> 1056959053 | H15: 회 사 분 | J15: ='7.설계명세서'!G560 -> 0
C16: 도 급 분 | E16: =E27+E28 -> 68336486 | H16: 도 급 분 | J16: =SUM(J18:J28) -> 73421721
B18: 1) 출고재료비 | E18: =E19+E20 -> 0 | G18: 1) 기계경비 | J18: ='7.설계명세서'!G563 -> 2900000
C19: 본 사 분 | E19: 0 | G19: 2) 공구손료 | J19: ='7.설계명세서'!$G564 -> 6585831
C20: 사업소분 | E20: 0 | G20: 3) 산재보험료 | J20: ='7.설계명세서'!$G565 -> 10015138
B21: 2) 구입재료비 | E21: =E22+E23+E24 -> 1056959053 | G21: 4) 고용보험료 | J21: ='7.설계명세서'!$G566 -> 2789655
C22: CP외자 | G22: 5) 국민건강보험료 | J22: ='7.설계명세서'!$G567 -> 9649656
C23: CP내자 | E23: ='7.설계명세서'!$G6 -> 1056959053 | G23: 6) 국민연금보험료 | J23: ='7.설계명세서'!$G568 -> 12249211
C24: LP내자 | G24: 7) 노인장기요양보험료 | J24: ='7.설계명세서'!$G569 -> 1249630
B25: 3) 회사운반비 | G25: 8) 퇴직공제부금비 | J25: ='7.설계명세서'!$G570 -> 5504922
B26: 4) 외자조작비 | G26: 9) 산업안전보건관리비 | J26: ='7.설계명세서'!$G571 -> 8696079
B27: 5) 지입재료비 | E27: ='7.설계명세서'!$G111 -> 68336486 | G27: 10) 기타경비 | J27: ='7.설계명세서'!G574 -> 13781599
B28: 6) 잡 재 료 비
B30: 나. 노 무 비 | E30: =SUM(E31:E32) -> 276203502 | G30: 라. 일반관리비 | J30: ='7.설계명세서'!$G577 -> 33436936
C31: 회 사 분
C32: 도 급 분 | E32: =SUM(E34:E35) -> 276203502 | G32: 마. 이 윤 | J32: ='7.설계명세서'!$G580 -> 51445446
B34: 1) 직접노무비 | E34: ='7.설계명세서'!G318 -> 239344456
B35: 2) 간접노무비 | E35: ='7.설계명세서'!G556 -> 36859046

Sheet 집계표
A1: 공사비 집계표(전력통신)
A2: ='3.공사비총괄표'!A4 -> 공사명 : 동해안#1 변환소 전력통신설비 시설공사
A3: 구 분 | C3: 비율 | D3: 요율 | F3: 과목별 예산내역 | L3: 비고
E4: 비금속광케이블 | F4: 송변전광전송장치 | G4: 전원설비 | H4: LAN,PIA | I4: IP계통운영 | J4: 무인보안 | K4: 합 계
A6: 재료비 | B6: 사급재료비 | F6: ='7.설계명세서'!G8 -> 320731684 | G6: ='7.설계명세서'!G31 -> 80375673 | H6: ='7.설계명세서'!G45 -> 13899124 | I6: ='7.설계명세서'!G52 -> 14215014 | J6: ='7.설계명세서'!G57 -> 627737558 | K6: =SUM(E6:J6) -> 1056959053 | M6: ='7.설계명세서'!G6 -> 1056959053
B7: 지입재료비 | F7: ='7.설계명세서'!G113 -> 1792930 | G7: ='7.설계명세서'!G176 -> 16306791 | H7: ='7.설계명세서'!G195 -> 1788725 | I7: ='7.설계명세서'!G229 -> 1204261 | J7: ='7.설계명세서'!G249 -> 47243779 | K7: =SUM(E7:J7) -> 68336486 | M7: ='7.설계명세서'!G111 -> 68336486
B8: 소 계 | F8: =SUM(F6:F7) -> 322524614 | G8: =SUM(G6:G7) -> 96682464 | H8: =SUM(H6:H7) -> 15687849 | I8: =SUM(I6:I7) -> 15419275 | J8: =SUM(J6:J7) -> 6.7498134e+08 | K8: =SUM(E8:J8) -> 1.1252955e+09 | M8: ='7.설계명세서'!G5 -> 1.1252955e+09
A9: 노무비 | B9: 직접노무비 | F9: ='7.설계명세서'!G341 -> 18783666 | G9: ='7.설계명세서'!G393 -> 27254707 | H9: ='7.설계명세서'!G414 -> 2616844 | I9: ='7.설계명세서'!G444 -> 2869166 | J9: ='7.설계명세서'!G461 -> 187820073 | K9: =SUM(E9:J9) -> 239344456 | M9: ='7.설계명세서'!G318 -> 239344456
B10: 간접노무비 | C10: ='7.설계명세서'!B557 -> 간접노무비(직접노무비 * 요율) | D10: ='7.설계명세서'!E557 -> 0.154 | F10: =INT(F9*$D$10) -> 2892684 | G10: =INT(G9*$D$10) -> 4197224 | H10: =INT(H9*$D$10) -> 402993 | I10: =INT(I9*$D$10) -> 441851 | J10: =INT(J9*$D$10) -> 28924291 | K10: =SUM(E10:J10) -> 36859043 | M10: ='7.설계명세서'!G556 -> 36859046
B11: 소 계 | F11: =SUM(F9:F10) -> 21676350 | G11: =SUM(G9:G10) -> 31451931 | H11: =SUM(H9:H10) -> 3019837 | I11: =SUM(I9:I10) -> 3311017 | J11: =SUM(J9:J10) -> 216744364 | K11: =SUM(K9:K10) -> 276203499 | M11: ='7.설계명세서'!G317 -> 276203502
A12: 경비 | B12: 공구손료 | C12: 직접노무비*3% | D12: ='7.설계명세서'!E564 -> 0.03 | F12: =INT((F9-1569606)*$D$12) -> 516421 | G12: =INT((G9-164016)*$D$12) -> 812720 | H12: =INT((H9-309732)*$D$12) -> 69213 | I12: =INT((I9-352446)*$D$12) -> 75501 | J12: =INT((J9-20182697)*$D$12)+'7.설계명세서'!G563 -> 7929121 | K12: =SUM(E12:J12) -> 9402976 | M12: ='7.설계명세서'!G564 -> 6585831
B13: 산재보험료 | C13: 노무비*3.763% | D13: ='7.설계명세서'!E565 -> 0.03626 | F13: =INT($D$13*F11) -> 785984 | G13: =INT($D$13*G11) -> 1140447 | H13: =INT($D$13*H11) -> 109499 | I13: =INT($D$13*I11) -> 120057 | J13: =INT($D$13*J11) -> 7859150 | K13: =SUM(E13:J13) -> 10015137 | M13: ='7.설계명세서'!G565 -> 10015138
B14: 고용보험료 | C14: 노무비*1.01% | D14: ='7.설계명세서'!E566 -> 0.0101 | F14: =INT($D$14*F11) -> 218931 | G14: =INT($D$14*G11) -> 317664 | H14: =INT($D$14*H11) -> 30500 | I14: =INT($D$14*I11) -> 33441 | J14: =INT($D$14*J11) -> 2189118 | K14: =SUM(E14:J14) -> 2789654 | M14: ='7.설계명세서'!G566 -> 2789655
B15: 국민건강보험료 | C15: 직노*3.545% | D15: ='7.설계명세서'!E567 -> 0.03545 | F15: =INT($D$15*F9) -> 665880 | G15: =INT($D$15*G9) -> 966179 | H15: =INT($D$15*H9) -> 92767 | I15: =INT($D$15*I9) -> 101711 | J15: =INT($D$15*J9) -> 6658221 | K15: =SUM(E15:J15) -> 8484758 | M15: ='7.설계명세서'!G567 -> 9649656
B16: 국민연금보험료 | C16: 직노*4.5% | D16: ='7.설계명세서'!E568 -> 0.045 | F16: =INT($D$16*F9) -> 845264 | G16: =INT($D$16*G9) -> 1226461 | H16: =INT($D$16*H9) -> 117757 | I16: =INT($D$16*I9) -> 129112 | J16: =INT($D$16*J9) -> 8451903 | K16: =SUM(E16:J16) -> 10770497 | M16: ='7.설계명세서'!G568 -> 12249211
B17: 노인장기요양보험료 | C17: 국민건강보험료*11.52% | D17: ='7.설계명세서'!E569 -> 0.1295 | F17: =INT(F15*$D$17) -> 86231 | G17: =INT(G15*$D$17) -> 125120 | H17: =INT(H15*$D$17) -> 12013 | I17: =INT(I15*$D$17) -> 13171 | J17: =INT(J15*$D$17) -> 862239 | K17: =SUM(E17:J17) -> 1098774 | M17: ='7.설계명세서'!G569 -> 1249630
B18: 퇴직공제가입금 | C18: 직노*2.3% | D18: ='7.설계명세서'!E570 -> 0.023 | F18: =INT($D$18*F9) -> 432024 | G18: =INT($D$18*G9) -> 626858 | H18: =INT($D$18*H9) -> 60187 | I18: =INT($D$18*I9) -> 65990 | J18: =INT($D$18*J9) -> 4319861 | K18: =SUM(E18:J18) -> 5504920 | M18: ='7.설계명세서'!G570 -> 5504922
B19: 산업안전보건관리비 | C19: [(지입재료비+직접노무비) × 적용율 + 기초액] × 1.2 | D19: ='7.설계명세서'!D572 -> 0.0207 | F19: =INT(((F7+F9)*$D$19)*1.2) -> 511122 | G19: =INT(((G7+G9)*$D$19)*1.2) -> 1082067 | H19: =INT(((H7+H9)*$D$19)*1.2) -> 109434 | I19: =INT(((I7+I9)*$D$19)*1.2) -> 101183 | J19: =INT(((J7+J9)*$D$19)*1.2) -> 5838986 | K19: =SUM(E19:J19) -> 7642792 | M19: ='7.설계명세서'!G571 -> 8696079
B20: 기타경비 | C20: (지입재료비+노무비)*4.0% | D20: ='7.설계명세서'!E574 -> 0.04 | F20: =INT(($D$20*(F11+F7))) -> 938771 | G20: =INT(($D$20*(G11+G7))) -> 1910348 | H20: =INT(($D$20*(H11+H7))) -> 192342 | I20: =INT(($D$20*(I11+I7))) -> 180611 | J20: =INT(($D$20*(J11+J7))) -> 10559525 | K20: =SUM(E20:J20) -> 13781597 | M20: ='7.설계명세서'!G574 -> 13781599
B21: 소 계 | F21: =SUM(F12:F20) -> 5000628 | G21: =SUM(G12:G20) -> 8207864 | H21: =SUM(H12:H20) -> 793712 | I21: =SUM(I12:I20) -> 820777 | J21: =SUM(J12:J20) -> 54668124 | K21: =SUM(E21:J21) -> 69491105 | M21: ='7.설계명세서'!G562 -> 73421721
A22: 일반관리비 | C22: (지입재료비+노무비+도급경비) X 요율 | D22: ='7.설계명세서'!E578 -> 0.08 | F22: =INT($D$22*((F11+F7+F21))) -> 2277592 | G22: =INT($D$22*((G11+G7+G21))) -> 4477326 | H22: =INT($D$22*((H11+H7+H21))) -> 448181 | I22: =INT($D$22*((I11+I7+I21))) -> 426884 | J22: =INT($D$22*((J11+J7+J21))) -> 25492501 | K22: =SUM(E22:J22) -> 33122484 | M22: ='7.설계명세서'!G577 -> 33436936
A23: 이 윤 | C23: (노무비 + 경비 + 일반관리비) X 이윤율 | D23: ='7.설계명세서'!E581 -> 0.13431 | F23: =INT($D$23*((F22+F21+F11))) -> 3888888 | G23: =INT($D$23*((G22+G21+G11))) -> 5928056 | H23: =INT($D$23*((H22+H21+H11))) -> 572392 | I23: =INT($D$23*((I22+I21+I11))) -> 612276 | J23: =INT($D$23*((J22+J21+J11)))-5664 -> 39871645 | K23: =SUM(E23:J23) -> 50873257 | M23: ='7.설계명세서'!G580 -> 51445446
A24: 추정가격(a) | F24: =INT(F23+F22+F21+F11+F7) -> 34636388 | G24: =INT(G23+G22+G21+G11+G7) -> 66371968 | H24: =INT(H23+H22+H21+H11+H7) -> 6622847 | I24: =INT(I23+I22+I21+I11+I7) -> 6375215 | J24: =INT(J23+J22+J21+J11+J7) -> 384020412 | K24: =SUM(E24:J24)+L24 -> 498026830 | M24: ='7.설계명세서'!G600 -> 5.0284409e+08 | U24: =S24-T24 -> 0
A25: 추정가격 VAT( c ) | F25: =F24*10% -> 3463638.8 | G25: =G24*10% -> 6637196.8 | H25: =H24*10% -> 662284.7 | I25: =I24*10% -> 637521.5 | J25: =J24*10% -> 38402041 | K25: =SUM(E25:J25) -> 49802683 | M25: ='7.설계명세서'!G601 -> 50284409
A26: 추정금액(d) | C26: d=(a+b)*1.1 | F26: =(F24+F27)*1.1 -> 3.9090488e+08 | G26: =(G24+G27)*1.1 -> 1.6142241e+08 | H26: =(H24+H27)*1.1 -> 22574168 | I26: =(I24+I27)*1.1 -> 22649252 | J26: =(J24+J27)*1.1 -> 1112933767 | K26: =SUM(E26:J26) -> 1.7104845e+09 | M26: ='7.설계명세서'!G598 -> 553128500
A27: 회사분(b) | F27: =F6 -> 320731684 | G27: =G6 -> 80375673 | H27: =H6 -> 13899124 | I27: =I6 -> 14215014 | J27: =J6 -> 627737558 | K27: =SUM(E27:J27) -> 1056959053 | M27: ='7.설계명세서'!G599 -> 0
A28: 총공사비( E ) | F28: =F24+F27 -> 355368072 | G28: =G24+G27 -> 146747641 | H28: =H24+H27 -> 20521971 | I28: =I24+I27 -> 20590229 | J28: =J24+J27 -> 1011757970 | K28: =SUM(E28:J28)+L28 -> 1554985883 | M28: ='7.설계명세서'!G583 -> 5.0284409e+08

Sheet 7.설계명세서
A2: 7. 설 계 명 세 서 | J2: Ⅶ. 설 계 명 세 서(전력통신-종합)
A3: =표지!A13 -> 공사명 : 동해안#1 변환소 전력통신설비 시설공사 | J3: =$A3 -> 공사명 : 동해안#1 변환소 전력통신설비 시설공사
A4: No. | B4: 품 명 | C4: 규 격 | D4: 단위 | E4: 수량 | F4: 단 가 | G4: 금 액 | H4: 비 고 | J4: No. | K4: 품 명 | L4: 규 격 | M4: 단위 | N4: 수량 | O4: 단 가 | P4: 금 액 | Q4: 비 고
A5: [ 재 료 비 ] | G5: =G6+G111 -> 1.1252955e+09 | J5: [ 재 료 비 ] | P5: =P6+P111 -> #REF! | R5: =E5-N5 -> 0 | S5: =G5-P5 -> #REF! | T5: =#REF!+#REF! -> #REF! | U5: =P5-T5 -> #REF!
A6: Ⅰ. 사 급 분 | G6: =G8+G31+G45+G52+G57 -> 1056959053 | I6: 단수정리 | J6: Ⅰ. 사 급 분 | P6: =#REF!+#REF!+#REF!+P8+P31+P45 -> #REF! | R6: =E6-N6 -> 0 | S6: =G6-P6 -> #REF! | T6: =#REF!+#REF! -> #REF! | U6: =P6-T6 -> #REF!
N7: =#REF!+#REF! -> #REF! | R7: =E7-N7 -> #REF! | S7: =G7-P7 -> 0 | T7: =#REF!+#REF! -> #REF! | U7: =P7-T7 -> #REF!
A8: ='8-1.설비자재산출(전력통신)'!A3 -> 1. 송변전광전송단말장치 | G8: =SUM(G9:G28) -> 320731684 | J8: =$A8 -> 1. 송변전광전송단말장치 | N8: =#REF!+#REF! -> #REF! | P8: =SUM(P9:P116) -> #REF! | R8: =E8-N8 -> #REF! | S8: =G8-P8 -> #REF! | T8: =#REF!+#REF! -> #REF! | U8: =P8-T8 -> #REF!
A9: ='8-1.설비자재산출(전력통신)'!B7 -> 126546 | B9: ='8-1.설비자재산출(전력통신)'!C7 -> 주셀프 | C9: ='8-1.설비자재산출(전력통신)'!D7 -> MAIN-S | D9: ='8-1.설비자재산출(전력통신)'!I7 -> EA | E9: ='8-1.설비자재산출(전력통신)'!N7 -> 3 | F9: =VLOOKUP(C9,'8-6.자재단가비교표'!$C$7:$O$332,12,0) -> 3238028.4 | G9: =INT(E9*F9) -> 9714085 | H9: =VLOOKUP(C9,'8-6.자재단가비교표'!$C$7:$O$332,13,0) -> ERP단가 | J9: =$A9 -> 126546 | K9: =$B9 -> 주셀프 | L9: =$C9 -> MAIN-S | M9: =$D9 -> EA | N9: =#REF!+#REF! -> #REF! | O9: =VLOOKUP(L9,'8-6.자재단가비교표'!$C$8:$O$332,12,0) -> 3238028.4 | P9: =INT(N9*O9) -> #REF! | Q9: =VLOOKUP(L9,'8-6.자재단가비교표'!$C$8:$O$328,13,0) -> ERP단가 | R9: =E9-N9 -> #REF! | S9: =G9-P9 -> #REF! | T9: =#REF!+#REF! -> #REF! | U9: =P9-T9 -> #REF!
A10: ='8-1.설비자재산출(전력통신)'!B8 -> 126547 | B10: ='8-1.설비자재산출(전력통신)'!C8 -> 확장셀프 | C10: ='8-1.설비자재산출(전력통신)'!D8 -> EXT-S | D10: ='8-1.설비자재산출(전력통신)'!I8 -> EA | E10: ='8-1.설비자재산출(전력통신)'!N8 -> 0 | F10: =VLOOKUP(C10,'8-6.자재단가비교표'!$C$7:$O$332,12,0) -> 2996081.8 | G10: =INT(E10*F10) -> 0 | H10: =VLOOKUP(C10,'8-6.자재단가비교표'!$C$7:$O$332,13,0) -> ERP단가 | J10: =$A10 -> 126547 | K10: =$B10 -> 확장셀프 | L10: =$C10 -> EXT-S | M10: =$D10 -> EA | N10: =#REF!+#REF! -> #REF! | O10: =VLOOKUP(L10,'8-6.자재단가비교표'!$C$8:$O$332,12,0) -> 2996081.8 | P10: =INT(N10*O10) -> #REF! | Q10: =VLOOKUP(L10,'8-6.자재단가비교표'!$C$8:$O$328,13,0) -> ERP단가 | R10: =E10-N10 -> #REF! | S10: =G10-P10 -> #REF! | T10: =#REF!+#REF! -> #REF! | U10: =P10-T10 -> #REF!
A11: ='8-1.설비자재산출(전력통신)'!B9 -> 126548 | B11: ='8-1.설비자재산출(전력통신)'!C9 -> 광전송유니트(A) | C11: ='8-1.설비자재산출(전력통신)'!D9 -> CTRU(A) | D11: ='8-1.설비자재산출(전력통신)'!I9 -> EA | E11: ='8-1.설비자재산출(전력통신)'!N9 -> 4 | F11: =VLOOKUP(C11,'8-6.자재단가비교표'!$C$7:$O$332,12,0) -> 15504516 | G11: =INT(E11*F11) -> 62018063 | H11: =VLOOKUP(C11,'8-6.자재단가비교표'!$C$7:$O$332,13,0) -> ERP단가 | J11: =$A11 -> 126548 | K11: =$B11 -> 광전송유니트(A) | L11: =$C11 -> CTRU(A) | M11: =$D11 -> EA | N11: =#REF!+#REF! -> #REF! | O11: =VLOOKUP(L11,'8-6.자재단가비교표'!$C$8:$O$332,12,0) -> 15504516 | P11: =INT(N11*O11) -> #REF! | Q11: =VLOOKUP(L11,'8-6.자재단가비교표'!$C$8:$O$328,13,0) -> ERP단가 | R11: =E11-N11 -> #REF! | S11: =G11-P11 -> #REF! | T11: =#REF!+#REF! -> #REF! | U11: =P11-T11 -> #REF!
A12: ='8-1.설비자재산출(전력통신)'!B10 -> 126549 | B12: ='8-1.설비자재산출(전력통신)'!C10 -> 광전송유니트(B) | C12: ='8-1.설비자재산출(전력통신)'!D10 -> CTRU(B) | D12: ='8-1.설비자재산출(전력통신)'!I10 -> 대 | E12: ='8-1.설비자재산출(전력통신)'!N10 -> 0 | F12: =VLOOKUP(C12,'8-6.자재단가비교표'!$C$7:$O$332,12,0) -> 15965698 | G12: =INT(E12*F12) -> 0 | H12: =VLOOKUP(C12,'8-6.자재단가비교표'!$C$7:$O$332,13,0) -> ERP단가
A13: ='8-1.설비자재산출(전력통신)'!B11 -> 126550 | B13: ='8-1.설비자재산출(전력통신)'!C11 -> 광전송유니트(C) | C13: ='8-1.설비자재산출(전력통신)'!D11 -> CTRU(C) | D13: ='8-1.설비자재산출(전력통신)'!I11 -> EA | E13: ='8-1.설비자재산출(전력통신)'!N11 -> 2 | F13: =VLOOKUP(C13,'8-6.자재단가비교표'!$C$7:$O$332,12,0) -> 19091522 | G13: =INT(E13*F13) -> 38183043 | H13: =VLOOKUP(C13,'8-6.자재단가비교표'!$C$7:$O$332,13,0) -> ERP단가
A14: ='8-1.설비자재산출(전력통신)'!B12 -> 126551 | B14: ='8-1.설비자재산출(전력통신)'!C12 -> 제어유니트 | C14: ='8-1.설비자재산출(전력통신)'!D12 -> MCU | D14: ='8-1.설비자재산출(전력통신)'!I12 -> EA | E14: ='8-1.설비자재산출(전력통신)'!N12 -> 3 | F14: =VLOOKUP(C14,'8-6.자재단가비교표'!$C$7:$O$332,12,0) -> 2309609 | G14: =INT(E14*F14) -> 6928826 | H14: =VLOOKUP(C14,'8-6.자재단가비교표'!$C$7:$O$332,13,0) -> ERP단가
A15: ='8-1.설비자재산출(전력통신)'!B13 -> 126552 | B15: ='8-1.설비자재산출(전력통신)'!C13 -> DS-1/E 회선유니트 | C15: ='8-1.설비자재산출(전력통신)'!D13 -> LIU | D15: ='8-1.설비자재산출(전력통신)'!I13 -> EA | E15: ='8-1.설비자재산출(전력통신)'!N13 -> 3 | F15: =VLOOKUP(C15,'8-6.자재단가비교표'!$C$7:$O$332,12,0) -> 2890329.1 | G15: =INT(E15*F15) -> 8670987 | H15: =VLOOKUP(C15,'8-6.자재단가비교표'!$C$7:$O$332,13,0) -> ERP단가
A16: ='8-1.설비자재산출(전력통신)'!B14 -> 126553 | B16: ='8-1.설비자재산출(전력통신)'!C14 -> 계통보호 회선유니트 | C16: ='8-1.설비자재산출(전력통신)'!D14 -> PIU | D16: ='8-1.설비자재산출(전력통신)'!I14 -> EA | E16: ='8-1.설비자재산출(전력통신)'!N14 -> 0 | F16: =VLOOKUP(C16,'8-6.자재단가비교표'!$C$7:$O$332,12,0) -> 0 | G16: =INT(E16*F16) -> 0 | H16: =VLOOKUP(C16,'8-6.자재단가비교표'!$C$7:$O$332,13,0) -> ERP단가
A17: ='8-1.설비자재산출(전력통신)'!B15 -> 126554 | B17: ='8-1.설비자재산출(전력통신)'!C15 -> 확장셀프 데이터 집선유니트 | C17: ='8-1.설비자재산출(전력통신)'!D15 -> ECU | D17: ='8-1.설비자재산출(전력통신)'!I15 -> EA | E17: ='8-1.설비자재산출(전력통신)'!N15 -> 0 | F17: =VLOOKUP(C17,'8-6.자재단가비교표'!$C$7:$O$332,12,0) -> 1626802.2 | G17: =INT(E17*F17) -> 0 | H17: =VLOOKUP(C17,'8-6.자재단가비교표'!$C$7:$O$332,13,0) -> ERP단가
A18: ='8-1.설비자재산출(전력통신)'!B16 -> 127955 | B18: ='8-1.설비자재산출(전력통신)'!C16 -> 채널급 유니트 | C18: ='8-1.설비자재산출(전력통신)'!D16 -> 4W E&M | D18: ='8-1.설비자재산출(전력통신)'!I16 -> EA | E18: ='8-1.설비자재산출(전력통신)'!N16 -> 0 | F18: =VLOOKUP(C18,'8-6.자재단가비교표'!$C$7:$O$332,12,0) -> 2297842.1 | G18: =INT(E18*F18) -> 0 | H18: =VLOOKUP(C18,'8-6.자재단가비교표'!$C$7:$O$332,13,0) -> ERP단가
A19: ='8-1.설비자재산출(전력통신)'!B17 -> 126555 | B19: ='8-1.설비자재산출(전력통신)'!C17 -> P-to-P(A) 광전송장치 | C19: ='8-1.설비자재산출(전력통신)'!D17 -> PTPU(A) | D19: ='8-1.설비자재산출(전력통신)'!I17 -> EA | E19: ='8-1.설비자재산출(전력통신)'!N17 -> 0 | F19: =VLOOKUP(C19,'8-6.자재단가비교표'!$C$7:$O$332,12,0) -> 3427715.5 | G19: =INT(E19*F19) -> 0 | H19: =VLOOKUP(C19,'8-6.자재단가비교표'!$C$7:$O$332,13,0) -> ERP단가
A20: ='8-1.설비자재산출(전력통신)'!B18 -> 126556 | B20: ='8-1.설비자재산출(전력통신)'!C18 -> P-to-P(B) 광전송장치 | C20: ='8-1.설비자재산출(전력통신)'!D18 -> PTPU(B) | D20: ='8-1.설비자재산출(전력통신)'!I18 -> EA | E20: ='8-1.설비자재산출(전력통신)'!N18 -> 0 | F20: =VLOOKUP(C20,'8-6.자재단가비교표'!$C$7:$O$332,12,0) -> 3998046.4 | G20: =INT(E20*F20) -> 0 | H20: =VLOOKUP(C20,'8-6.자재단가비교표'!$C$7:$O$332,13,0) -> ERP단가
A21: ='8-1.설비자재산출(전력통신)'!B19 -> 126557 | B21: ='8-1.설비자재산출(전력통신)'!C19 -> P-to-P(C) 광전송장치 | C21: ='8-1.설비자재산출(전력통신)'!D19 -> PTPU(C) | D21: ='8-1.설비자재산출(전력통신)'!I19 -> EA | E21: ='8-1.설비자재산출(전력통신)'!N19 -> 2 | F21: =VLOOKUP(C21,'8-6.자재단가비교표'!$C$7:$O$332,12,0) -> 4764201.4 | G21: =INT(E21*F21) -> 9528402 | H21: =VLOOKUP(C21,'8-6.자재단가비교표'!$C$7:$O$332,13,0) -> ERP단가
A22: ='8-1.설비자재산출(전력통신)'!B20 -> 126558 | B22: ='8-1.설비자재산출(전력통신)'!C20 -> 전용랙(내진) | C22: ='8-1.설비자재산출(전력통신)'!D20 -> 19"-내진랙 | D22: ='8-1.설비자재산출(전력통신)'!I20 -> EA | E22: ='8-1.설비자재산출(전력통신)'!N20 -> 4 | F22: =VLOOKUP(C22,'8-6.자재단가비교표'!$C$7:$O$332,12,0) -> 5985995.9 | G22: =INT(E22*F22) -> 23943983 | H22: =VLOOKUP(C22,'8-6.자재단가비교표'!$C$7:$O$332,13,0) -> ERP단가
A23: ='8-1.설비자재산출(전력통신)'!B21 -> 120544 | B23: ='8-1.설비자재산출(전력통신)'!C21 -> 챔프케이블(송광치) | C23: ='8-1.설비자재산출(전력통신)'!D21 -> CH-SM-15(송광치) | D23: ='8-1.설비자재산출(전력통신)'!I21 -> EA | E23: ='8-1.설비자재산출(전력통신)'!N21 -> 4 | F23: =VLOOKUP(C23,'8-6.자재단가비교표'!$C$7:$O$332,12,0) -> 94859.772 | G23: =INT(E23*F23) -> 379439 | H23: =VLOOKUP(C23,'8-6.자재단가비교표'!$C$7:$O$332,13,0) -> ERP단가
... A26: ='8-1.설비자재산출(전력통신)'!B24 -> 127037 | B26: ='8-1.설비자재산출(전력통신)'!C24 -> 송변전용스위치(A) | C26: ='8-1.설비자재산출(전력통신)'!D24 -> L3SWU(A) | D26: ='8-1.설비자재산출(전력통신)'!I24 -> EA | E26: ='8-1.설비자재산출(전력통신)'!N24 -> 7 | F26: =VLOOKUP(C26,'8-6.자재단가비교표'!$C$7:$O$332,12,0) -> 3509880 | G26: =INT(E26*F26) -> 24569160 | H26: =VLOOKUP(C26,'8-6.자재단가비교표'!$C$7:$O$332,13,0) -> ERP단가
B27: ='8-1.설비자재산출(전력통신)'!C25 -> 광증폭기 | C27: ='8-1.설비자재산출(전력통신)'!D25 -> 8CH | D27: ='8-1.설비자재산출(전력통신)'!I25 -> EA | E27: ='8-1.설비자재산출(전력통신)'!N25 -> 5 | F27: =VLOOKUP(C27,'8-6.자재단가비교표'!$C$7:$O$332,12,0) -> 21936750 | G27: =INT(E27*F27) -> 109683750 | H27: 견적가
B28: ='8-1.설비자재산출(전력통신)'!C32 -> 컨테이너 | C28: ='8-1.설비자재산출(전력통신)'!D32 -> ICT실용, 냉방기, 단열재, 운송 설치 포함 | D28: ='8-1.설비자재산출(전력통신)'!I32 -> EA | E28: ='8-1.설비자재산출(전력통신)'!N32 -> 1 | F28: ='8-6.자재단가비교표'!N32 -> 26536520 | G28: =INT(E28*F28) -> 26536519 | H28: 견적가
N30: =#REF!+#REF! -> #REF! | R30: =E30-N30 -> #REF! | S30: =G30-P30 -> 0 | T30: =#REF!+#REF! -> #REF! | U30: =P30-T30 -> #REF!
A31: ='8-1.설비자재산출(전력통신)'!A95 -> 2. 전원설비 | G31: =SUM(G32:G43) -> 80375673 | J31: =$A31 -> 2. 전원설비 | N31: =#REF!+#REF! -> #REF! | P31: =SUM(P32:P43) -> #REF! | R31: =E31-N31 -> #REF! | S31: =G31-P31 -> #REF! | T31: =#REF!+#REF! -> #REF! | U31: =P31-T31 -> #REF!
A32: ='8-1.설비자재산출(전력통신)'!B98 -> 127046 | B32: ='8-1.설비자재산출(전력통신)'!C98 -> UPS | C32: ='8-1.설비자재산출(전력통신)'!D98 -> 15kVA 입력 3상4선 출력 단상, 내진랙(19") | D32: ='8-1.설비자재산출(전력통신)'!I98 -> 대 | E32: ='8-1.설비자재산출(전력통신)'!N98 -> 1 | F32: =VLOOKUP(C32,'8-6.자재단가비교표'!$C$7:$O$332,12,0) -> 8421907.9 | G32: =INT(E32*F32) -> 8421907 | H32: =VLOOKUP(C32,'8-6.자재단가비교표'!$C$7:$O$332,13,0) -> ERP단가 | J32: =$A32 -> 127046 | K32: =$B32 -> UPS | L32: =$C32 -> 15kVA 입력 3상4선 출력 단상, 내진랙(19") | M32: =$D32 -> 대 | N32: =#REF!+#REF! -> #REF! | O32: =VLOOKUP(L32,'8-6.자재단가비교표'!$C$8:$O$332,12,0) -> 8421907.9 | P32: =INT(N32*O32) -> #REF! | Q32: =VLOOKUP(L32,'8-6.자재단가비교표'!$C$8:$O$328,13,0) -> ERP단가 | R32: =E32-N32 -> #REF! | S32: =G32-P32 -> #REF! | T32: =#REF!+#REF! -> #REF! | U32: =P32-T32 -> #REF!
A33: ='8-1.설비자재산출(전력통신)'!B99 -> 124375 | B33: ='8-1.설비자재산출(전력통신)'!C99 -> UPS | C33: ='8-1.설비자재산출(전력통신)'!D99 -> 5kVA 입력 3상4선 출력 단상, 내진랙(19") | D33: ='8-1.설비자재산출(전력통신)'!I99 -> 대 | E33: ='8-1.설비자재산출(전력통신)'!N99 -> 1 | F33: ='8-6.자재단가비교표'!E98 -> 9343862 | G33: =INT(E33*F33) -> 9343862 | H33: =VLOOKUP(C33,'8-6.자재단가비교표'!$C$7:$O$332,13,0) -> ERP단가
A34: ='8-1.설비자재산출(전력통신)'!B100 -> 125497 | B34: ='8-1.설비자재산출(전력통신)'!C100 -> 통신용충전기 | C34: ='8-1.설비자재산출(전력통신)'!D100 -> 48V 100A(50A * 2), 단독형, 내진랙(19") | D34: ='8-1.설비자재산출(전력통신)'!I100 -> 대 | E34: ='8-1.설비자재산출(전력통신)'!N100 -> 1 | F34: =VLOOKUP(C34,'8-6.자재단가비교표'!$C$7:$O$332,12,0) -> 7651000.5 | G34: =INT(E34*F34) -> 7651000 | H34: =VLOOKUP(C34,'8-6.자재단가비교표'!$C$7:$O$332,13,0) -> ERP단가
A35: ='8-1.설비자재산출(전력통신)'!B101 -> 125498 | B35: ='8-1.설비자재산출(전력통신)'!C101 -> 통신용충전기 | C35: ='8-1.설비자재산출(전력통신)'!D101 -> 48V 100A(50A * 3), 단독형, 내진랙(19") | D35: ='8-1.설비자재산출(전력통신)'!I101 -> 대 | E35: ='8-1.설비자재산출(전력통신)'!N101 -> 2 | F35: =VLOOKUP(C35,'8-6.자재단가비교표'!$C$7:$O$332,12,0) -> 8191102.6 | G35: =INT(E35*F35) -> 16382205 | H35: =VLOOKUP(C35,'8-6.자재단가비교표'!$C$7:$O$332,13,0) -> ERP단가 | J35: =$A35 -> 125498 | K35: =$B35 -> 통신용충전기 | L35: =$C35 -> 48V 100A(50A * 3), 단독형, 내진랙(19") | M35: =$D35 -> 대 | N35: =#REF!+#REF! -> #REF! | O35: =VLOOKUP(L35,'8-6.자재단가비교표'!$C$8:$O$332,12,0) -> 8191102.6 | P35: =INT(N35*O35) -> #REF! | Q35: =VLOOKUP(L35,'8-6.자재단가비교표'!$C$8:$O$328,13,0) -> ERP단가 | R35: =E35-N35 -> #REF! | S35: =G35-P35 -> #REF! | T35: =#REF!+#REF! -> #REF! | U35: =P35-T35 -> #REF!
A36: ='8-1.설비자재산출(전력통신)'!B102 -> 124379 | B36: ='8-1.설비자재산출(전력통신)'!C102 -> AC/UPS/DC분전반 | C36: ='8-1.설비자재산출(전력통신)'!D102 -> AC 2회로, UPS 20회로, DC 16회로 | D36: ='8-1.설비자재산출(전력통신)'!I102 -> 대 | E36: ='8-1.설비자재산출(전력통신)'!N102 -> 2 | F36: =VLOOKUP(C36,'8-6.자재단가비교표'!$C$7:$O$332,12,0) -> 6250659.3 | G36: =INT(E36*F36) -> 12501318 | H36: =VLOOKUP(C36,'8-6.자재단가비교표'!$C$7:$O$332,13,0) -> ERP단가 | J36: =$A36 -> 124379 | K36: =$B36 -> AC/UPS/DC분전반 | L36: =$C36 -> AC 2회로, UPS 20회로, DC 16회로 | M36: =$D36 -> 대 | N36: =#REF!+#REF! -> #REF! | O36: =VLOOKUP(L36,'8-6.자재단가비교표'!$C$8:$O$332,12,0) -> 6250659.3 | P36: =INT(N36*O36) -> #REF! | Q36: =VLOOKUP(L36,'8-6.자재단가비교표'!$C$8:$O$328,13,0) -> ERP단가 | R36: =E36-N36 -> #REF! | S36: =G36-P36 -> #REF! | T36: =#REF!+#REF! -> #REF! | U36: =P36-T36 -> #REF!
B37: ='8-1.설비자재산출(전력통신)'!C103 -> DC분전반 | C37: ='8-1.설비자재산출(전력통신)'!D103 -> DC 20+20회로 | D37: ='8-1.설비자재산출(전력통신)'!I103 -> 대 | E37: ='8-1.설비자재산출(전력통신)'!N103 -> 0 | F37: =VLOOKUP(C37,'8-6.자재단가비교표'!$C$7:$O$332,12,0) -> 0 | G37: =INT(E37*F37) -> 0 | H37: =VLOOKUP(C37,'8-6.자재단가비교표'!$C$7:$O$332,13,0) -> 0 | J37: =$A37 -> 0 | K37: =$B37 -> DC분전반 | L37: =$C37 -> DC 20+20회로 | M37: =$D37 -> 대 | N37: =#REF!+#REF! -> #REF! | O37: =VLOOKUP(L37,'8-6.자재단가비교표'!$C$8:$O$332,12,0) -> 0 | P37: =INT(N37*O37) -> #REF! | Q37: =VLOOKUP(L37,'8-6.자재단가비교표'!$C$8:$O$328,13,0) -> 0 | R37: =E37-N37 -> #REF! | S37: =G37-P37 -> #REF! | T37: =#REF!+#REF! -> #REF! | U37: =P37-T37 -> #REF!
A38: ='8-1.설비자재산출(전력통신)'!B104 -> 111126 | B38: ='8-1.설비자재산출(전력통신)'!C104 -> 축전지 | C38: ='8-1.설비자재산출(전력통신)'!D104 -> 12V/150AH, UPS용 | D38: ='8-1.설비자재산출(전력통신)'!I104 -> 개 | E38: ='8-1.설비자재산출(전력통신)'!N104 -> 16 | F38: =VLOOKUP(C38,'8-6.자재단가비교표'!$C$7:$O$332,12,0) -> 260950.8 | G38: =INT(E38*F38) -> 4175212 | H38: =VLOOKUP(C38,'8-6.자재단가비교표'!$C$7:$O$332,13,0) -> ERP단가 | J38: =$A38 -> 111126 | K38: =$B38 -> 축전지 | L38: =$C38 -> 12V/150AH, UPS용 | M38: =$D38 -> 개 | N38: =#REF!+#REF! -> #REF! | O38: =VLOOKUP(L38,'8-6.자재단가비교표'!$C$8:$O$332,12,0) -> 260950.8 | P38: =INT(N38*O38) -> #REF! | Q38: =VLOOKUP(L38,'8-6.자재단가비교표'!$C$8:$O$328,13,0) -> ERP단가 | R38: =E38-N38 -> #REF! | S38: =G38-P38 -> #REF! | T38: =#REF!+#REF! -> #REF! | U38: =P38-T38 -> #REF!
A39: ='8-1.설비자재산출(전력통신)'!B105 -> 111125 | B39: ='8-1.설비자재산출(전력통신)'!C105 -> 축전지 | C39: ='8-1.설비자재산출(전력통신)'!D105 -> 12V/100AH, UPS용 | D39: ='8-1.설비자재산출(전력통신)'!I105 -> 개 | E39: ='8-1.설비자재산출(전력통신)'!N105 -> 16 | F39: =VLOOKUP(C39,'8-6.자재단가비교표'!$C$7:$O$332,12,0) -> 194620.21 | G39: =INT(E39*F39) -> 3113923 | H39: =VLOOKUP(C39,'8-6.자재단가비교표'!$C$7:$O$332,13,0) -> ERP단가 | J39: =$A39 -> 111125 | K39: =$B39 -> 축전지 | L39: =$C39 -> 12V/100AH, UPS용 | M39: =$D39 -> 개 | N39: =#REF!+#REF! -> #REF! | O39: =VLOOKUP(L39,'8-6.자재단가비교표'!$C$8:$O$332,12,0) -> 194620.21 | P39: =INT(N39*O39) -> #REF! | Q39: =VLOOKUP(L39,'8-6.자재단가비교표'!$C$8:$O$328,13,0) -> ERP단가 | R39: =E39-N39 -> #REF! | S39: =G39-P39 -> #REF! | T39: =#REF!+#REF! -> #REF! | U39: =P39-T39 -> #REF!
A40: ='8-1.설비자재산출(전력통신)'!B106 -> 111127 | B40: ='8-1.설비자재산출(전력통신)'!C106 -> 축전지 | C40: ='8-1.설비자재산출(전력통신)'!D106 -> 12V/200AH, 충전기용 | D40: ='8-1.설비자재산출(전력통신)'!I106 -> 개 | E40: ='8-1.설비자재산출(전력통신)'!N106 -> 8 | F40: =VLOOKUP(C40,'8-6.자재단가비교표'!$C$7:$O$332,12,0) -> 342213.3 | G40: =INT(E40*F40) -> 2737706 | H40: =VLOOKUP(C40,'8-6.자재단가비교표'!$C$7:$O$332,13,0) -> 견적가
A41: ='8-1.설비자재산출(전력통신)'!B107 -> 111125 | B41: ='8-1.설비자재산출(전력통신)'!C107 -> 축전지 | C41: ='8-1.설비자재산출(전력통신)'!D107 -> 12V/150AH, 충전기용 | D41: ='8-1.설비자재산출(전력통신)'!I107 -> 개 | E41: ='8-1.설비자재산출(전력통신)'!N107 -> 4 | F41: =VLOOKUP(C41,'8-6.자재단가비교표'!$C$7:$O$332,12,0) -> 260950.8 | G41: =INT(E41*F41) -> 1043803 | H41: =VLOOKUP(C41,'8-6.자재단가비교표'!$C$7:$O$332,13,0) -> ERP단가
B42: ='8-1.설비자재산출(전력통신)'!C108 -> 축전지함체 | C42: ='8-1.설비자재산출(전력통신)'!D108 -> UPS용, 내진랙(19") | D42: ='8-1.설비자재산출(전력통신)'!I108 -> 대 | E42: ='8-1.설비자재산출(전력통신)'!N108 -> 6 | F42: =VLOOKUP(C42,'8-6.자재단가비교표'!$C$7:$O$332,12,0) -> 1667193 | G42: =INT(E42*F42) -> 10003158 | H42: =VLOOKUP(C42,'8-6.자재단가비교표'!$C$7:$O$332,13,0) -> 견적가 | J42: =$A42 -> 0 | K42: =$B42 -> 축전지함체 | L42: =$C42 -> UPS용, 내진랙(19") | M42: =$D42 -> 대 | N42: =#REF!+#REF! -> #REF! | O42: =VLOOKUP(L42,'8-6.자재단가비교표'!$C$8:$O$332,12,0) -> 1667193 | P42: =INT(N42*O42) -> #REF! | Q42: =VLOOKUP(L42,'8-6.자재단가비교표'!$C$8:$O$328,13,0) -> 견적가 | R42: =E42-N42 -> #REF! | S42: =G42-P42 -> #REF! | T42: =#REF!+#REF! -> #REF! | U42: =P42-T42 -> #REF!
B43: ='8-1.설비자재산출(전력통신)'!C109 -> 축전지함체 | C43: ='8-1.설비자재산출(전력통신)'!D109 -> 충전기용, 내진랙(19") | D43: ='8-1.설비자재산출(전력통신)'!I109 -> 대 | E43: ='8-1.설비자재산출(전력통신)'!N109 -> 3 | F43: =VLOOKUP(C43,'8-6.자재단가비교표'!$C$7:$O$332,12,0) -> 1667193 | G43: =INT(E43*F43) -> 5001579 | H43: =VLOOKUP(C43,'8-6.자재단가비교표'!$C$7:$O$332,13,0) -> 견적가 | J43: =$A43 -> 0 | K43: =$B43 -> 축전지함체 | L43: =$C43 -> 충전기용, 내진랙(19") | M43: =$D43 -> 대 | N43: =#REF!+#REF! -> #REF! | O43: =VLOOKUP(L43,'8-6.자재단가비교표'!$C$8:$O$332,12,0) -> 1667193 | P43: =INT(N43*O43) -> #REF! | Q43: =VLOOKUP(L43,'8-6.자재단가비교표'!$C$8:$O$328,13,0) -> 견적가 | R43: =E43-N43 -> #REF! | S43: =G43-P43 -> #REF! | T43: =#REF!+#REF! -> #REF! | U43: =P43-T43 -> #REF!
N44: =#REF!+#REF! -> #REF! | R44: =E44-N44 -> #REF! | S44: =G44-P44 -> 0 | T44: =#REF!+#REF! -> #REF! | U44: =P44-T44 -> #REF!
...

Sheet 8-1.설비자재산출(전력통신)
A1: 8-1-1. 자 재 수 량 산 출 내 역( 전 력 통 신 )
A3: 1. 송변전광전송단말장치
A4: 구 분 | B4: 자재번호 | C4: 품 명 | D4: 규 격 | E4: 용 도 | F4: 시 설 구 간 | H4: 산 출 기 준 | I4: 단위 | J4: 수 량 | O4: 비 고
F6: FROM | G6: TO | J6: 동해안#1 | K6: 동강CH | L6: 신태백S/S | N6: 합계
A7: 사 급 분 | B7: 126546 | C7: 주셀프 | D7: MAIN-S | E7: 주장치용 Shelf | H7: 신설개소 1대 | I7: EA | J7: 1 | K7: 1 | L7: 1 | N7: =SUM(J7:M7) -> 3
B8: 126547 | C8: 확장셀프 | D8: EXT-S | E8: 확장용 Shelf | H8: 필요시(PIU 5유니트 이상시) | I8: EA | N8: =SUM(J8:M8) -> 0
B9: 126548 | C9: 광전송유니트(A) | D9: CTRU(A) | E9: 1.25G X 8파장, 40㎞용 광전송유니트, CWDM Transmit & Receive Unit | H9: 주 Shelf 1대당 2EA | I9: EA | K9: 2 | L9: 2 | N9: =SUM(J9:M9) -> 4 | O9: 광점퍼코드 포함
B10: 126549 | C10: 광전송유니트(B) | D10: CTRU(B) | E10: 1.25G X 8파장, 100㎞용 광전송유니트, CWDM Transmit & Receive Unit | H10: 주 Shelf 1대당 2EA | I10: 대 | N10: =SUM(J10:M10) -> 0 | O10: 광점퍼코드 포함
B11: 126550 | C11: 광전송유니트(C) | D11: CTRU(C) | E11: 1.25G X 8파장, 200㎞용 광전송유니트, CWDM Transmit & Receive Unit | H11: 주 Shelf 1대당 2EA | I11: EA | J11: 2 | N11: =SUM(J11:M11) -> 2 | O11: 광점퍼코드 포함
B12: 126551 | C12: 제어유니트 | D12: MCU | E12: 운용 제어 유니트, Main Control Unit | H12: 주 Shelf, 확장샐프 각 1대당 1EA | I12: EA | J12: 1 | K12: 1 | L12: 1 | N12: =SUM(J12:M12) -> 3
B13: 126552 | C13: DS-1/E 회선유니트 | D13: LIU | E13: DS-1/E 수용 유니트(12CH), Line Interface Unit | H13: 필요수량 | I13: EA | J13: 2 | K13: 1 | N13: =SUM(J13:M13) -> 3
B14: 126553 | C14: 계통보호 회선유니트 | D14: PIU | E14: 계통보호신호 수용 유니트(1CH), Protective Information Unit | H14: 1T/L당 2EA, 단거리(or 345) 1T/L당 4EA | I14: EA | N14: =SUM(J14:M14) -> 0
B15: 126554 | C15: 확장셀프 데이터 집선유니트 | D15: ECU | E15: 주셀프 ∼ 확장셀프간 연결 유니트, Extension Concentraion Unit | H15: 확장셀프당 2EA | I15: EA | N15: =SUM(J15:M15) -> 0
B16: 127955 | C16: 채널급 유니트 | D16: 4W E&M | E16: 채널급 회선 구성용 | H16: Shelf 1대당 2EA | I16: EA | N16: =SUM(J16:M16) -> 0
B17: 126555 | C17: P-to-P(A) 광전송장치 | D17: PTPU(A) | E17: DS-1/E급 데이터 전송을 위한 40km용 광전송장치 | H17: T/L구간별 1대/개소(계통보호용) | I17: EA | N17: =SUM(J17:M17) -> 0 | O17: 광점퍼코드 포함
B18: 126556 | C18: P-to-P(B) 광전송장치 | D18: PTPU(B) | E18: DS-1/E급 데이터 전송을 위한 100km용 광전송장치 | H18: T/L구간별 1대/개소(계통보호용) | I18: EA | N18: =SUM(J18:M18) -> 0 | O18: 광점퍼코드 포함
B19: 126557 | C19: P-to-P(C) 광전송장치 | D19: PTPU(C) | E19: DS-1/E급 데이터 전송을 위한 200km용 광전송장치 | H19: T/L구간별 1대/개소(계통보호용) | I19: EA | J19: 1 | L19: 1 | N19: =SUM(J19:M19) -> 2 | O19: 광점퍼코드 포함
B20: 126558 | C20: 전용랙(내진) | D20: 19"-내진랙 | E20: 19" 타입 내진 RACK 및 부대장비 | H20: 주장치, PTP, L3 SW, 확장셀프용 | I20: EA | J20: 2 | K20: 1 | L20: 1 | N20: =SUM(J20:M20) -> 4
B21: 120544 | C21: 챔프케이블(송광치) | D21: CH-SM-15(송광치) | E21: 송변전광단말 원격지용 PtoP 장치 | H21: HSR PtoP 1개, LIU 1개 | I21: EA | J21: =J13/2+J17+J18+J19+J16/2 -> 2 | K21: =ROUNDUP(K13/2+K17+K18+K19+K16/2,0) -> 1 | L21: =L13/2+L17+L18+L19+L16/2 -> 1 | N21: =SUM(J21:M21) -> 4 | O21: 신형 PTP용
B22: 120669 | C22: 집중배선반 | D22: QDF | E22: 채널급 종속신호 분배용 | H22: E1/G.703 1대/개소, LIU, PtpP 1대당 1EA | I22: EA | J22: =J13/2+IF(J14=0,0,J14/J14)+J17+J18+J19+J27+J28+J16/2 -> 2 | K22: =ROUNDUP(K13/2+IF(K14=0,0,K14/K14)+K17+K18+K19+K27+K28+K16/2,0) -> 1 | L22: =L13/2+IF(L14=0,0,L14/L14)+L17+L18+L19+L27+L28+L16/2 -> 1 | N22: =SUM(J22:M22) -> 4 | O22: 신형 PTP+구형PTP용 포함
B23: 109725 | C23: 중간배선반 | D23: IDF | E23: T1/E1, 채널급 종속신호 분배용 | H23: E1/G.703 1대/개소, LIU, PtpP 1대당 1EA | I23: EA | N23: =SUM(J23:M23) -> 0 | O23: 신형 PTP+구형PTP용 포함
B24: 127037 | C24: 송변전용스위치(A) | D24: L3SWU(A) | E24: L3 스위치(4Port)(기본형) | H24: 사내망(업무망, 인터넷망), FA, 무인보안 | I24: EA | J24: 6 | K24: 1 | N24: =SUM(J24:M24) -> 7 | O24: OA, FA, 인터넷망, 통합보안,지중감시,가평지중감시
C25: 광증폭기 | D25: 8CH | E25: 장거리 선로 광단말장치 신호 보강 | H25: 신가평~신태백 2EA, 동강 2EA, 예비품 1EA | I25: EA | K25: 2 | L25: 3 | N25: =SUM(J25:M25) -> 5 | O25: 신가평 2EA, 동강 1EA, 신태백 : 2EA(예비품 포함)
B26: 127038 | C26: 송변전용스위치(B) | D26: L3SWU(B) IRIG-B신호 수신 | E26: L3 스위치(4Port) (IRIG-B신호 수신모듈 내장형) | H26: PIU용 | I26: EA | N26: =SUM(J26:M26) -> 0
B27: 124668 | C27: 통합단말 부속장비 | D27: PTPU(A), 40km | E27: 통합단말 원격지용 PtoP 장치 | H27: 구)PtoP 1대당 2EA | I27: EA | N27: =SUM(J27:M27) -> 0 | O27: PIU예비/DAS용
B28: 124669 | C28: 통합단말 부속장비 | D28: PTPU(B), 100km | E28: 통합단말 원격지용 PtoP 장치 | H28: 구)PtoP 1대당 2EA | I28: EA | N28: =SUM(J28:M28) -> 0
B29: 109726 | C29: 통화로분선반 | D29: VDF | E29: T1/E1, CH급 회선 연결용 | H29: 구)PtoP 1대당 1EA | I29: EA | N29: =SUM(J29:M29) -> 0 | O29: 구)PTPU CH급
B30: 120544 | C30: 챔프케이블(구형 PTP) | D30: CH-SM-15(구형 PTP) | E30: 통합단말 원격지용 PtoP 장치 | H30: 구)PtoP 2개 | I30: EA | N30: =SUM(J30:M30) -> 0 | O30: 구형 PTP용
B31: 120543 | C31: LIU-DS | D31: LIU-DS | E31: 디지털 SCADA 집선장치, DS-1E 20CH, Ethernet 6CH | H31: 필요수량 | I31: EA | N31: =SUM(J31:M31) -> 0 | O31: SCADA회선구성용
C32: 컨테이너 | D32: ICT실용, 냉방기, 단열재, 운송 설치 포함 | E32: 동강C/H ICT실 컨테이너 | H32: 필요수량 | I32: EA | K32: 1 | N32: =SUM(J32:M32) -> 1
A33: 도 급 분 | B33: 주장치 | C33: 난연성제어케이블 | D33: FR-CVV-S, 6SQ/2C | E33: 송변전광전송장치 전원㈜ | F33: FADP 전원부㈜ | G33: 전원분전반(충전기) | H33: 거리 * 1조 | I33: m | J33: ='10-3-1. 송광단말케이블LIST(동해안)'!$H4+'10-3-1. 송광단말케이블LIST(동해안)'!$H15 -> 26 | K33: ='10-3-2. 송광단말케이블LIST(동강)'!H4+'10-3-2. 송광단말케이블LIST(동강)'!H15 -> 8 | L33: ='10-3-3. 송광단말케이블LIST(신태백)'!H4+'10-3-3. 송광단말케이블LIST(신태백)'!H15 -> 18 | N33: =SUM(J33:M33) -> 52
C34: 난연성제어케이블 | D34: FR-CVV-S, 6SQ/2C | E34: 송변전광전송장치 전원(예) | F34: FADP 전원부(예) | G34: 전원분전반(UPS) | H34: 거리 * 1조 | I34: m | J34: ='10-3-1. 송광단말케이블LIST(동해안)'!$H5+'10-3-1. 송광단말케이블LIST(동해안)'!$H16 -> 26 | K34: ='10-3-2. 송광단말케이블LIST(동강)'!H5+'10-3-2. 송광단말케이블LIST(동강)'!H16 -> 8 | L34: ='10-3-3. 송광단말케이블LIST(신태백)'!H5+'10-3-3. 송광단말케이블LIST(신태백)'!H16 -> 18 | N34: =SUM(J34:M34) -> 52
C35: 난연성제어케이블 | D35: FR-CVV-S, 6SQ/2C | E35: Rack AC전원 | F35: 단말장치/IDF Rack | G35: 전원분전반(UPS) | H35: 거리 * 1조 | I35: m | J35: ='10-3-1. 송광단말케이블LIST(동해안)'!$H6+'10-3-1. 송광단말케이블LIST(동해안)'!$H17 -> 26 | K35: ='10-3-2. 송광단말케이블LIST(동강)'!H6+'10-3-2. 송광단말케이블LIST(동강)'!H17 -> 8 | L35: ='10-3-3. 송광단말케이블LIST(신태백)'!H6+'10-3-3. 송광단말케이블LIST(신태백)'!H17 -> 18 | N35: =SUM(J35:M35) -> 52
C36: 광점퍼코드 | D36: SC/APC-SC/APC, 15m, 1C | E36: 광선로 구성(패치용) | F36: OFD | G36: OFD | H36: 거리 * 1조 | I36: EA | J36: ='10-3-1. 송광단말케이블LIST(동해안)'!H8/2+'10-3-1. 송광단말케이블LIST(동해안)'!H19/2 -> 16 | K36: ='10-3-2. 송광단말케이블LIST(동강)'!H8/2+'10-3-2. 송광단말케이블LIST(동강)'!H19/2 -> 16 | L36: ='10-3-3. 송광단말케이블LIST(신태백)'!H8/2+'10-3-3. 송광단말케이블LIST(신태백)'!H19/2 -> 12 | N36: =SUM(J36:M36) -> 44
C37: UTP케이블 | D37: UTP CAT.5E 100P | E37: DS0신호 결선(C-MUX) | F37: C-MUX(DSO출력,VDF) | G37: C-MUX(VDF,MDF) | H37: 거리 * 1조 | I37: m
C38: UTP케이블 | D38: UTP CAT.5E 25P | E38: DS0신호 결선(PtoP,C-MUX) | F38: PTP,C-MUX(DSO출력/VDF) | G38: PTP,C-MUX(VDF/MDF) | H38: 거리 * 1조 | I38: m
C39: UTP케이블 | D39: CAT.5E 4P | E39: LAN 구성용 | F39: 주셀프 | G39: LAN HUB | H39: 거리 * 1조 | I39: m | J39: ='10-3-1. 송광단말케이블LIST(동해안)'!$H10+'10-3-1. 송광단말케이블LIST(동해안)'!$H21 -> 27 | K39: ='10-3-2. 송광단말케이블LIST(동강)'!H10+'10-3-2. 송광단말케이블LIST(동강)'!H21 -> 6 | L39: ='10-3-3. 송광단말케이블LIST(신태백)'!H10+'10-3-3. 송광단말케이블LIST(신태백)'!H21 -> 10 | N39: =SUM(J39:M39) -> 43
C40: UTP케이블 | D40: CAT.5E 4P | E40: TRMS용 경보 | F40: 주셀프 | G40: EPIA | H40: 거리 * 1조 | I40: m | J40: ='10-3-1. 송광단말케이블LIST(동해안)'!$H12+'10-3-1. 송광단말케이블LIST(동해안)'!$H23 -> 24 | K40: ='10-3-2. 송광단말케이블LIST(동강)'!H12+'10-3-2. 송광단말케이블LIST(동강)'!H23 -> 8 | L40: ='10-3-3. 송광단말케이블LIST(신태백)'!H12+'10-3-3. 송광단말케이블LIST(신태백)'!H23 -> 7 | N40: =SUM(J40:M40) -> 39
C41: 후렉시블전선관 | D41: 22㎜, 일반방수(GW-22) | E41: 케이블 보호(광점퍼코드) | F41: 광카드(CTRU/PtoP) | G41: OFD | H41: 거리 * 1조 | I41: m | J41: ='10-3-1. 송광단말케이블LIST(동해안)'!$H9+'10-3-1. 송광단말케이블LIST(동해안)'!$H20 -> 16 | K41: ='10-3-2. 송광단말케이블LIST(동강)'!H9+'10-3-2. 송광단말케이블LIST(동강)'!H20 -> 16 | L41: ='10-3-3. 송광단말케이블LIST(신태백)'!H9+'10-3-3. 송광단말케이블LIST(신태백)'!H20 -> 12 | N41: =SUM(J41:M41) -> 44
C42: 후렉시블전선관 | D42: 16㎜, 일반방수(GW-16) | E42: 케이블 보호(광점퍼코드) | F42: OFD | G42: OFD | H42: 거리 * 1조 | I42: m | N42: =SUM(J42:M42) -> 0
...

Sheet 8-2.설비자재산출(무인보안)
A1: - | C1: 8-1-2. 자 재 수 량 산 출 내 역 ( 무 인 보 안 )
EN2: 설비관리동 | FF2: 옥외 | FN2: 본관동 | GA2: 동강
B3: 번호 | D3: 단 위 공 종 | G3: 단위 | H3: 할증후 수량 (재료비) | I3: 할증 (%) | J3: 산출수량 (노임) | K3: 설비관리동 | CF3: 본관동 | DY3: 옥외 | EG3: 설비관리동 | EK3: 본관동 | EN3: COT | EO3: RT#502 | EP3: RT#501 | EQ3: RT#503 | ER3: RT#504 | ES3: RT403 | ET3: RT#402 | EU3: RT#401 | EV3: RT#301 | EW3: RT#202 | EX3: RT#203 | EY3: RT#201 | EZ3: RT#105 | FA3: RT#104 | FB3: RT#103 | FC3: RT#102 | FD3: RT#101 | FE3: RT#B01 | FF3: RT#01 | FG3: RT#02 | FH3: RT#03 | FI3: RT#04 | FJ3: RT#05 | FK3: RT#06 | FL3: RT#07 | FM3: RT#08 | FN3: RT#A101 | FO3: RT#A102 | FP3: RT#B102 | FQ3: RT#B101 | FR3: RT#B201 | FS3: RT#B103 | FT3: RT#B104 | FU3: RT#옥상1 | FV3: RT#C401 | FW3: RT#C101 | FX3: RT#A104 | FY3: RT#A103 | FZ3: RT#A201 | GB3: 비고
C4: 자재번호 | D4: 품 명 | E4: 규 격 | F4: 구간 | K4: RACK | L4: CA 1번 | M4: CA 2번 | N4: CA 3번 | O4: CA 4번 | P4: CA 5번 | Q4: CA 6번 | R4: CA 7번 | S4: CA 8번 | T4: CA 9번 | U4: CA 10번 | V4: CA 11번 | W4: CA 12번 | X4: CA 13번 | Y4: CA 14번 | Z4: CA 15번 | AA4: CA 16번 | AB4: CA 17번 | AC4: CA 18번 | AD4: CA 19번 | AE4: CA 20번 | AF4: CA 21번 | AG4: CA 22번 | AH4: CA 23번 | AI4: CA 24번 | AJ4: CA 25번 | AK4: CA 26번 | AL4: CA 27번 | AM4: CA 28번 | AN4: CA 29번 | AO4: CA 30번 | AP4: CA 31번 | AQ4: CA 32번 | AR4: CA 33번 | AS4: CA 34번 | AT4: CA 35번 | AU4: CA 36번 | AV4: CA 37번 | AW4: CA 38번 | AX4: CA 39번 | AY4: CA 40번 | AZ4: CA 41번 | BA4: CA 42번 | BB4: CA 43번 | BC4: CA 44번 | BD4: CA 45번 | BE4: CA 46번 | BF4: CA 47번 | BG4: CA 48번 | BH4: CA 49번 | BI4: CA 50번 | BJ4: CA 51번 | BK4: CA 52번 | BL4: CA 53번 | BM4: CA 54번 | BN4: CA 55번 | BO4: CA 56번 | BP4: CA 57번 | BQ4: CA 58번 | BR4: CA 59번 | BS4: CA 60번 | BT4: CA 61번 | BU4: CA 62번 | BV4: CA 63번 | BW4: CA 64번 | BX4: CA 65번 | BY4: CA 66번 | BZ4: CA 67번 | CA4: CA 68번 | CB4: CA 69번 | CC4: CA 70번 | CD4: CA 71번 | CE4: CA 72번 | CF4: CA 73번 | CG4: CA 74번 | CH4: CA 75번 | CI4: CA 76번 | CJ4: CA 77번 | CK4: CA 78번 | CL4: CA 79번 | CM4: CA 80번 | CN4: CA 81번 | CO4: CA 82번 | CP4: CA 83번 | CQ4: CA 84번 | CR4: CA 85번 | CS4: CA 86번 | CT4: CA 87번 | CU4: CA 88번 | CV4: CA 89번 | CW4: CA 90번 | CX4: CA 91번 | CY4: CA 92번 | CZ4: CA 93번 | DA4: CA 94번 | DB4: CA 95번 | DC4: CA 96번 | DD4: CA 97번 | DE4: CA 98번 | DF4: CA 99번 | DG4: CA 100번 | DH4: CA 101번 | DI4: CA 102번 | DJ4: CA 103번 | DK4: CA 104번 | DL4: CA 105번 | DM4: CA 106번 | DN4: CA 107번 | DO4: CA 108번 | DP4: CA 109번 | DQ4: CA 110번 | DR4: CA 111번 | DS4: CA 112번 | DT4: CA 113번 | DU4: CA 114번 | DV4: CA 115번 | DW4: CA 116번 | DX4: CA 117번 | DY4: CA 120번 | DZ4: CA 121번 | EA4: CA 122번 | EB4: CA 123번 | EC4: CA 124번 | ED4: CA 125번 | EE4: CA 126번 | EF4: CA 127번 | EG4: 침투주장치 | EH4: 현관 | EI4: 출입문 | EJ4: 출입문 | EK4: 출입문 | EL4: 출입문 | EM4: 출입문 | EN4: RT#502-> | EO4: COT-> | EP4: RT#502> | EQ4: RT#501-> | ER4: RT#503-> | ES4: RT#504-> | ET4: RT#403-> | EU4: RT#402-> | EV4: RT#401-> | EW4: RT#301-> | EX4: RT#202-> | EY4: RT#203-> | EZ4: RT#201-> | FA4: RT105-> | FB4: RT#104-> | FC4: RT#103-> | FD4: RT#102-> | FE4: RT#101-> | FF4: RT#B01-> | FG4: RT#01-> | FH4: RT#02-> | FI4: RT#03-> | FJ4: RT#04-> | FK4: RT#05-> | FL4: RT#B01-> | FM4: RT#B01-> | FN4: RT#08 | FO4: RT#A101-> | FP4: RT#A102-> | FQ4: RT#B102-> | FR4: RT#B101-> | FS4: RT#B201-> | FT4: RT#B103-> | FU4: RT#B104-> | FV4: RT#옥상1-> | FW4: RT#C401-> | FX4: RT#C101-> | FY4: RT#A104-> | FZ4: RT#A103-> | GC4: 광케이블
K5: COT | L5: RT#B01 | M5: RT#B01 | N5: RT#101 | O5: RT#101 | P5: RT#101 | Q5: RT#102 | R5: RT#102 | S5: RT#102 | T5: RT#103 | U5: RT#103 | V5: RT#103 | W5: RT#103 | X5: RT#104 | Y5: RT#104 | Z5: RT#104 | AA5: RT#104 | AB5: RT#105 | AC5: RT#105 | AD5: RT#105 | AE5: RT#201 | AF5: RT#201 | AG5: RT#201 | AH5: RT#201 | AI5: RT#201 | AJ5: RT#201 | AK5: RT#202 | AL5: RT#202 | AM5: RT#202 | AN5: RT#202 | AO5: RT#202 | AP5: RT#202 | AQ5: RT#203 | AR5: RT#203 | AS5: RT#203 | AT5: RT#203 | AU5: RT#203 | AV5: RT#203 | AW5: RT#301 | AX5: RT#301 | AY5: RT#301 | AZ5: RT#301 | BA5: RT#401 | BB5: RT#401 | BC5: RT#401 | BD5: RT#401 | BE5: RT#402 | BF5: RT#402 | BG5: RT#402 | BH5: RT#402 | BI5: RT#403 | BJ5: RT#403 | BK5: RT#403 | BL5: RT#403 | BM5: RT#501 | BN5: RT#501 | BO5: RT#501 | BP5: RT#501 | BQ5: RT#501 | BR5: RT#502 | BS5: RT#502 | BT5: RT#503 | BU5: RT#503 | BV5: RT#503 | BW5: RT#503 | BX5: RT#503 | BY5: RT#503 | BZ5: RT#504 | CA5: RT#504 | CB5: RT#504 | CC5: RT#504 | CD5: RT#504 | CE5: RT#504 | CF5: RT#A101 | CG5: RT#A101 | CH5: RT#A102 | CI5: RT#A102 | CJ5: RT#A103 | CK5: RT#A103 | CL5: RT#A103 | CM5: RT#A103 | CN5: RT#A103 | CO5: RT#A104 | CP5: RT#A104 | CQ5: RT#A104 | CR5: RT#B101 | CS5: RT#B101 | CT5: RT#B101 | CU5: RT#B102 | CV5: RT#B102 | CW5: RT#B103 | CX5: RT#B103 | CY5: RT#B103 | CZ5: RT#B103 | DA5: RT#B103 | DB5: RT#B104 | DC5: RT#B104 | DD5: RT#B104 | DE5: RT#C101 | DF5: RT#C101 | DG5: RT#C101 | DH5: RT#A201 | DI5: RT#A201 | DJ5: RT#A201 | DK5: RT#A201 | DL5: RT#A201 | DM5: RT#B201 | DN5: RT#B201 | DO5: RT#B201 | DP5: RT#B201 | DQ5: RT#B201 | DR5: RT#C401 | DS5: RT#C401 | DT5: RT#C401 | DU5: RT#C401 | DV5: RT#C401 | DW5: RT#옥상1 | DX5: RT#옥상1 | DY5: RT#01 | DZ5: RT#02 | EA5: RT#03 | EB5: RT#04 | EC5: RT#05 | ED5: RT#06 | EE5: RT#07 | EF5: RT#A08 | EG5: COT | EH5: RT#101 | EI5: RT#501 | EJ5: RT#502 | EK5: RT#A101 | EL5: RT#B101 | EM5: RT#C101 | EU5: COT-> | EV5: COT-> | FD5: COT-> | FF5: COT-> | FN5: COT-> | GC5: 전원케이블
K6: 지상5층 | L6: 지하1층 | M6: 지하1층 | N6: 지상1층 | O6: 지상1층 | P6: 지상1층 | Q6: 지상1층 | R6: 지상1층 | S6: 지상1층 | T6: 지상1층 | U6: 지상1층 | V6: 지상1층 | W6: 지상1층 | X6: 지상1층 | Y6: 지상1층 | Z6: 지상1층 | AA6: 지상1층 | AB6: 지상1층 | AC6: 지상1층 | AD6: 지상1층 | AE6: 지상2층 | AF6: 지상2층 | AG6: 지상2층 | AH6: 지상2층 | AI6: 지상2층 | AJ6: 지상2층 | AK6: 지상2층 | AL6: 지상2층 | AM6: 지상2층 | AN6: 지상2층 | AO6: 지상2층 | AP6: 지상2층 | AQ6: 지상2층 | AR6: 지상2층 | AS6: 지상2층 | AT6: 지상2층 | AU6: 지상2층 | AV6: 지상2층 | AW6: 지상3층 | AX6: 지상3층 | AY6: 지상3층 | AZ6: 지상3층 | BA6: 지상4층 | BB6: 지상4층 | BC6: 지상4층 | BD6: 지상4층 | BE6: 지상4층 | BF6: 지상4층 | BG6: 지상4층 | BH6: 지상4층 | BI6: 지상4층 | BJ6: 지상4층 | BK6: 지상4층 | BL6: 지상4층 | BM6: 지상5층 | BN6: 지상5층 | BO6: 지상5층 | BP6: 지상5층 | BQ6: 지상5층 | BR6: 지상5층 | BS6: 지상5층 | BT6: 지상5층 | BU6: 지상5층 | BV6: 지상5층 | BW6: 지상5층 | BX6: 지상5층 | BY6: 지상5층 | BZ6: 지상5층 | CA6: 지상5층 | CB6: 지상5층 | CC6: 지상5층 | CD6: 지상5층 | CE6: 지상5층 | CF6: 지상1층 | CG6: 지상1층 | CH6: 지상1층 | CI6: 지상1층 | CJ6: 지상1층 | CK6: 지상1층 | CL6: 지상1층 | CM6: 지상1층 | CN6: 지상1층 | CO6: 지상1층 | CP6: 지상1층 | CQ6: 지상1층 | CR6: 지상1층 | CS6: 지상1층 | CT6: 지상1층 | CU6: 지상1층 | CV6: 지상1층 | CW6: 지상1층 | CX6: 지상1층 | CY6: 지상1층 | CZ6: 지상1층 | DA6: 지상1층 | DB6: 지상1층 | DC6: 지상1층 | DD6: 지상1층 | DE6: 지상1층 | DF6: 지상2층 | DG6: 지상3층 | DH6: 지상2층 | DI6: 지상2층 | DJ6: 지상2층 | DK6: 지상2층 | DL6: 지상2층 | DM6: 지상2층 | DN6: 지상2층 | DO6: 지상2층 | DP6: 지상2층 | DQ6: 지상2층 | DR6: 지상4층 | DS6: 지상4층 | DT6: 지상4층 | DU6: 지상4층 | DV6: 지상4층 | DW6: 옥상층 | DX6: 옥상층 | DY6: 옥외 | DZ6: 옥외 | EA6: 옥외 | EB6: 옥외 | EC6: 옥외 | ED6: 옥외 | EE6: 옥외 | EF6: 옥외 | EG6: 지상5층 | EH6: 지상1층 | EI6: 지상5층 | EJ6: 지상5층 | EK6: 지상1층 | EL6: 지상1층 | EM6: 지상1층 | EN6: 지상5층 | EO6: 지상5층 | EP6: 지상5층 | EQ6: 지상5층 | ER6: 지상5층 | ES6: 지상4층 | ET6: 지상4층 | EU6: 지상4층 | EV6: 지상3층 | EW6: 지상2층 | EX6: 지상2층 | EY6: 지상2층 | EZ6: 지상1층 | FA6: 지상1층 | FB6: 지상1층 | FC6: 지상1층 | FD6: 지상1층 | FE6: 지하1층 | FF6: 옥외 | FG6: 옥외 | FH6: 옥외 | FI6: 옥외 | FJ6: 옥외 | FK6: 옥외 | FL6: 옥외 | FM6: 옥외 | FN6: 지상1층 | FO6: 지상1층 | FP6: 지상1층 | FQ6: 지상1층 | FR6: 지상2층 | FS6: 지상1층 | FT6: 지상1층 | FU6: 지상4층 | FV6: 지상4층 | FW6: 지상1층 | FX6: 지상1층 | FY6: 지상1층 | FZ6: 지상2층
K7: ICT실 | L7: CAM#B01 | M7: CAM#B02 | N7: CAM#101 | O7: CAM#102 | P7: CAM#103 | Q7: CAM#104 | R7: CAM#105 | S7: CAM#106 | T7: CAM#107 | U7: CAM#108 | V7: CAM#109 | W7: CAM#110 | X7: CAM#111 | Y7: CAM#112 | Z7: CAM#113 | AA7: CAM#114 | AB7: CAM#115 | AC7: CAM#116 | AD7: CAM#117 | AE7: CAM#201 | AF7: CAM#202 | AG7: CAM#203 | AH7: CAM#204 | AI7: CAM#205 | AJ7: CAM#206 | AK7: CAM#207 | AL7: CAM#208 | AM7: CAM#209 | AN7: CAM#210 | AO7: CAM#211 | AP7: CAM#212 | AQ7: CAM#213 | AR7: CAM#214 | AS7: CAM#215 | AT7: CAM#216 | AU7: CAM#217 | AV7: CAM#218 | AW7: CAM#301 | AX7: CAM#302 | AY7: CAM#303 | AZ7: CAM#304 | BA7: CAM#401 | BB7: CAM#402 | BC7: CAM#403 | BD7: CAM#404 | BE7: CAM#405 | BF7: CAM#406 | BG7: CAM#407 | BH7: CAM#408 | BI7: CAM#409 | BJ7: CAM#410 | BK7: CAM#411 | BL7: CAM#412 | BM7: CAM#501 | BN7: CAM#502 | BO7: CAM#503 | BP7: CAM#504 | BQ7: CAM#505 | BR7: CAM#506 | BS7: CAM#507 | BT7: CAM#508 | BU7: CAM#509 | BV7: CAM#510 | BW7: CAM#511 | BX7: CAM#512 | BY7: CAM#513 | BZ7: CAM#514 | CA7: CAM#515 | CB7: CAM#516 | CC7: CAM#517 | CD7: CAM#518 | CE7: CAM#519 | CF7: CAM#A101 | CG7: CAM#A102 | CH7: CAM#A103 | CI7: CAM#A104 | CJ7: CAM#A105 | CK7: CAM#A106 | CL7: CAM#A107 | CM7: CAM#A108 | CN7: CAM#A109 | CO7: CAM#A110 | CP7: CAM#A111 | CQ7: CAM#A112 | CR7: CAM#B101 | CS7: CAM#B102 | CT7: CAM#전력구 | CU7: CAM#B103 | CV7: CAM#B104 | CW7: CAM#B105 | CX7: CAM#B106 | CY7: CAM#B107 | CZ7: CAM#B108 | DA7: CAM#B109 | DB7: CAM#B110 | DC7: CAM#B111 | DD7: CAM#B112 | DE7: CAM#C101 | DF7: CAM#C201 | DG7: CAM#C301 | DH7: CAM#A201 | DI7: CAM#A202 | DJ7: CAM#A203 | DK7: CAM#A204 | DL7: CAM#A205 | DM7: CAM#B201 | DN7: CAM#B202 | DO7: CAM#B203 | DP7: CAM#B204 | DQ7: CAM#B205 | DR7: CAM#C401 | DS7: CAM#C402 | DT7: CAM#C403 | DU7: CAM#C404 | DV7: CAM#C405 | DW7: CAM함체#옥상1,2 | DX7: CAM함체#옥상3,4 | DY7: CAM#01 | DZ7: CAM#02 | EA7: CAM#03 | EB7: CAM#04 | EC7: CAM#05 | ED7: CAM#06 | EE7: CAM#07 | EF7: CAM#08 | EG7: 감시실 | EH7: 현관 | EI7: ICT실 | EJ7: 감시실 | EK7: 현관 | EL7: 현관 | EM7: 현관 | EN7: ICT실 RACK
B8: 가. | C8: 가. | D8: 회사분
A9: 1 | B9: 1 | C9: 126571 | D9: 녹화장치(동강C/H) | E9: 4core 2.4GHz*1EA이상,8GB이상, SSD256GB,스토리지4TB이하 | G9: 대 | H9: =ROUNDUP(J9+INT(J9*I9/100),1) -> 1 | J9: =ROUNDUP(SUM(K9:GA9),1) -> 1 | GA9: 1
A10: 2 | B10: =B9+1 -> 2 | C10: 126571 | D10: 녹화장치 | E10: 4core 2.4GHz*1EA이상,16GB이상, SSD512GB,스토리지80TB이상 | G10: 대 | H10: =ROUNDUP(J10+INT(J10*I10/100),1) -> 2 | J10: =ROUNDUP(SUM(K10:GA10),1) -> 2 | K10: 2
A11: 3 | B11: =B10+1 -> 3 | C11: 126572 | D11: 운영자 단말 | E11: 2.9GHz, 16GB, Display 다중전송, 23인치 이상 LCD모니터 포함 | G11: 대 | H11: =ROUNDUP(J11+INT(J11*I11/100),1) -> 4 | J11: =ROUNDUP(SUM(K11:GA11),1) -> 4 | K11: 3 | GA11: 1
A12: 4 | B12: =B11+1 -> 4 | C12: 126573 | D12: 멀티 모니터링장치 | E12: 3.4GHz, 8GB, Display 다중전송 | G12: 대 | H12: =ROUNDUP(J12+INT(J12*I12/100),1) -> 0 | J12: =ROUNDUP(SUM(K12:GA12),1) -> 0
A13: 5 | B13: =B12+1 -> 5 | C13: 126574 | D13: KVM스위치 | E13: 8채널 이상, 19" 랙타입 | G13: 대 | H13: =ROUNDUP(J13+INT(J13*I13/100),1) -> 1 | J13: =ROUNDUP(SUM(K13:GA13),1) -> 1 | K13: 1
A14: 6 | B14: =B13+1 -> 6 | C14: 126575 | D14: 42" LED모니터 | E14: 42” 이상 (16:9 지원) | G14: 대 | H14: =ROUNDUP(J14+INT(J14*I14/100),1) -> 0 | J14: =ROUNDUP(SUM(K14:GA14),1) -> 0
A15: 7 | B15: =B14+1 -> 7 | C15: 126576 | D15: 55" LED모니터 | E15: 55” 이상 (16:9 지원) | G15: 대 | H15: =ROUNDUP(J15+INT(J15*I15/100),1) -> 4 | J15: =ROUNDUP(SUM(K15:GA15),1) -> 4 | K15: 4
A16: 8 | B16: =B15+1 -> 8 | C16: 126577 | D16: 영상추적서버 | E16: 3.4GHz, 8GB, SATA 1TB | G16: 대 | H16: =ROUNDUP(J16+INT(J16*I16/100),1) -> 0 | J16: =ROUNDUP(SUM(K16:GA16),1) -> 0
A17: 9 | B17: =B16+1 -> 9 | C17: 126578 | D17: 영상추적 소프트웨어 | E17: 영상분석, 움직임추적 | G17: 개 | H17: =ROUNDUP(J17+INT(J17*I17/100),1) -> 0 | J17: =ROUNDUP(SUM(K17:GA17),1) -> 0
A18: 10 | B18: =B17+1 -> 10 | C18: 126579 | D18: 오디오앰프 | E18: 30W, G.711 또는 G729a/b | G18: 개 | H18: =ROUNDUP(J18+INT(J18*I18/100),1) -> 0 | J18: =ROUNDUP(SUM(K18:GA18),1) -> 0
A19: 11 | B19: =B18+1 -> 11 | C19: 126580 | D19: Full-HD PTZ IP카메라(30X) | E19: 30배줌, Onvif 2.0, TTA인증 | G19: 대 | H19: =ROUNDUP(J19+INT(J19*I19/100),1) -> 0 | J19: =ROUNDUP(SUM(K19:GA19),1) -> 0
A20: 12 | B20: =B19+1 -> 12 | C20: 126581 | D20: Full-HD PTZ IP카메라(20X) | E20: 20배줌, Onvif 2.0, TTA인증 | G20: 대 | H20: =ROUNDUP(J20+INT(J20*I20/100),1) -> 127 | J20: =ROUNDUP(SUM(K20:GA20),1) -> 127 | L20: 1 | M20: 1 | N20: 1 | O20: 1 | P20: 1 | Q20: 1 | R20: 1 | S20: 1 | T20: 1 | U20: 1 | V20: 1 | W20: 1 | X20: 1 | Y20: 1 | Z20: 1 | AA20: 1 | AB20: 1 | AC20: 1 | AD20: 1 | AE20: 1 | AF20: 1 | AG20: 1 | AH20: 1 | AI20: 1 | AJ20: 1 | AK20: 1 | AL20: 1 | AM20: 1 | AN20: 1 | AO20: 1 | AP20: 1 | AQ20: 1 | AR20: 1 | AS20: 1 | AT20: 1 | AU20: 1 | AV20: 1 | AW20: 1 | AX20: 1 | AY20: 1 | AZ20: 1 | BA20: 1 | BB20: 1 | BC20: 1 | BD20: 1 | BE20: 1 | BF20: 1 | BG20: 1 | BH20: 1 | BI20: 1 | BJ20: 1 | BK20: 1 | BL20: 1 | BM20: 1 | BN20: 1 | BO20: 1 | BP20: 1 | BQ20: 1 | BR20: 1 | BS20: 1 | BT20: 1 | BU20: 1 | BV20: 1 | BW20: 1 | BX20: 1 | BY20: 1 | BZ20: 1 | CA20: 1 | CB20: 1 | CC20: 1 | CD20: 1 | CE20: 1 | CF20: 1 | CG20: 1 | CH20: 1 | CI20: 1 | CJ20: 1 | CK20: 1 | CL20: 1 | CM20: 1 | CN20: 1 | CO20: 1 | CP20: 1 | CQ20: 1 | CR20: 1 | CS20: 1 | CT20: 1 | CU20: 1 | CV20: 1 | CW20: 1 | CX20: 1 | CY20: 1 | CZ20: 1 | DA20: 1 | DB20: 1 | DC20: 1 | DD20: 1 | DE20: 1 | DF20: 1 | DG20: 1 | DH20: 1 | DI20: 1 | DJ20: 1 | DK20: 1 | DL20: 1 | DM20: 1 | DN20: 1 | DO20: 1 | DP20: 1 | DQ20: 1 | DR20: 1 | DS20: 1 | DT20: 1 | DU20: 1 | DV20: 1 | DW20: 2 | DX20: 2 | DY20: 1 | DZ20: 1 | EA20: 1 | EB20: 1 | EC20: 1 | ED20: 1 | EE20: 1 | EF20: 1
A21: 12 | B21: =B20+1 -> 13 | D21: Full-HD PTZ IP카메라(20X) | E21: 20배줌, Onvif 2.0 | G21: 대 | H21: =ROUNDUP(J21+INT(J21*I21/100),1) -> 0 | J21: =ROUNDUP(SUM(K21:GA21),1) -> 0
A22: 13 | B22: =B20+1 -> 13 | C22: 127781 | D22: Full-HD IP카메라(고정형) | E22: 4배줌, Onvif 2.0, TTA인증 | G22: 대 | H22: =ROUNDUP(J22+INT(J22*I22/100),1) -> 1 | J22: =ROUNDUP(SUM(K22:GA22),1) -> 1 | GA22: 1
A23: 13 | B23: =B22+1 -> 14 | C23: 126582 | D23: 19인치 랙(내진형) | E23: 내진형, 600×750×2000 | G23: 대 | H23: =ROUNDUP(J23+INT(J23*I23/100),1) -> 3 | J23: =ROUNDUP(SUM(K23:GA23),1) -> 3 | K23: 2 | GA23: 1
A24: 14 | B24: =B23+1 -> 15 | C24: 126583 | D24: 카메라함체 | E24: 방수형, Stainless | G24: 대 | H24: =ROUNDUP(J24+INT(J24*I24/100),1) -> 0 | J24: =ROUNDUP(SUM(K24:GA24),1) -> 0
A25: 15 | B25: =B24+1 -> 16 | C25: 126584 | D25: 네트워크장치함체 | E25: 네트웍 방수형, Stainless | G25: 대 | H25: =ROUNDUP(J25+INT(J25*I25/100),1) -> 0 | J25: =ROUNDUP(SUM(K25:GA25),1) -> 0
A26: 16 | B26: =B25+1 -> 17 | C26: 126585 | D26: 카메라 지지대 | E26: 일반형, W165 X H6000 X T5mm, 안전작업대 포함 | G26: 대 | H26: =ROUNDUP(J26+INT(J26*I26/100),1) -> 8 | J26: =ROUNDUP(SUM(K26:GA26),1) -> 8 | DY26: 1 | DZ26: 1 | EA26: 1 | EB26: 1 | EC26: 1 | ED26: 1 | EE26: 1 | EF26: 1
A27: 16 | B27: =B26+1 -> 18 | D27: ㄷ'자 카메라 폴대 | E27: 일반형, W700 X H700 X 200 | G27: 대 | H27: =ROUNDUP(J27+INT(J27*I27/100),1) -> 0 | J27: =ROUNDUP(SUM(K27:GA27),1) -> 0
A28: 16 | B28: =B27+1 -> 19 | D28: 스마트 카메라 지지대 | E28: 일반형, W165 X H6000 X T5mm | G28: 대 | H28: =ROUNDUP(J28+INT(J28*I28/100),1) -> 0 | J28: =ROUNDUP(SUM(K28:GA28),1) -> 0
A29: 17 | B29: =B26+1 -> 18 | C29: 127030 | D29: 카메라리프트(옥내) | E29: 카메라 승하강 동작, 자동, 수동 | G29: 대 | H29: =ROUNDUP(J29+INT(J29*I29/100),1) -> 69 | J29: =ROUNDUP(SUM(K29:GA29),1) -> 69 | Q29: 1 | R29: 1 | S29: 1 | T29: 1 | U29: 1 | V29: 1 | W29: 1 | X29: 1 | Y29: 1 | Z29: 1 | AA29: 1 | AB29: 1 | AC29: 1 | AD29: 1 | AK29: 1 | AL29: 1 | AM29: 1 | AN29: 1 | AO29: 1 | AP29: 1 | AQ29: 1 | AR29: 1 | AS29: 1 | AT29: 1 | AU29: 1 | AV29: 1 | BA29: 1 | BB29: 1 | BC29: 1 | BE29: 1 | BF29: 1 | BG29: 1 | BH29: 1 | BI29: 1 | BJ29: 1 | BK29: 1 | BL29: 1 | BT29: 1 | BU29: 1 | BV29: 1 | BW29: 1 | BX29: 1 | BY29: 1 | BZ29: 1 | CA29: 1 | CB29: 1 | CC29: 1 | CD29: 1 | CE29: 1 | CH29: 1 | CI29: 1 | CJ29: 1 | CK29: 1 | CL29: 1 | CM29: 1 | CN29: 1 | CO29: 1 | CP29: 1 | CQ29: 1 | CU29: 1 | CV29: 1 | CW29: 1 | CX29: 1 | CY29: 1 | CZ29: 1 | DA29: 1 | DB29: 1 | DC29: 1 | DD29: 1
A30: 17 | B30: =B29+1 -> 19 | C30: 127780 | D30: 카메라리프트 | E30: 카메라 승하강 동작, 자동, 수동, 방수, 6m 이하 | G30: 대 | H30: =ROUNDUP(J30+INT(J30*I30/100),1) -> 8 | J30: =ROUNDUP(SUM(K30:GA30),1) -> 8 | DY30: 1 | DZ30: 1 | EA30: 1 | EB30: 1 | EC30: 1 | ED30: 1 | EE30: 1 | EF30: 1
A31: 18 | B31: =B29+1 -> 19 | C31: 126586 | D31: 주전원공급장치 | E31: AC220V 60Hz, 8채널 | G31: 대 | H31: =ROUNDUP(J31+INT(J31*I31/100),1) -> 3 | J31: =ROUNDUP(SUM(K31:GA31),1) -> 3 | K31: 2 | GA31: 1
A32: 19 | B32: =B31+1 -> 20 | C32: 126587 | D32: 전원분배기 | E32: AC220V, 8채널 | G32: 대 | H32: =ROUNDUP(J32+INT(J32*I32/100),1) -> 0 | J32: =ROUNDUP(SUM(K32:GA32),1) -> 0
B33: =B32+1 -> 21 | C33: 126588 | D33: 서지전원장치 | E33: AC220V, 60Hz, 40KA, KS인증제품 | G33: 개 | H33: =ROUNDUP(J33+INT(J33*I33/100),1) -> 128 | J33: =ROUNDUP(SUM(K33:GA33),1) -> 128 | L33: 1 | M33: 1 | N33: 1 | O33: 1 | P33: 1 | Q33: 1 | R33: 1 | S33: 1 | T33: 1 | U33: 1 | V33: 1 | W33: 1 | X33: 1 | Y33: 1 | Z33: 1 | AA33: 1 | AB33: 1 | AC33: 1 | AD33: 1 | AE33: 1 | AF33: 1 | AG33: 1 | AH33: 1 | AI33: 1 | AJ33: 1 | AK33: 1 | AL33: 1 | AM33: 1 | AN33: 1 | AO33: 1 | AP33: 1 | AQ33: 1 | AR33: 1 | AS33: 1 | AT33: 1 | AU33: 1 | AV33: 1 | AW33: 1 | AX33: 1 | AY33: 1 | AZ33: 1 | BA33: 1 | BB33: 1 | BC33: 1 | BD33: 1 | BE33: 1 | BF33: 1 | BG33: 1 | BH33: 1 | BI33: 1 | BJ33: 1 | BK33: 1 | BL33: 1 | BM33: 1 | BN33: 1 | BO33: 1 | BP33: 1 | BQ33: 1 | BR33: 1 | BS33: 1 | BT33: 1 | BU33: 1 | BV33: 1 | BW33: 1 | BX33: 1 | BY33: 1 | BZ33: 1 | CA33: 1 | CB33: 1 | CC33: 1 | CD33: 1 | CE33: 1 | CF33: 1 | CG33: 1 | CH33: 1 | CI33: 1 | CJ33: 1 | CK33: 1 | CL33: 1 | CM33: 1 | CN33: 1 | CO33: 1 | CP33: 1 | CQ33: 1 | CR33: 1 | CS33: 1 | CT33: 1 | CU33: 1 | CV33: 1 | CW33: 1 | CX33: 1 | CY33: 1 | CZ33: 1 | DA33: 1 | DB33: 1 | DC33: 1 | DD33: 1 | DE33: 1 | DF33: 1 | DG33: 1 | DH33: 1 | DI33: 1 | DJ33: 1 | DK33: 1 | DL33: 1 | DM33: 1 | DN33: 1 | DO33: 1 | DP33: 1 | DQ33: 1 | DR33: 1 | DS33: 1 | DT33: 1 | DU33: 1 | DV33: 1 | DW33: 2 | DX33: 2 | DY33: 1 | DZ33: 1 | EA33: 1 | EB33: 1 | EC33: 1 | ED33: 1 | EE33: 1 | EF33: 1 | GA33: 1
A34: 20 | B34: =B33+1 -> 22 | C34: 126589 | D34: 경보주장치 | E34: 터치형 7인치 LCD(16DI*1, 16DO*2) | G34: 대 | H34: =ROUNDUP(J34+INT(J34*I34/100),1) -> 1 | J34: =ROUNDUP(SUM(K34:GA34),1) -> 1 | EG34: 1
A35: 20 | B35: =B34+1 -> 23 | C35: 128131 | D35: 컴팩트 LCD 출입리더기 | E35: 번호, RF카드, 지문인식(OR, AND인증 설정지원), 상태표시창 | G35: 대 | H35: =ROUNDUP(J35+INT(J35*I35/100),1) -> 6 | J35: =ROUNDUP(SUM(K35:GA35),1) -> 6 | EH35: 1 | EI35: 1 | EJ35: 1 | EK35: 1 | EL35: 1 | EM35: 1
A36: 22 | B36: =B35+1 -> 24 | C36: 126591 | D36: 출입리더기 함체 | E36: Stainless Steel, Window는 안전접합 유리 | G36: 개 | H36: =ROUNDUP(J36+INT(J36*I36/100),1) -> 0 | J36: =ROUNDUP(SUM(K36:GA36),1) -> 0
A37: 22 | B37: =B36+1 -> 25 | C37: 126592 | D37: E/M Lock | E37: 500㎏ 이상, NO/NC, Com+ | G37: 개 | H37: =ROUNDUP(J37+INT(J37*I37/100),1) -> 0 | J37: =ROUNDUP(SUM(K37:GA37),1) -> 0
A38: 22 | B38: =B37+1 -> 26 | C38: 126593 | D38: 퇴실버튼 | E38: 벽면부착형 | G38: 개 | H38: =ROUNDUP(J38+INT(J38*I38/100),1) -> 0 | J38: =ROUNDUP(SUM(K38:GA38),1) -> 0
A39: 22 | B39: =B38+1 -> 27 | C39: 126594 | D39: 지문등록기 | E39: 지문등록 | G39: 개 | H39: =ROUNDUP(J39+INT(J39*I39/100),1) -> 0 | J39: =ROUNDUP(SUM(K39:GA39),1) -> 0
A40: 22 | B40: =B39+1 -> 28 | C40: 126595 | D40: ID Card | E40: 비접촉 근접식 | G40: 개 | H40: =ROUNDUP(J40+INT(J40*I40/100),1) -> 0 | J40: =ROUNDUP(SUM(K40:GA40),1) -> 0
...

Sheet 8-3.노무산출
A2: 8-3. 노 무 임 수 량 산 출 내 역 | K2: 8-2. 노 무 임 수 량 산 출 내 역
A4: =표지!A13 -> 공사명 : 동해안#1 변환소 전력통신설비 시설공사 | K4: 공사명 : 동해안#1 변환소 전력통신설비 시설공사
A5: No. | B5: 품 셈 명 | C5: 규 격 | D5: 단 위 | I5: 단가 | J5: 비 고 | K5: No.
H6: 소계
A7: ='8-1.설비자재산출(전력통신)'!#REF! -> #REF! | K7: #REF!
