Workbook

Sheet 증감총괄
A1: 공 사 비 증.△감 내 역
A3: 공 사 명 : 평창군 에코랜드 조성사업(전기) | F3: (단위 : 원)
A4: 구 분 | B4: 당 초 | C4: 변 경 | D4: 증 | E4: △감 | F4: 비 고
A5: 총 공 사 비 | B5: =원가계산!E38 -> 5.4133038e+08 | C5: =원가계산!F38 -> 5.0510863e+08 | D5: =B5-C5 -> 36221758 | F5: 천단위절사
A6: 도 급 액 | B6: =원가계산!E29 -> 240025200 | C6: =원가계산!F29 -> 260900000 | D6: =C6-B6 -> 20874800
A7: 관급자관급 | B7: =원가계산!E33 -> 180667661 | C7: =원가계산!F33 -> 99053574 | E7: =C7-B7 -> -81614087
A8: 도급자관급 | B8: =원가계산!E34 -> 99053574 | C8: =원가계산!F34 -> 117459903 | D8: =C8-B8 -> 18406329
A9: 한전불입금 | B9: =원가계산!E36 -> 21183800 | C9: =원가계산!F36 -> 27295000 | D9: =C9-B9 -> 6111200

Sheet 표지(설계서)
B2: 관 리 번 호 | AA2: 사 본 번 호
A7: 평창군 에코랜드 조성사업(전기)
A9: [ 전 체 : 1회 변경]
AP10: `
O11: 2024. 03.
A15: 평창군

Sheet 설계서(결재란)
A1: 설계년월일 2024년 03월 일 | L1: 책임감리회사 : ㈜예강ENG
L2: 설 계 자 (책임건설사업관리기술자) | T2: 심 사 자 (기술지원건설사업관리기술자) | AB2: 대표이사
A7: ='표지(설계서)'!A7:AG7 -> 평창군 에코랜드 조성사업(전기)
A9: [ 전 체 : 1회 변경 ]
G11: 결 재 | H11: 년 월 일 | I11: 검 토 자 | N11: 계 장 | S11: 과 장 | X11: 군 수

Sheet 목차(설계변경용)
A3: 목 차
G6: Ⅰ. | I6: 설계변경사유서
G7: Ⅱ. | I7: 시방서 | S7: (변 경)
G8: Ⅲ. | I8: 보안및기타사항 | S8: (변경없음)
G9: Ⅳ. | I9: 예정공정표 | S9: (변경없음)
G10: Ⅴ. | I10: 동원인원계획표 | S10: (변경없음)
G11: Ⅵ. | I11: 공사비 증 · 감 대비표 | S11: (변 경)
G12: Ⅶ. | I12: 설계예산서

Sheet 1.설계변경사유서
A1: Ⅰ. 설 계 변 경 사 유 서
B3: ■ 건축조성 변경으로인한 변경
C4: 4) 기타 현장의 여건 변동에 따라 계약내용이 변경 시
C5: ○ 설계변경 세부내역 | H5: ○ 설계변경 제외내역
C6: 1.전력간선공사 | H6: 1.동력설비공사
C7: 2.옥외보안등공사 | H7: 2.태양광발전설비공사
C8: 3.전열공사
C9: 4.전등공사

Sheet 3.시방서
A7: Ⅲ. 공 사 시 방 서(변경없음)
A10: (별 권)

Sheet 4.보안및기타사항
A1: Ⅳ. 보안 및 기타유의사항(변경없음)
B3: 1. 수급자는 공사시행에 필요한 제반보안 대책을 수립하여야 하며 수급자 대표의 보안각서를 제출하여야 한다.
B4: 2. 수급자는 공사시행에 따른 연구내용 및 조사자료를 타용도에 임의로 사용하거나 외부로 유출되지 않도록 하여야 하며,
B5: 과업 수행중 과실로 인한 일체의 사고에 대하여는 수급자가 책임을 져야 한다.
B6: 3. 수급자는 본 공사를 위하여 수집된 모든 기록 및 자료와 모든 도면을 보관할 사람을 지정하여 발주청장의 승인을 받도록 한다.
B7: 4. 국가보안상 중요하다고 생각되는 모든 기록과 자료는 시건장치가 되어 있는 함에 보관하고 열쇠는 책임건설사업관리기술자가
B8: 소지하여야 한다.
B9: 5. 모든 비밀문서는 관리번호를 부여하고, 보관관리 기록부에 기록한 후 시건장치가 이중으로 되어있는 함에 보관하여 열쇠는 책임건설
B10: 사업관리기술자가 소지하여야 한다.
B11: 6. 수급자는 본 공사와 관련있는 모든 기록과 자료에 대하여 업무와 관련없는 일에 사용할수 있으며, 발주청장의 사전서면 승인 없이는
B12: 타인에게 제공 또는 대여할 수 없다.
B13: 7. 편입된 모든 도서 및 기타 자료를 다른 목적에 이용할 수 없으며, 공사시행시 발생한 보안사항에 대하여 사실을 누설하여서는 안되며
B14: 누설로 인하여 문제점이 발생될 시에는 책임건설사업관리기술자 및 수급자가 모든 책임을 진다.
... B18: 이 지시사항에 특별한 사유가 없는 한 이의없이 따라야 한다.

Sheet 5.예정
A7: Ⅴ.예 정 공 정 표(변경없음)

Sheet 6.동원
A7: Ⅵ. 동 원 인 원 계 획 표(변경없음)

Sheet 갑지
J2: 설 | Q2: 심 | X2: 담 | AE2: 과
B3: 2024년 03월 일 변 경 | J3: 계 | Q3: 사
J4: 자 | Q4: 자 | X4: 당 | AE4: 장
C6: 2 0 2 4 년 도
F9: 평창군 에코랜드 조성사업(전기)
G11: 1회 [변경]
H12: ▣ 공사개요
I13: ⊙ | J13: 옥내.옥외공사 | P13: : | Q13: 평창군 에코랜드 조성사업(전기)
P14: : | Q14: 평창군 에코랜드 조성사업(전기)
H20: ▣ 공 사 비
I21: ⊙ | J21: 총사업비 | N21: : | O21: ="금"&NUMBERSTRING(Z21,1)&"원" -> 금오억일천구백칠십사만육천사백삼십오원 | Z21: =Z23+Z25 -> 519746435
N22: : | O22: ="금"&NUMBERSTRING(Z22,1)&"원" -> 금사억칠천칠백사십일만삼천사백칠십칠원 | Z22: =Z24+Z26 -> 477413477
I23: ⊙ | J23: 도급예정액 | N23: : | O23: ="금"&NUMBERSTRING(Z23,1)&"원" -> 금이억사천이만오천이백원 | Z23: =원가계산!E29 -> 240025200
N24: : | O24: ="금"&NUMBERSTRING(Z24,1)&"원" -> 금이억육천구십만원 | Z24: =원가계산!F29 -> 260900000
I25: ⊙ | J25: 관급자재대 | N25: : | O25: ="금"&NUMBERSTRING(Z25,1)&"원" -> 금이억칠천구백칠십이만일천이백삼십오원 | Z25: =원가계산!E35 -> 279721235
N26: : | O26: ="금"&NUMBERSTRING(Z26,1)&"원" -> 금이억일천육백오십일만삼천사백칠십칠원 | Z26: =원가계산!F35 -> 216513477

Sheet 7-1.증감내역
A1: Ⅶ. 공사비 증ㆍ감 대비표
A2: 품 명 | B2: 전 체 | E2: 비 고
B3: 당 초 | C3: 변 경 | D3: 증(▲)감
A4: 평창 에코랜드 조성사업(전기)
A5: 직접재료비 | B5: =원가계산!E3 -> 41868228 | C5: =원가계산!F3 -> 48895473 | D5: =C5-B5 -> 7027245
A6: 가. 직접노무비 | B6: =원가계산!E7 -> 98775174 | C6: =원가계산!F7 -> 106329490 | D6: =C6-B6 -> 7554316
A7: 나. 간접노무비 | B7: =원가계산!E8 -> 12939547 | C7: =원가계산!F8 -> 13929163 | D7: =C7-B7 -> 989616
A8: 다. 기계겅비 | B8: =원가계산!E10 -> 1540380 | C8: =원가계산!F10 -> 1281615
A9: 라. 산재보험료 | B9: =원가계산!E11 -> 4133444 | C9: =원가계산!F11 -> 4449570 | D9: =C9-B9 -> 316126
A10: 마. 고용보험료 | B10: =원가계산!E12 -> 1128318 | C10: =원가계산!F12 -> 1214612 | D10: =C10-B10 -> 86294
A11: 바. 건강보험료 | B11: =원가계산!E13 -> 3899173 | C11: =원가계산!F13 -> 3899173 | D11: =C11-B11 -> 0 | E11: 보험료정산
A12: 사. 연금보험료 | B12: =원가계산!E15 -> 5020394 | C12: =원가계산!F15 -> 5020394 | D12: =C12-B12 -> 0 | E12: 보험료정산
A13: 아. 노인장기요양보험료 | B13: =원가계산!E14 -> 478428 | C13: =원가계산!F14 -> 478428 | D13: =C13-B13 -> 0 | E13: 보험료정산
A14: 자. 퇴직공제부금비 | B14: =원가계산!E16 -> 2565979 | C14: =원가계산!F16 -> 2565979 | D14: =C14-B14 -> 0 | E14: 보험료정산
A15: 차. 산업안전보건관리비 | B15: =원가계산!E17 -> 5583192 | C15: =원가계산!F17 -> 5583192 | D15: =C15-B15 -> 0
A16: 카. 기타경비 | B16: =원가계산!E20 -> 8907811 | C16: =원가계산!F20 -> 9810939 | D16: =C16-B16 -> 903128
A17: A. 순공사원가 | B17: =원가계산!E24 -> 186840068 | C17: =원가계산!F24 -> 203458028 | D17: =C17-B17 -> 16617960
A18: B. 일반관리비 | B18: =원가계산!E25 -> 11210404 | C18: =원가계산!F25 -> 12207481 | D18: =C18-B18 -> 997077
A19: C. 이윤 | B19: =원가계산!E26 -> 20154256 | C19: =원가계산!F26 -> 21516310 | D19: =C19-B19 -> 1362054
A20: (1) 공 급 가 액 | B20: =+B17+B18+B19 -> 218204728 | C20: =+C17+C18+C19 -> 237181819 | D20: =+D17+D18+D19 -> 18977091
A21: (2) 부가가치세 | B21: =INT(B20*10%) -> 21820472 | C21: =INT(C20*10%) -> 23718181 | D21: =C21-B21 -> 1897709
A22: Ⅰ. 도 급 금 액 | B22: =+B20+B21 -> 240025200 | C22: =+C20+C21 -> 260900000 | D22: =C22-B22 -> 20874800
A23: ○ 총 공 사 비 | B23: =B22 -> 240025200 | C23: =C22 -> 260900000 | D23: =D22 -> 20874800

Sheet 원가계산
A1: [공사명] | C1: [ 평창 에코랜드 조성사업(전기) ]
A2: 비 목 | D2: 변경전 원가 | F2: 변경후 원가 | G2: 증 감 | H2: 구 성 비 | P2: 비 고
B3: 재 료 비 | C3: 직 접 재 료 비 | E3: =공종별집계표!I26 -> 41868228 | F3: =공종별집계표!I27 -> 48895473 | G3: =F3-E3 -> 7027245
C4: 간 접 재 료 비
C5: 작 업 설 , 부 산 물 등 (△) | E5: 0 | F5: 0
A6: 순 | C6: [ 소 계 ] | E6: =E3+E4+E5 -> 41868228 | F6: =F3+F4+F5 -> 48895473 | G6: =F6-E6 -> 7027245
B7: 노 무 비 | C7: 직 접 노 무 비 | E7: =공종별집계표!L26 -> 98775174 | F7: =공종별집계표!L27 -> 106329490 | G7: =F7-E7 -> 7554316
C8: 간 접 노 무 비 | E8: =TRUNC(E7*J8) -> 12939547 | F8: =TRUNC(F7*J8) -> 13929163 | G8: =F8-E8 -> 989616 | H8: 직접노무비 | I8: × | J8: 0.131 | L8: 0.124
A9: 공 | C9: [ 소 계 ] | E9: =SUM(E7:E8) -> 111714721 | F9: =SUM(F7:F8) -> 120258653 | G9: =F9-E9 -> 8543932
C10: 기 계 경 비 | E10: =공종별집계표!N26 -> 1540380 | F10: =공종별집계표!N27 -> 1281615 | G10: =F10-E10 -> -258765
C11: 산 재 보 험 료 | E11: =TRUNC(E9*J11) -> 4133444 | F11: =TRUNC(F9*J11) -> 4449570 | G11: =F11-E11 -> 316126 | H11: 노무비 | I11: × | J11: 0.037
A12: 사 | C12: 고 용 보 험 료 | E12: =TRUNC(E9*J12) -> 1128318 | F12: =TRUNC(F9*J12) -> 1214612 | G12: =F12-E12 -> 86294 | H12: 노무비 | I12: × | J12: 0.0101
B13: 경 | C13: 건 강 보 험 료 | E13: 3899173 | F13: 3899173 | G13: =F13-E13 -> 0 | H13: 직접노무비 | I13: × | J13: 0.03495
C14: 노 인 장 기 요 양 보 험 료 | E14: 478428 | F14: 478428 | G14: =F14-E14 -> 0 | H14: 건강보험료 | I14: × | J14: 0.1227
C15: 연 금 보 험 료 | E15: 5020394 | F15: 5020394 | G15: =F15-E15 -> 0 | H15: 직접노무비 | I15: × | J15: 0.045
A16: 원 | C16: 퇴 직 공 제 부 금 비 | E16: 2565979 | F16: 2565979 | G16: =F16-E16 -> 0 | H16: 직접노무비 | I16: × | J16: 0.023
C17: 산 업 안 전 보 건 관 리 비 | E17: 5583192 | F17: 5583192 | G17: =F17-E17 -> 0 | P17: ①과②비교후 적은 금액 적용
C18: ① | E18: 5583192 | F18: =E18 -> 5583192 | G18: =F18-E18 -> 0 | H18: ((재료비+직노) | I18: × | J18: 0.0293 | M18: ) × | N18: 1.2
A19: 가 | C19: ② | G19: =F19-E19 -> 0 | H19: (재료비+직노+관급자재비(도급자/1.1)) | I19: × | J19: 0.0293 | P19: 부가세,조달수수료 제외
B20: 비 | C20: 기 타 경 비 | E20: =TRUNC((E6+E9)*J20) -> 8907811 | F20: =TRUNC((F6+F9)*J20) -> 9810939 | G20: =F20-E20 -> 903128 | H20: (재료비+노무비) | I20: × | J20: 0.058 | L20: 0.077
C21: 환 경 보 존 비 | E21: 0 | F21: 0 | G21: =F21-E21 -> 0
C22: 건설하도급대금지급보증서발급수수료 | E22: 0 | F22: 0 | G22: =F22-E22 -> 0
C23: [ 소 계 ] | E23: =SUM(E10:E17,E20:E22) -> 33257119 | F23: =SUM(F10:F17,F20:F22) -> 34303902 | G23: =F23-E23 -> 1046783
B24: 계 | E24: =E6+E9+E23 -> 186840068 | F24: =F6+F9+F23 -> 203458028 | G24: =F24-E24 -> 16617960
A25: 일 반 관 리 비 | E25: =TRUNC(E24*J25) -> 11210404 | F25: =TRUNC(F24*J25) -> 12207481 | G25: =F25-E25 -> 997077 | H25: 계 | I25: × | J25: 0.06
A26: 이 윤 | E26: =TRUNC((E9+E23+E25)*J26)+P26 -> 20154256 | F26: =TRUNC((F9+F23+F25)*J26)-4120-109 -> 21516310 | G26: =F26-E26 -> 1362054 | H26: (노무비+경비+일반관리비) | I26: × | J26: 0.1290432 | R26: 240025200
A27: 공 급 가 액 | E27: =SUM(E24:E26) -> 218204728 | F27: =SUM(F24:F26) -> 237181819 | G27: =F27-E27 -> 18977091
A28: 부 가 가 치 세 | E28: =INT(E27*J28) -> 21820472 | F28: =INT(F27*J28) -> 23718181 | G28: =F28-E28 -> 1897709 | H28: 공급가액 | I28: × | J28: 0.1
A29: [도 급 액] | E29: =SUM(E27:E28) -> 240025200 | F29: =SUM(F27:F28) -> 260900000 | G29: =F29-E29 -> 20874800
A30: 관 급 자 재 (관급자설치) | F30: =#REF! -> #REF! | G30: =F30-E30 -> #REF! | H30: VAT포함
A31: 관 급 자 재 (도급자설치) | G31: =F31-E31 -> 0 | H31: VAT포함
A32: 관 급 공 사 비 (합 계) | E32: =E30+E31 -> 0 | G32: =F32-E32 -> 0
A33: 관급공사비 | E33: =공종별집계표!P29 -> 180667661 | F33: =공종별집계표!P31 -> 99053574 | G33: =F33-E33 -> -81614087
A34: 관급공사비도급자설치) | E34: =공종별집계표!P31 -> 99053574 | F34: =공종별집계표!P32 -> 117459903 | G34: =F34-E34 -> 18406329
A35: 관급공사비(합계) | E35: =E33+E34 -> 279721235 | F35: =F33+F34 -> 216513477 | G35: =F35-E35 -> -63207758
A36: 한 전 불 입 금 | E36: =[1]한전불입금!N5 -> 21183800 | F36: 27295000 | G36: =F36-E36 -> 6111200 | H36: VAT포함 | J36: 193kw
A37: 사 용 전 검 사 비 | E37: =[1]한전불입금!L22 -> 400149.77 | F37: =E37 -> 400149.77 | G37: =F37-E37 -> 0 | H37: VAT포함
A38: [총 공 사 비] | E38: =E29+E35+E36+E37 -> 5.4133038e+08 | F38: =F29+F35+F36+F37 -> 5.0510863e+08 | G38: =F38-E38 -> -36221758 | P38: 1000단위절사
P40: =E29/SUM(E3,E7,E10) -> 1.6881335

Sheet 공종별집계표
A1: 총줄수-> | B1: 159 | D1: [ 평창 에코랜드 조성사업(전기) ] | AA1: 연속견적가로형식
A2: 번호 | B2: 공종코드 | C2: … | D2: 공 종 명 | E2: 규격 | F2: 단위 | G2: 수량 | H2: 재료비 | J2: 노무비 | M2: 경비 | P2: 계 | Q2: 증 감
H3: 단가 | I3: 금액 | J3: 수량 | K3: 단가 | L3: 금액 | M3: 단가 | N3: 금액 | O3: 단가
B4: 공종줄 | D4: 평창 에코랜드 조성사업(전기)
B5: 01 | D5: 1.옥외공사 | F5: 식 | G5: 1 | H5: =I73 -> 28135332 | I5: =G5*H5 -> 28135332 | K5: =L73 -> 31160791 | L5: =G5*K5 -> 31160791 | M5: =N73 -> 1467222 | N5: =G5*M5 -> 1467222 | O5: =IF((H5+K5+M5)=0, "", (H5+K5+M5)) -> 60763345 | P5: =I5+L5+N5 -> 60763345 | Q5: =P6-P5 -> 43974463
B6: 01 | D6: 1.옥외공사 | F6: 식 | G6: 1 | H6: =I74 -> 42363814 | I6: =G6*H6 -> 42363814 | K6: =L74 -> 61092379 | L6: =G6*K6 -> 61092379 | M6: =N74 -> 1281615 | N6: =G6*M6 -> 1281615 | O6: =IF((H6+K6+M6)=0, "", (H6+K6+M6)) -> 104737808 | P6: =I6+L6+N6 -> 104737808
B7: 02 | D7: 2.옥내공사 | F7: 식 | G7: 1 | H7: =I100 -> 13732896 | I7: =G7*H7 -> 13732896 | K7: =L100 -> 67614383 | L7: =G7*K7 -> 67614383 | M7: =N100 -> 73158 | N7: =G7*M7 -> 73158 | O7: =IF((H7+K7+M7)=0, "", (H7+K7+M7)) -> 81420437 | P7: =I7+L7+N7 -> 81420437 | Q7: =P8-P7 -> -29651667
B8: 02 | D8: 2.옥내공사 | F8: 식 | G8: 1 | H8: =I101 -> 6531659 | I8: =G8*H8 -> 6531659 | K8: =L101 -> 45237111 | L8: =G8*K8 -> 45237111 | M8: =N101 -> 0 | N8: =G8*M8 -> 0 | O8: =IF((H8+K8+M8)=0, "", (H8+K8+M8)) -> 51768770 | P8: =I8+L8+N8 -> 51768770
C26: Total | D26: ( 합 계 ) | I26: =TRUNC([2]!sumcol(1,I3:I24)) -> 41868228 | L26: =TRUNC([2]!sumcol(1,L3:L24)) -> 98775174 | N26: =TRUNC([2]!sumcol(1,N3:N24)) -> 1540380 | O26: =IF((H26+K26+M26)=0, "", (H26+K26+M26)) | P26: =I26+L26+N26 -> 142183782 | Q26: =P27-P26 -> 14322796
C27: Total | D27: ( 합 계 ) | I27: =TRUNC([2]!sumcol(0,I4:I25)) -> 48895473 | L27: =TRUNC([2]!sumcol(0,L4:L25)) -> 106329490 | N27: =TRUNC([2]!sumcol(0,N4:N25)) -> 1281615 | O27: =IF((H27+K27+M27)=0, "", (H27+K27+M27)) | P27: =I27+L27+N27 -> 156506578
B28: 공종줄 | D28: 평창 에코랜드 조성사업(전기)
B29: 03 | D29: 3.관급자관급 | F29: 식 | G29: 1 | H29: =변경내역서!I673 -> 180667661 | I29: =G29*H29 -> 180667661 | K29: =공종별집계표!L126 -> 0 | L29: =G29*K29 -> 0 | M29: =공종별집계표!N126 -> 0 | N29: =G29*M29 -> 0 | O29: =IF((H29+K29+M29)=0, "", (H29+K29+M29)) -> 180667661 | P29: =I29+L29+N29 -> 180667661
B30: 03 | D30: 3.관급자관급 | F30: 식 | G30: 1 | H30: =변경내역서!I674 -> 179032531 | I30: =G30*H30 -> 179032531 | K30: =공종별집계표!L128 -> 0 | L30: =G30*K30 -> 0 | M30: =공종별집계표!N128 -> 0 | N30: =G30*M30 -> 0 | O30: =IF((H30+K30+M30)=0, "", (H30+K30+M30)) -> 179032531 | P30: =I30+L30+N30 -> 179032531
B31: 04 | D31: 4.도급자관급 | F31: 식 | G31: 1 | H31: =변경내역서!I724+변경내역서!I775 -> 99053574 | I31: =G31*H31 -> 99053574 | K31: =공종별집계표!L153 -> 0 | L31: =G31*K31 -> 0 | M31: =공종별집계표!N153 -> 0 | N31: =G31*M31 -> 0 | O31: =IF((H31+K31+M31)=0, "", (H31+K31+M31)) -> 99053574 | P31: =I31+L31+N31 -> 99053574
B32: 04 | D32: 4.도급자관급 | F32: 식 | G32: 1 | H32: =변경내역서!I725+변경내역서!I776 -> 117459903 | I32: =G32*H32 -> 117459903 | K32: =공종별집계표!L154 -> 0 | L32: =G32*K32 -> 0 | M32: =공종별집계표!N154 -> 0 | N32: =G32*M32 -> 0 | O32: =IF((H32+K32+M32)=0, "", (H32+K32+M32)) -> 117459903 | P32: =I32+L32+N32 -> 117459903
P33: =I33+L33+N33 -> 0
C49: Total | D49: ( 합 계 ) | I49: =I29+I31 -> 279721235 | L49: =L29+L31 -> 0 | N49: =N29+N31 -> 0 | O49: =IF((H49+K49+M49)=0, "", (H49+K49+M49)) | P49: =I49+L49+N49 -> 279721235
C50: Total | D50: ( 합 계 ) | I50: =I30+I32 -> 296492434 | L50: =TRUNC([2]!sumcol(0,L28:L48)) -> 0 | N50: =TRUNC([2]!sumcol(0,N28:N48)) -> 0 | O50: =IF((H50+K50+M50)=0, "", (H50+K50+M50)) | P50: =I50+L50+N50 -> 296492434
B51: 공종줄 | D51: 1.옥외공사
B52: 0101 | D52: 1-1.옥외보안등공사 | F52: 식 | G52: 1 | H52: =변경내역서!I113 -> 13168183 | I52: =G52*H52 -> 13168183 | K52: =변경내역서!K113 -> 23888985 | L52: =G52*K52 -> 23888985 | M52: =변경내역서!M113 -> 1270808 | N52: =G52*M52 -> 1270808 | O52: =IF((H52+K52+M52)=0, "", (H52+K52+M52)) -> 38327976 | P52: =I52+L52+N52 -> 38327976 | Q52: =P53-P52 -> 20416145
B53: 0101 | D53: 1-1.옥외보안등공사 | F53: 식 | G53: 1 | H53: =변경내역서!I114 -> 16886561 | I53: =G53*H53 -> 16886561 | K53: =변경내역서!K114 -> 40880064 | L53: =G53*K53 -> 40880064 | M53: =변경내역서!M114 -> 977496 | N53: =G53*M53 -> 977496 | O53: =IF((H53+K53+M53)=0, "", (H53+K53+M53)) -> 58744121 | P53: =I53+L53+N53 -> 58744121
B54: 0102 | D54: 1-2.옥외전력간선공사 | F54: 식 | G54: 1 | H54: =변경내역서!I216 -> 14967149 | I54: =G54*H54 -> 14967149 | K54: =변경내역서!K216 -> 7271806 | L54: =G54*K54 -> 7271806 | M54: =변경내역서!M216 -> 196414 | N54: =G54*M54 -> 196414 | O54: =IF((H54+K54+M54)=0, "", (H54+K54+M54)) -> 22435369 | P54: =I54+L54+N54 -> 22435369 | Q54: =P55-P54 -> 23558318
B55: 0102 | D55: 1-2.옥외전력간선공사 | F55: 식 | G55: 1 | H55: =변경내역서!I217 -> 25477253 | I55: =G55*H55 -> 25477253 | K55: =변경내역서!K217 -> 20212315 | L55: =G55*K55 -> 20212315 | M55: =변경내역서!M217 -> 304119 | N55: =G55*M55 -> 304119 | O55: =IF((H55+K55+M55)=0, "", (H55+K55+M55)) -> 45993687 | P55: =I55+L55+N55 -> 45993687
B73: 01 | C73: Total | D73: ( 합 계 ) | I73: =I52+I54 -> 28135332 | L73: =L52+L54 -> 31160791 | N73: =N52+N54 -> 1467222 | O73: =IF((H73+K73+M73)=0, "", (H73+K73+M73)) | P73: =I73+L73+N73 -> 60763345 | Q73: =P74-P73 -> 43974463
B74: 01 | C74: Total | D74: ( 합 계 ) | I74: =I53+I55 -> 42363814 | L74: =L53+L55 -> 61092379 | N74: =N53+N55 -> 1281615 | O74: =IF((H74+K74+M74)=0, "", (H74+K74+M74)) | P74: =I74+L74+N74 -> 104737808
B75: 공종줄 | D75: 2.옥내공사
B76: 0201 | D76: 2-1.전력간선공사 | F76: 식 | G76: 1 | H76: =변경내역서!I325 -> 2755691 | I76: =G76*H76 -> 2755691 | K76: =변경내역서!K325 -> 7094670 | L76: =G76*K76 -> 7094670 | M76: =변경내역서!M325 -> 2512 | N76: =G76*M76 -> 2512 | O76: =IF((H76+K76+M76)=0, "", (H76+K76+M76)) -> 9852873 | P76: =I76+L76+N76 -> 9852873 | Q76: =P77-P76 -> -2822057
B77: 0201 | D77: 2-1.전력간선공사 | F77: 식 | G77: 1 | H77: =변경내역서!I326 -> 1187761 | I77: =G77*H77 -> 1187761 | K77: =변경내역서!K326 -> 5843055 | L77: =G77*K77 -> 5843055 | M77: =변경내역서!M326 -> 0 | N77: =G77*M77 -> 0 | O77: =IF((H77+K77+M77)=0, "", (H77+K77+M77)) -> 7030816 | P77: =I77+L77+N77 -> 7030816
B78: 0202 | D78: 2-2.동력설비공사 | F78: 식 | G78: 1 | H78: =변경내역서!I348 -> 1191385 | I78: =G78*H78 -> 1191385 | K78: =변경내역서!K348 -> 7114104 | L78: =G78*K78 -> 7114104 | M78: =변경내역서!M148 -> 0 | N78: =G78*M78 -> 0 | O78: =IF((H78+K78+M78)=0, "", (H78+K78+M78)) -> 8305489 | P78: =I78+L78+N78 -> 8305489 | Q78: =P79-P78 -> -8305489
B79: 0202 | D79: 2-2.동력설비공사 | F79: 식 | G79: 1 | H79: =#REF! -> 0 | I79: =G79*H79 -> 0 | K79: =#REF! -> 0 | L79: =G79*K79 -> 0 | M79: =변경내역서!M149 -> 0 | N79: =G79*M79 -> 0 | O79: =IF((H79+K79+M79)=0, "", (H79+K79+M79)) | P79: =I79+L79+N79 -> 0
B80: 0203 | D80: 2-3.전등설비공사 | F80: 식 | G80: 1 | H80: =변경내역서!I453 -> 3244045 | I80: =G80*H80 -> 3244045 | K80: =변경내역서!K453 -> 26406118 | L80: =G80*K80 -> 26406118 | M80: =변경내역서!M453 -> 38536 | N80: =G80*M80 -> 38536 | O80: =IF((H80+K80+M80)=0, "", (H80+K80+M80)) -> 29688699 | P80: =I80+L80+N80 -> 29688699 | Q80: =P81-P80 -> -8501340
B81: 0203 | D81: 2-3.전등설비공사 | F81: 식 | G81: 1 | H81: =변경내역서!I454 -> 1914993 | I81: =G81*H81 -> 1914993 | K81: =변경내역서!K454 -> 19272366 | L81: =G81*K81 -> 19272366 | M81: =변경내역서!M454 -> 0 | N81: =G81*M81 -> 0 | O81: =IF((H81+K81+M81)=0, "", (H81+K81+M81)) -> 21187359 | P81: =I81+L81+N81 -> 21187359
B82: 0204 | D82: 2-4.전열설비공사 | F82: 식 | G82: 1 | H82: =변경내역서!I504 -> 1204069 | I82: =G82*H82 -> 1204069 | K82: =변경내역서!K504 -> 9403256 | L82: =G82*K82 -> 9403256 | M82: =변경내역서!M262 -> 0 | N82: =G82*M82 -> 0 | O82: =IF((H82+K82+M82)=0, "", (H82+K82+M82)) -> 10607325 | P82: =I82+L82+N82 -> 10607325 | Q82: =P83-P82 -> -218970
B83: 0204 | D83: 2-4.전열설비공사 | F83: 식 | G83: 1 | H83: =변경내역서!I505 -> 1845653 | I83: =G83*H83 -> 1845653 | K83: =변경내역서!K505 -> 8542702 | L83: =G83*K83 -> 8542702 | M83: =변경내역서!M263 -> 0 | N83: =G83*M83 -> 0 | O83: =IF((H83+K83+M83)=0, "", (H83+K83+M83)) -> 10388355 | P83: =I83+L83+N83 -> 10388355
B84: 0205 | D84: 2-5.냉난방설비공사 | F84: 식 | G84: 1 | H84: =변경내역서!I597 -> 2915089 | I84: =G84*H84 -> 2915089 | K84: =변경내역서!K597 -> 13385262 | L84: =G84*K84 -> 13385262 | M84: =#REF! -> 0 | N84: =G84*M84 -> 0 | O84: =IF((H84+K84+M84)=0, "", (H84+K84+M84)) -> 16300351 | P84: =I84+L84+N84 -> 16300351 | Q84: =P85-P84 -> -3138111
B85: 0205 | D85: 2-5.냉난방설비공사 | F85: 식 | G85: 1 | H85: =변경내역서!I598 -> 1583252 | I85: =G85*H85 -> 1583252 | K85: =변경내역서!K598 -> 11578988 | L85: =G85*K85 -> 11578988 | M85: =#REF! -> 0 | N85: =G85*M85 -> 0 | O85: =IF((H85+K85+M85)=0, "", (H85+K85+M85)) -> 13162240 | P85: =I85+L85+N85 -> 13162240
B86: 0206 | D86: 2-6.태양광발전설비공사 | F86: 식 | G86: 1 | H86: =변경내역서!I648 -> 2422617 | I86: =G86*H86 -> 2422617 | K86: =변경내역서!K648 -> 4210973 | L86: =G86*K86 -> 4210973 | M86: =변경내역서!M648 -> 32110 | N86: =G86*M86 -> 32110 | O86: =IF((H86+K86+M86)=0, "", (H86+K86+M86)) -> 6665700 | P86: =I86+L86+N86 -> 6665700 | Q86: =P87-P86 -> -6665700
B87: 0206 | D87: 2-6.태양광발전설비공사 | F87: 식 | G87: 1 | H87: =#REF! -> 0 | I87: =G87*H87 -> 0 | K87: =#REF! -> 0 | L87: =G87*K87 -> 0 | M87: =#REF! -> 0 | N87: =G87*M87 -> 0 | O87: =IF((H87+K87+M87)=0, "", (H87+K87+M87)) | P87: =I87+L87+N87 -> 0
B100: 02 | C100: Total | D100: ( 합 계 ) | I100: =I76+I78+I80+I82+I84+I86 -> 13732896 | L100: =L76+L78+L80+L82+L84+L86 -> 67614383 | N100: =N76+N78+N80+N82+N84+N86 -> 73158 | O100: =IF((H100+K100+M100)=0, "", (H100+K100+M100)) | P100: =I100+L100+N100 -> 81420437 | Q100: =P101-P100 -> -29651667
B101: 02 | C101: Total | D101: ( 합 계 ) | I101: =I77+I79+I81+I83+I85+I87 -> 6531659 | L101: =L77+L79+L81+L83+L85+L87 -> 45237111 | N101: =N77+N79+N81+N83+N85+N87 -> 0 | O101: =IF((H101+K101+M101)=0, "", (H101+K101+M101)) | P101: =I101+L101+N101 -> 51768770
...

Sheet 증감대비표
B2: 공 사 비 물 량 증.감 대 비 표
B4: 명 칭 | C4: 규 격 | D4: 단위 | E4: 수량 | F4: 당 초 | I4: 변 경 | L4: 증 · 감(△)
F5: 단 가 | G5: 수 량 | H5: 금 액 | I5: 단 가 | J5: 수 량 | K5: 금 액 | L5: 단 가 | M5: 수 량 | N5: 금 액
B6: 1.옥외공사::1-1.옥외보안등공사 | C6: HI 70 mm | D6: M | E6: 6 | F6: =변경내역서!N5 -> 67413 | G6: =변경내역서!G5 -> 6 | H6: =변경내역서!I5 -> 19338 | I6: =변경내역서!N4 -> 0 | J6: =변경내역서!G4 -> 0 | K6: =변경내역서!I4 -> 0 | L6: =I6-F6 -> -67413 | M6: =J6-G6 -> -6 | N6: =K6-H6 -> -19338
B7: 파상형 폴리에틸렌 전선관 | C7: 30㎜(가로등,신호,구내) | D7: M | E7: 144 | F7: =변경내역서!N7 -> 6217 | G7: =변경내역서!G7 -> 144 | H7: =변경내역서!I7 -> 62064 | I7: =변경내역서!N6 -> 0 | J7: =변경내역서!G6 -> 0 | K7: =변경내역서!I6 -> 0 | L7: =I7-F7 -> -6217 | M7: =J7-G7 -> -144 | N7: =K7-H7 -> -62064
B8: 파상형 폴리에틸렌 전선관 | C8: 40㎜(가로등,신호,구내) | D8: M | E8: 796 | F8: =변경내역서!N9 -> 7643 | G8: =변경내역서!G9 -> 796 | H8: =변경내역서!I9 -> 448944 | I8: =변경내역서!N8 -> 0 | J8: =변경내역서!G8 -> 0 | K8: =변경내역서!I8 -> 0 | L8: =I8-F8 -> -7643 | M8: =J8-G8 -> -796 | N8: =K8-H8 -> -448944
B9: 파상형 폴리에틸렌 전선관 | C9: 65㎜(가로등,신호,구내) | D9: M | E9: 21 | F9: =변경내역서!N11 -> 9957 | G9: =변경내역서!G11 -> 21 | H9: =변경내역서!I11 -> 22680 | I9: =변경내역서!N10 -> 0 | J9: =변경내역서!G10 -> 0 | K9: =변경내역서!I10 -> 0 | L9: =I9-F9 -> -9957 | M9: =J9-G9 -> -21 | N9: =K9-H9 -> -22680
B10: 관로구방수장치 | C10: D65 | D10: 조 | E10: 1 | F10: =변경내역서!N13 -> 64970 | G10: =변경내역서!G13 -> 1 | H10: =변경내역서!I13 -> 15857 | I10: =변경내역서!N12 -> 0 | J10: =변경내역서!G12 -> 0 | K10: =변경내역서!I12 -> 0 | L10: =I10-F10 -> -64970 | M10: =J10-G10 -> -1 | N10: =K10-H10 -> -15857
B11: 경질비닐전선관용 부품 | C11: 노말밴드, 70 mm | D11: 개 | E11: 1 | F11: =변경내역서!N15 -> 3124 | G11: =변경내역서!G15 -> 1 | H11: =변경내역서!I15 -> 3124 | I11: =변경내역서!N14 -> 0 | J11: =변경내역서!G14 -> 0 | K11: =변경내역서!I14 -> 0 | L11: =I11-F11 -> -3124 | M11: =J11-G11 -> -1 | N11: =K11-H11 -> -3124
B12: 풀박스 | C12: 400×400×300 | D12: 개 | E12: 1 | F12: =변경내역서!N17 -> 101182 | G12: =변경내역서!G17 -> 1 | H12: =변경내역서!I17 -> 20945 | I12: =변경내역서!N16 -> 0 | J12: =변경내역서!G16 -> 0 | K12: =변경내역서!I16 -> 0 | L12: =I12-F12 -> -101182 | M12: =J12-G12 -> -1 | N12: =K12-H12 -> -20945
B13: 접지용난연절연전선(FGV) | C13: 6㎟(옥외) | D13: M | E13: 986 | F13: =변경내역서!N19 -> 2112 | G13: =변경내역서!G19 -> 986 | H13: =변경내역서!I19 -> 726682 | I13: =변경내역서!N18 -> 0 | J13: =변경내역서!G18 -> 0 | K13: =변경내역서!I18 -> 0 | L13: =I13-F13 -> -2112 | M13: =J13-G13 -> -986 | N13: =K13-H13 -> -726682
B14: 0.6/1kv 폴리에틸렌 난연케이블 | C14: F-CV 2C×2.5㎟(옥외) | D14: M | E14: 141 | F14: =변경내역서!N21 -> 4412 | G14: =변경내역서!G21 -> 141 | H14: =변경내역서!I21 -> 162150 | I14: =변경내역서!N20 -> 0 | J14: =변경내역서!G20 -> 0 | K14: =변경내역서!I20 -> 0 | L14: =I14-F14 -> -4412 | M14: =J14-G14 -> -141 | N14: =K14-H14 -> -162150
B15: 0.6/1kv 폴리에틸렌 난연케이블 | C15: F-CV 2C×6㎟(옥외) | D15: M | E15: 147 | F15: =변경내역서!N23 -> 5276 | G15: =변경내역서!G23 -> 147 | H15: =변경내역서!I23 -> 296058 | I15: =변경내역서!N22 -> 0 | J15: =변경내역서!G22 -> 0 | K15: =변경내역서!I22 -> 0 | L15: =I15-F15 -> -5276 | M15: =J15-G15 -> -147 | N15: =K15-H15 -> -296058
B16: 0.6/1kv 폴리에틸렌 난연케이블 | C16: F-CV 2C×6㎟(옥외),2열포설1열 | D16: M | E16: 1619 | F16: =변경내역서!N25 -> 4946 | G16: =변경내역서!G25 -> 1619 | H16: =변경내역서!I25 -> 3250952 | I16: =변경내역서!N24 -> 0 | J16: =변경내역서!G24 -> 0 | K16: =변경내역서!I24 -> 0 | L16: =I16-F16 -> -4946 | M16: =J16-G16 -> -1619 | N16: =K16-H16 -> -3250952
B17: 0.6/1kv 폴리에틸렌 난연케이블 | C17: F-CV 2C×6㎟(옥외),5열포설1열 | D17: M | E17: 57 | F17: =변경내역서!N27 -> 4746 | G17: =변경내역서!G27 -> 57 | H17: =변경내역서!I27 -> 114228 | I17: =변경내역서!N26 -> 0 | J17: =변경내역서!G26 -> 0 | K17: =변경내역서!I26 -> 0 | L17: =I17-F17 -> -4746 | M17: =J17-G17 -> -57 | N17: =K17-H17 -> -114228
B18: 0.6/1kv 폴리에틸렌 난연케이블 | C18: F-CV 2C×6㎟(옥외),6열포설1열 | D18: M | E18: 111 | F18: =변경내역서!N29 -> 4711 | G18: =변경내역서!G29 -> 111 | H18: =변경내역서!I29 -> 222333 | I18: =변경내역서!N28 -> 0 | J18: =변경내역서!G28 -> 0 | K18: =변경내역서!I28 -> 0 | L18: =I18-F18 -> -4711 | M18: =J18-G18 -> -111 | N18: =K18-H18 -> -222333
B19: 지중선용 가선철물 | C19: 케이블표지시트, 0.15x150 | D19: M | E19: 900 | F19: =변경내역서!N31 -> 494 | G19: =변경내역서!G31 -> 900 | H19: =변경내역서!I31 -> 218700 | I19: =변경내역서!N30 -> 0 | J19: =변경내역서!G30 -> 0 | K19: =변경내역서!I30 -> 0 | L19: =I19-F19 -> -494 | M19: =J19-G19 -> -900 | N19: =K19-H19 -> -218700
B20: 가로등중공기초 | C20: 접지(유),500*800*700 | D20: 개소 | E20: 30 | F20: =변경내역서!N33 -> 183741 | G20: =변경내역서!G33 -> 30 | H20: =변경내역서!I33 -> 3857820 | I20: =변경내역서!N32 -> 0 | J20: =변경내역서!G32 -> 0 | K20: =변경내역서!I32 -> 0 | L20: =I20-F20 -> -183741 | M20: =J20-G20 -> -30 | N20: =K20-H20 -> -3857820
B21: 가로등 건주 기계화 시공 | C21: 일반 5m-7m | D21: 개소 | E21: 30 | F21: =변경내역서!N35 -> 98669 | G21: =변경내역서!G35 -> 30 | H21: =변경내역서!I35 -> 248610 | I21: =변경내역서!N34 -> 0 | J21: =변경내역서!G34 -> 0 | K21: =변경내역서!I34 -> 0 | L21: =I21-F21 -> -98669 | M21: =J21-G21 -> -30 | N21: =K21-H21 -> -248610
B22: 정원등중공기초 | C22: 400x500x565x400 | D22: 개소 | E22: 22 | F22: =변경내역서!N37 -> 124369 | G22: =변경내역서!G37 -> 22 | H22: =변경내역서!I37 -> 1999448 | I22: =변경내역서!N36 -> 0 | J22: =변경내역서!G36 -> 0 | K22: =변경내역서!I36 -> 0 | L22: =I22-F22 -> -124369 | M22: =J22-G22 -> -22 | N22: =K22-H22 -> -1999448
B23: 기계터파기 | C23: 보통토사(0.7㎥/43.6) | D23: ㎥ | E23: 324 | F23: =변경내역서!N39 -> 1137 | G23: =변경내역서!G39 -> 324 | H23: =변경내역서!I39 -> 107892 | I23: =변경내역서!N38 -> 0 | J23: =변경내역서!G38 -> 0 | K23: =변경내역서!I38 -> 0 | L23: =I23-F23 -> -1137 | M23: =J23-G23 -> -324 | N23: =K23-H23 -> -107892
B24: 기계되메우기 | C24: 보통토사(0.7㎥/43.6) | D24: ㎥ | E24: 324 | F24: =변경내역서!N41 -> 1137 | G24: =변경내역서!G41 -> 324 | H24: =변경내역서!I41 -> 107892 | I24: =변경내역서!N40 -> 0 | J24: =변경내역서!G40 -> 0 | K24: =변경내역서!I40 -> 0 | L24: =I24-F24 -> -1137 | M24: =J24-G24 -> -324 | N24: =K24-H24 -> -107892
B25: 다기능 접속함 | C25: 방수형 | D25: EA | E25: 30 | F25: =변경내역서!N43 -> 84271 | G25: =변경내역서!G43 -> 30 | H25: =변경내역서!I43 -> 1221420 | I25: =변경내역서!N42 -> 0 | J25: =변경내역서!G42 -> 0 | K25: =변경내역서!I42 -> 0 | L25: =I25-F25 -> -84271 | M25: =J25-G25 -> -30 | N25: =K25-H25 -> -1221420
B26: 조명기구(TYPE-OA) | C26: 보안등(열주등)LED 45W,H:4M | D26: SET | E26: 30 | F26: =변경내역서!N45 -> 42790 | G26: =변경내역서!G45 -> 30 | H26: =변경내역서!I45 -> 25140 | I26: =변경내역서!N44 -> 0 | J26: =변경내역서!G44 -> 0 | K26: =변경내역서!I44 -> 0 | L26: =I26-F26 -> -42790 | M26: =J26-G26 -> -30 | N26: =K26-H26 -> -25140
B27: 조명기구(TYEP-OB) | C27: 볼라드 LED 12W | D27: SET | E27: 22 | F27: =변경내역서!N47 -> 36932 | G27: =변경내역서!G47 -> 22 | H27: =변경내역서!I47 -> 15906 | I27: =변경내역서!N46 -> 0 | J27: =변경내역서!G46 -> 0 | K27: =변경내역서!I46 -> 0 | L27: =I27-F27 -> -36932 | M27: =J27-G27 -> -22 | N27: =K27-H27 -> -15906
B28: 풀박스 | C28: 100X100X50 | D28: 개 | F28: =변경내역서!N49 -> 0 | G28: =변경내역서!G49 -> 0 | H28: =변경내역서!I49 -> 0 | I28: =변경내역서!N48 -> 0 | J28: =변경내역서!G48 -> 0 | K28: =변경내역서!I48 -> 0 | L28: =I28-F28 -> 0 | M28: =J28-G28 -> 0 | N28: =K28-H28 -> 0
B29: 난연 비닐 절연 접지용전선(F-GV) | C29: 0.6/1kV 4㎟ | D29: m | E29: 4 | F29: =변경내역서!N51 -> 0 | G29: =변경내역서!G51 -> 0 | H29: =변경내역서!I51 -> 0 | I29: =변경내역서!N50 -> 12062 | J29: =변경내역서!G50 -> 4 | K29: =변경내역서!I50 -> 10652 | L29: =I29-F29 -> 12062 | M29: =J29-G29 -> 4 | N29: =K29-H29 -> 10652
B30: 난연 비닐 절연 접지용전선(F-GV) | C30: 0.6/1kV 6㎟ | D30: m | E30: 564.5 | F30: =변경내역서!N53 -> 0 | G30: =변경내역서!G53 -> 0 | H30: =변경내역서!I53 -> 0 | I30: =변경내역서!N52 -> 3078 | J30: =변경내역서!G52 -> 564.5 | K30: =변경내역서!I52 -> 544178 | L30: =I30-F30 -> 3078 | M30: =J30-G30 -> 564.5 | N30: =K30-H30 -> 544178
B31: 0.6/1kV 난연 전력 케이블(F-CV) | C31: 2C 4㎟ | D31: m | E31: 654.5 | F31: =변경내역서!N55 -> 0 | G31: =변경내역서!G55 -> 0 | H31: =변경내역서!I55 -> 0 | I31: =변경내역서!N54 -> 3179 | J31: =변경내역서!G54 -> 654.5 | K31: =변경내역서!I54 -> 555670 | L31: =I31-F31 -> 3179 | M31: =J31-G31 -> 654.5 | N31: =K31-H31 -> 555670
B32: 0.6/1kV 난연 전력 케이블(F-CV) | C32: 2C 6㎟ | D32: m | E32: 564.5 | F32: =변경내역서!N57 -> 0 | G32: =변경내역서!G57 -> 0 | H32: =변경내역서!I57 -> 0 | I32: =변경내역서!N56 -> 5763 | J32: =변경내역서!G56 -> 564.5 | K32: =변경내역서!I56 -> 946666 | L32: =I32-F32 -> 5763 | M32: =J32-G32 -> 564.5 | N32: =K32-H32 -> 946666
B33: 누전차단기 | C33: ELB 2P 30AF | D33: 개 | E33: 960 | F33: =변경내역서!N59 -> 0 | G33: =변경내역서!G59 -> 0 | H33: =변경내역서!I59 -> 0 | I33: =변경내역서!N58 -> 5960 | J33: =변경내역서!G58 -> 960 | K33: =변경내역서!I58 -> 2184000 | L33: =I33-F33 -> 5960 | M33: =J33-G33 -> 960 | N33: =K33-H33 -> 2184000
B34: 경고테이프 포설 | C34: 저압용 | D34: M | E34: 16 | F34: =변경내역서!N61 -> 0 | G34: =변경내역서!G61 -> 0 | H34: =변경내역서!I61 -> 0 | I34: =변경내역서!N60 -> 72035 | J34: =변경내역서!G60 -> 16 | K34: =변경내역서!I60 -> 652496 | L34: =I34-F34 -> 72035 | M34: =J34-G34 -> 16 | N34: =K34-H34 -> 652496
B35: 파상형 폴리에틸렌 전선관 | C35: 30mm | D35: M | E35: 1116.5 | F35: =변경내역서!N63 -> 0 | G35: =변경내역서!G63 -> 0 | H35: =변경내역서!I63 -> 0 | I35: =변경내역서!N62 -> 536 | J35: =변경내역서!G62 -> 1116.5 | K35: =변경내역서!I62 -> 301455 | L35: =I35-F35 -> 536 | M35: =J35-G35 -> 1116.5 | N35: =K35-H35 -> 301455
B36: 합성수지 파형관(ELP)설치 | C36: 40mm | D36: M | E36: 858.5 | F36: =변경내역서!N65 -> 0 | G36: =변경내역서!G65 -> 0 | H36: =변경내역서!I65 -> 0 | I36: =변경내역서!N64 -> 7022 | J36: =변경내역서!G64 -> 858.5 | K36: =변경내역서!I64 -> 418089 | L36: =I36-F36 -> 7022 | M36: =J36-G36 -> 858.5 | N36: =K36-H36 -> 418089
B37: AL DUCT 신설 | C37: W:50 | D37: m | E37: 306 | F37: =변경내역서!N67 -> 0 | G37: =변경내역서!G67 -> 0 | H37: =변경내역서!I67 -> 0 | I37: =변경내역서!N66 -> 8634 | J37: =변경내역서!G66 -> 306 | K37: =변경내역서!I66 -> 195228 | L37: =I37-F37 -> 8634 | M37: =J37-G37 -> 306 | N37: =K37-H37 -> 195228
B38: 옥외 조명기구(라인조명) | C38: LED 18W | D38: 개 | E38: 60 | F38: =변경내역서!N69 -> 0 | G38: =변경내역서!G69 -> 0 | H38: =변경내역서!I69 -> 0 | I38: =변경내역서!N68 -> 35556 | J38: =변경내역서!G68 -> 60 | K38: =변경내역서!I68 -> 300420 | L38: =I38-F38 -> 35556 | M38: =J38-G38 -> 60 | N38: =K38-H38 -> 300420
B39: 옥외 조명기구(투광등) | C39: LED 54W | D39: 개 | E39: 60 | F39: =변경내역서!N71 -> 0 | G39: =변경내역서!G71 -> 0 | H39: =변경내역서!I71 -> 0 | I39: =변경내역서!N70 -> 33401 | J39: =변경내역서!G70 -> 60 | K39: =변경내역서!I70 -> 58320 | L39: =I39-F39 -> 33401 | M39: =J39-G39 -> 60 | N39: =K39-H39 -> 58320
B40: 투광등 기초 기성품설치 | D40: 개소 | E40: 36 | F40: =변경내역서!N73 -> 0 | G40: =변경내역서!G73 -> 0 | H40: =변경내역서!I73 -> 0 | I40: =변경내역서!N72 -> 50345 | J40: =변경내역서!G72 -> 36 | K40: =변경내역서!I72 -> 52776 | L40: =I40-F40 -> 50345 | M40: =J40-G40 -> 36 | N40: =K40-H40 -> 52776
B41: SMPS함-1 신설 | C41: 옥외 자립형 | D41: 면 | E41: 36 | F41: =변경내역서!N75 -> 0 | G41: =변경내역서!G75 -> 0 | H41: =변경내역서!I75 -> 0 | I41: =변경내역서!N74 -> 112126 | J41: =변경내역서!G74 -> 36 | K41: =변경내역서!I74 -> 1735812 | L41: =I41-F41 -> 112126 | M41: =J41-G41 -> 36 | N41: =K41-H41 -> 1735812
B42: SMPS함-2 신설 | C42: 옥외 자립형 | D42: 면 | E42: 1 | F42: =변경내역서!N77 -> 0 | G42: =변경내역서!G77 -> 0 | H42: =변경내역서!I77 -> 0 | I42: =변경내역서!N76 -> 1750411 | J42: =변경내역서!G76 -> 1 | K42: =변경내역서!I76 -> 1380760 | L42: =I42-F42 -> 1750411 | M42: =J42-G42 -> 1 | N42: =K42-H42 -> 1380760
...

Sheet 변경내역서
A1: 총줄수-> | B1: 341 | D1: [ 평창 에코랜드 조성사업(전기) ] | X1: 노임 계산 정보 | AB1: 부속재 및 손료
A2: 번호 | B2: 공종코드 | C2: 코드 | D2: 명 칭 | E2: 규 격 | F2: 단위 | G2: 수량 | H2: 재료비 | J2: 노무비 | L2: 경비 | N2: 단가 | O2: 합 계 | P2: 증감 | R2: 비고 | X2: 노임계 | Y2: 전체(%) | Z2: 공종별(%) | AA2: 노임 소수 | AB2: CD배관재 | AC2: 일반배관재 | AD2: 소모재 | AE2: 자재계 | AF2: 노임계
H3: 단가 | I3: 금액 | J3: 단가 | K3: 금액 | L3: 단가 | M3: 금액 | N3: 합 계 | P3: 수량 | Q3: 금액 | AE3: =IF(옵션!$C$11 =0, "1", 옵션!$C$11) -> 1 | AF3: =IF(옵션!$C$12 =0, "1", 옵션!$C$12) -> 1
B4: 공종줄 | D4: 1.옥외공사::1-1.옥외보안등공사
A5: 5975B467018 | B5: 0101 | C5: 5975B467018 | D5: 경질비닐전선관 | E5: HI 70 mm | F5: M | G5: 6 | H5: 3223 | I5: 19338 | J5: 64190 | K5: 385140 | L5: 0 | M5: 0 | N5: =H5+J5 -> 67413 | O5: =IF((I5+K5+M5)=0, "", (I5+K5+M5)) -> 404478 | P5: =G6-G5 -> -6 | Q5: =O6-O5 -> -404478 | R5: 제 17호 | AC5: 19344 | AD5: 19344 | AF5: 385140
A6: 5975B467018 | B6: 0101 | C6: 5975B467018 | AC6: =I6 -> 0 | AD6: =G6*H6 -> 0 | AF6: =K6 -> 0
A7: 56959000176 | B7: 0101 | C7: 56959000176 | D7: 파상형 폴리에틸렌 전선관 | E7: 30㎜(가로등,신호,구내) | F7: M | G7: 144 | H7: 431 | I7: 62064 | J7: 5786 | K7: 833184 | L7: 0 | M7: 0 | N7: =H7+J7 -> 6217 | O7: =IF((I7+K7+M7)=0, "", (I7+K7+M7)) -> 895248 | P7: =G8-G7 -> -144 | Q7: =O8-O7 -> -895248 | R7: 제 76호 | AC7: 62064 | AD7: 62064 | AF7: 833184
A8: 56959000176 | B8: 0101 | C8: 56959000176 | AC8: =I8 -> 0 | AD8: =G8*H8 -> 0 | AF8: =K8 -> 0
A9: 56959000177 | B9: 0101 | C9: 56959000177 | D9: 파상형 폴리에틸렌 전선관 | E9: 40㎜(가로등,신호,구내) | F9: M | G9: 796 | H9: 564 | I9: 448944 | J9: 7079 | K9: 5634884 | L9: 0 | M9: 0 | N9: =H9+J9 -> 7643 | O9: =IF((I9+K9+M9)=0, "", (I9+K9+M9)) -> 6083828 | P9: =G10-G9 -> -796 | Q9: =O10-O9 -> -6083828 | R9: 제 77호 | AC9: 449740 | AD9: 449740 | AF9: 5635680
A10: 56959000177 | B10: 0101 | C10: 56959000177 | AC10: =I10 -> 0 | AD10: =G10*H10 -> 0 | AF10: =K10 -> 0
A11: 56959000191 | B11: 0101 | C11: 56959000191 | D11: 파상형 폴리에틸렌 전선관 | E11: 65㎜(가로등,신호,구내) | F11: M | G11: 21 | H11: 1080 | I11: 22680 | J11: 8877 | K11: 186417 | L11: 0 | M11: 0 | N11: =H11+J11 -> 9957 | O11: =IF((I11+K11+M11)=0, "", (I11+K11+M11)) -> 209097 | P11: =G12-G11 -> -21 | Q11: =O12-O11 -> -209097 | R11: 제 91호 | AC11: 22680 | AD11: 22680 | AF11: 186417
A12: 56959000191 | B12: 0101 | C12: 56959000191 | N12: =H12+J12 -> 0 | AC12: =I12 -> 0 | AD12: =G12*H12 -> 0 | AF12: =K12 -> 0
A13: 5975E877202 | B13: 0101 | C13: 5975E877202 | D13: 관로구방수장치 | E13: D65 | F13: 조 | G13: 1 | H13: 15857 | I13: 15857 | J13: 49113 | K13: 49113 | L13: 0 | M13: 0 | N13: =H13+J13 -> 64970 | O13: =IF((I13+K13+M13)=0, "", (I13+K13+M13)) -> 64970 | P13: =G14-G13 -> -1 | Q13: =O14-O13 -> -64970 | R13: 제 29호 | AF13: 49114
A14: 5975E877202 | B14: 0101 | C14: 5975E877202 | N14: =H14+J14 -> 0 | AF14: =K14 -> 0
A15: 5975J027005 | B15: 0101 | C15: 5975J027005 | D15: 경질비닐전선관용 부품 | E15: 노말밴드, 70 mm | F15: 개 | G15: 1 | H15: 3124 | I15: 3124 | J15: 0 | K15: 0 | L15: 0 | M15: 0 | N15: =H15+J15 -> 3124 | O15: =IF((I15+K15+M15)=0, "", (I15+K15+M15)) -> 3124 | P15: =G16-G15 -> -1 | Q15: =O16-O15 -> -3124 | R15: 제 35호
A16: 5975J027005 | B16: 0101 | C16: 5975J027005 | N16: =H16+J16 -> 0
A17: 5975D857181 | B17: 0101 | C17: 5975D857181 | D17: 풀박스 | E17: 400×400×300 | F17: 개 | G17: 1 | H17: 20945 | I17: 20945 | J17: 80237 | K17: 80237 | L17: 0 | M17: 0 | N17: =H17+J17 -> 101182 | O17: =IF((I17+K17+M17)=0, "", (I17+K17+M17)) -> 101182 | P17: =G18-G17 -> -1 | Q17: =O18-O17 -> -101182 | R17: 제 48호 | AF17: 80238
A18: 5975D857181 | B18: 0101 | C18: 5975D857181 | N18: =H18+J18 -> 0 | AF18: =K18 -> 0
A19: 56959000173 | B19: 0101 | C19: 56959000173 | D19: 접지용난연절연전선(FGV) | E19: 6㎟(옥외) | F19: M | G19: 986 | H19: 737 | I19: 726682 | J19: 1375 | K19: 1355750 | L19: 0 | M19: 0 | N19: =H19+J19 -> 2112 | O19: =IF((I19+K19+M19)=0, "", (I19+K19+M19)) -> 2082432 | P19: =G20-G19 -> -986 | Q19: =O20-O19 -> -2082432 | R19: 제 73호 | AD19: 727668 | AF19: 1355750
A20: 56959000173 | B20: 0101 | C20: 56959000173 | N20: =H20+J20 -> 0 | AD20: =G20*H20 -> 0 | AF20: =K20 -> 0
A21: 56959000172 | B21: 0101 | C21: 56959000172 | D21: 0.6/1kv 폴리에틸렌 난연케이블 | E21: F-CV 2C×2.5㎟(옥외) | F21: M | G21: 141 | H21: 1150 | I21: 162150 | J21: 3262 | K21: 459942 | L21: 0 | M21: 0 | N21: =H21+J21 -> 4412 | O21: =IF((I21+K21+M21)=0, "", (I21+K21+M21)) -> 622092 | P21: =G22-G21 -> -141 | Q21: =O22-O21 -> -622092 | R21: 제 72호 | AD21: 162150 | AF21: 460083
A22: 56959000172 | B22: 0101 | C22: 56959000172 | N22: =H22+J22 -> 0 | AD22: =G22*H22 -> 0 | AF22: =K22 -> 0
A23: 56959000170 | B23: 0101 | C23: 56959000170 | D23: 0.6/1kv 폴리에틸렌 난연케이블 | E23: F-CV 2C×6㎟(옥외) | F23: M | G23: 147 | H23: 2014 | I23: 296058 | J23: 3262 | K23: 479514 | L23: 0 | M23: 0 | N23: =H23+J23 -> 5276 | O23: =IF((I23+K23+M23)=0, "", (I23+K23+M23)) -> 775572 | P23: =G24-G23 -> -147 | Q23: =O24-O23 -> -775572 | R23: 제 70호 | AD23: 296205 | AF23: 479661
A24: 56959000170 | B24: 0101 | C24: 56959000170 | N24: =H24+J24 -> 0 | AD24: =G24*H24 -> 0 | AF24: =K24 -> 0
A25: 56959000171 | B25: 0101 | C25: 56959000171 | D25: 0.6/1kv 폴리에틸렌 난연케이블 | E25: F-CV 2C×6㎟(옥외),2열포설1열 | F25: M | G25: 1619 | H25: 2008 | I25: 3250952 | J25: 2938 | K25: 4756622 | L25: 0 | M25: 0 | N25: =H25+J25 -> 4946 | O25: =IF((I25+K25+M25)=0, "", (I25+K25+M25)) -> 8007574 | P25: =G26-G25 -> -1619 | Q25: =O26-O25 -> -8007574 | R25: 제 71호 | AD25: 3250952 | AF25: 4758241
A26: 56959000171 | B26: 0101 | C26: 56959000171 | N26: =H26+J26 -> 0 | AD26: =G26*H26 -> 0 | AF26: =K26 -> 0
A27: 56959000192 | B27: 0101 | C27: 56959000192 | D27: 0.6/1kv 폴리에틸렌 난연케이블 | E27: F-CV 2C×6㎟(옥외),5열포설1열 | F27: M | G27: 57 | H27: 2004 | I27: 114228 | J27: 2742 | K27: 156294 | L27: 0 | M27: 0 | N27: =H27+J27 -> 4746 | O27: =IF((I27+K27+M27)=0, "", (I27+K27+M27)) -> 270522 | P27: =G28-G27 -> -57 | Q27: =O28-O27 -> -270522 | R27: 제 92호 | AD27: 114228 | AF27: 156294
A28: 56959000192 | B28: 0101 | C28: 56959000192 | N28: =H28+J28 -> 0 | AD28: =G28*H28 -> 0 | AF28: =K28 -> 0
A29: 56959000193 | B29: 0101 | C29: 56959000193 | D29: 0.6/1kv 폴리에틸렌 난연케이블 | E29: F-CV 2C×6㎟(옥외),6열포설1열 | F29: M | G29: 111 | H29: 2003 | I29: 222333 | J29: 2708 | K29: 300588 | L29: 0 | M29: 0 | N29: =H29+J29 -> 4711 | O29: =IF((I29+K29+M29)=0, "", (I29+K29+M29)) -> 522921 | P29: =G30-G29 -> -111 | Q29: =O30-O29 -> -522921 | R29: 제 93호 | AD29: 222333 | AF29: 300588
A30: 56959000193 | B30: 0101 | C30: 56959000193 | N30: =H30+J30 -> 0 | AD30: =G30*H30 -> 0 | AF30: =K30 -> 0
A31: 5975F057152 | B31: 0101 | C31: 5975F057152 | D31: 지중선용 가선철물 | E31: 케이블표지시트, 0.15x150 | F31: M | G31: 900 | H31: 243 | I31: 218700 | J31: 251 | K31: 225900 | L31: 0 | M31: 0 | N31: =H31+J31 -> 494 | O31: =IF((I31+K31+M31)=0, "", (I31+K31+M31)) -> 444600 | P31: =G32-G31 -> -900 | Q31: =O32-O31 -> -444600 | R31: 제 67호 | AF31: 225900
A32: 5975F057152 | B32: 0101 | C32: 5975F057152 | N32: =H32+J32 -> 0 | AF32: =K32 -> 0
A33: 56951004514 | B33: 0101 | C33: 56951004514 | D33: 가로등중공기초 | E33: 접지(유),500*800*700 | F33: 개소 | G33: 30 | H33: 128594 | I33: 3857820 | J33: 55147 | K33: 1654410 | L33: 4817 | M33: =TRUNC(G33*L33) -> 144510 | N33: =H33+J33 -> 183741 | O33: =IF((I33+K33+M33)=0, "", (I33+K33+M33)) -> 5656740 | P33: =G34-G33 -> -30 | Q33: =O34-O33 -> -5656740 | R33: 제 6호 | AF33: 1654410
A34: 56951004514 | B34: 0101 | C34: 56951004514 | N34: =H34+J34 -> 0 | AF34: =K34 -> 0
A35: 56951004517 | B35: 0101 | C35: 56951004517 | D35: 가로등 건주 기계화 시공 | E35: 일반 5m-7m | F35: 개소 | G35: 30 | H35: 8287 | I35: 248610 | J35: 90382 | K35: 2711460 | L35: 24982 | M35: =TRUNC(G35*L35) -> 749460 | N35: =H35+J35 -> 98669 | O35: =IF((I35+K35+M35)=0, "", (I35+K35+M35)) -> 3709530 | P35: =G36-G35 -> -30 | Q35: =O36-O35 -> -3709530 | R35: 제 7호 | AF35: 2711460
N36: =H36+J36 -> 0
A37: 56959000166 | B37: 0101 | C37: 56959000166 | D37: 정원등중공기초 | E37: 400x500x565x400 | F37: 개소 | G37: 22 | H37: 90884 | I37: 1999448 | J37: 33485 | K37: 736670 | L37: 4817 | M37: =TRUNC(G37*L37) -> 105974 | N37: =H37+J37 -> 124369 | O37: =IF((I37+K37+M37)=0, "", (I37+K37+M37)) -> 2842092 | P37: =G38-G37 -> -22 | Q37: =O38-O37 -> -2842092 | R37: 제 8호 | AF37: 736670
N38: =H38+J38 -> 0
A39: CA565826042 | B39: 0101 | C39: CA565826042 | D39: 기계터파기 | E39: 보통토사(0.7㎥/43.6) | F39: ㎥ | G39: 324 | H39: 333 | I39: 107892 | J39: 804 | K39: 260496 | L39: 418 | M39: =TRUNC(G39*L39) -> 135432 | N39: =H39+J39 -> 1137 | O39: =IF((I39+K39+M39)=0, "", (I39+K39+M39)) -> 503820 | P39: =G40-G39 -> -324 | Q39: =O40-O39 -> -503820 | R39: CA565826042
N40: =H40+J40 -> 0
...

Sheet 신규_공종별내역서
A1: [ 평창 에코랜드 카페 신축공사(전기) ]
A2: 품 명 | B2: 규 격 | C2: 단위 | D2: 수량 | E2: 재 료 비 | G2: 노 무 비 | I2: 경 비 | L2: 비 고 | M2: 품목코드 | N2: 변수 | O2: 설정 | P2: 공종코드 | Q2: 일위 | R2: 단산 | S2: 자재 | T2: 손료적용 | U2: 손료저장 | V2: 적용율 | W2: JUK1 | X2: JUK2 | Y2: JUK3 | Z2: JUK4 | AA2: JUK5 | AB2: JUK6 | AC2: JUK7 | AD2: JUK8 | AE2: JUK9 | AF2: JUK10 | AG2: JUK11 | AH2: JUK12 | AI2: JUK13 | AJ2: JUK14 | AK2: JUK15 | AL2: JUK16 | AM2: JUK17 | AN2: JUK18 | AO2: JUK19 | AP2: JUK20 | AQ2: 자재구분 | AR2: 공종구분 | AS2: 공종레벨 | AT2: 공종+자재 | AU2: 고유번호
E3: 단 가 | F3: 금 액 | G3: 단 가 | H3: 금 액 | I3: 단 가 | J3: 금 액 | K3: 금 액
A4: 1-1-1.전력간선공사 | P4: 01010101
A5: 전주입상관 설치 | B5: HI 104C | C5: M | D5: 10 | E5: =TRUNC(신규_일위대가목록!E4,0) -> 7912 | F5: =TRUNC(E5*D5, 0) -> 79120 | G5: =TRUNC(신규_일위대가목록!F4,0) -> 129719 | H5: =TRUNC(G5*D5, 0) -> 1297190 | I5: =TRUNC(신규_일위대가목록!G4,0) -> 0 | J5: =TRUNC(I5*D5, 0) -> 0 | K5: =TRUNC(F5+H5+J5, 0) -> 1376310 | L5: 신규호표 1 | M5: 56D721037238540E9D307EF2D93E5A | P5: 01010101 | Q5: T | R5: F | S5: F | AT5: 0101010156D721037238540E9D307EF2D93E5A | AU5: 5876
A6: ST 케이블 트레이-STRAIGHT | B6: W400x100Hx2.3t | C6: m | D6: 1 | E6: =TRUNC(신규_일위대가목록!E5,0) -> 35300 | F6: =TRUNC(E6*D6, 0) -> 35300 | G6: =TRUNC(신규_일위대가목록!F5,0) -> 56399 | H6: =TRUNC(G6*D6, 0) -> 56399 | I6: =TRUNC(신규_일위대가목록!G5,0) -> 0 | J6: =TRUNC(I6*D6, 0) -> 0 | K6: =TRUNC(F6+H6+J6, 0) -> 91699 | L6: 신규호표 2 | M6: 56D72103723884C205FF9F5B17316B | P6: 01010101 | Q6: T | R6: F | S6: F | AT6: 0101010156D72103723884C205FF9F5B17316B | AU6: 5944
A7: 난연 비닐 절연 접지용전선(F-GV) | B7: 0.6/1kV 4㎟ | C7: m | D7: 72 | E7: =TRUNC(신규_일위대가목록!E6,0) -> 964 | F7: =TRUNC(E7*D7, 0) -> 69408 | G7: =TRUNC(신규_일위대가목록!F6,0) -> 2114 | H7: =TRUNC(G7*D7, 0) -> 152208 | I7: =TRUNC(신규_일위대가목록!G6,0) -> 0 | J7: =TRUNC(I7*D7, 0) -> 0 | K7: =TRUNC(F7+H7+J7, 0) -> 221616 | L7: 신규호표 3 | M7: 56D721037238E46A4237DB110EC84A | P7: 01010101 | Q7: T | R7: F | S7: F | AT7: 0101010156D721037238E46A4237DB110EC84A | AU7: 6029
A8: 난연 비닐 절연 접지용전선(F-GV) | B8: 0.6/1kV 6㎟ | C8: m | D8: 47 | E8: =TRUNC(신규_일위대가목록!E7,0) -> 849 | F8: =TRUNC(E8*D8, 0) -> 39903 | G8: =TRUNC(신규_일위대가목록!F7,0) -> 2330 | H8: =TRUNC(G8*D8, 0) -> 109510 | I8: =TRUNC(신규_일위대가목록!G7,0) -> 0 | J8: =TRUNC(I8*D8, 0) -> 0 | K8: =TRUNC(F8+H8+J8, 0) -> 149413 | L8: 신규호표 4 | M8: 56D721037238E46A4237DB110EC952 | P8: 01010101 | Q8: T | R8: F | S8: F | AT8: 0101010156D721037238E46A4237DB110EC952 | AU8: 6030
A9: 난연 비닐 절연 접지용전선(F-GV) | B9: 0.6/1kV 16㎟ | C9: m | D9: 165 | E9: =TRUNC(신규_일위대가목록!E8,0) -> 1963 | F9: =TRUNC(E9*D9, 0) -> 323895 | G9: =TRUNC(신규_일위대가목록!F8,0) -> 2467 | H9: =TRUNC(G9*D9, 0) -> 407055 | I9: =TRUNC(신규_일위대가목록!G8,0) -> 0 | J9: =TRUNC(I9*D9, 0) -> 0 | K9: =TRUNC(F9+H9+J9, 0) -> 730950 | L9: 신규호표 5 | M9: 56D721037238E46A4237DB110ECFFA | P9: 01010101 | Q9: T | R9: F | S9: F | AT9: 0101010156D721037238E46A4237DB110ECFFA | AU9: 5956
A10: 난연 비닐 절연 접지용전선(F-GV) | B10: 0.6/1kV 25㎟ | C10: m | D10: 228 | E10: =TRUNC(신규_일위대가목록!E9,0) -> 3829 | F10: =TRUNC(E10*D10, 0) -> 873012 | G10: =TRUNC(신규_일위대가목록!F9,0) -> 2467 | H10: =TRUNC(G10*D10, 0) -> 562476 | I10: =TRUNC(신규_일위대가목록!G9,0) -> 0 | J10: =TRUNC(I10*D10, 0) -> 0 | K10: =TRUNC(F10+H10+J10, 0) -> 1435488 | L10: 신규호표 6 | M10: 56D721037238E46A4237DB110ECFFE | P10: 01010101 | Q10: T | R10: F | S10: F | AT10: 0101010156D721037238E46A4237DB110ECFFE | AU10: 5957
A11: 난연 비닐 절연 접지용전선(F-GV) | B11: 0.6/1kV 185㎟ | C11: m | D11: 19.5 | E11: =TRUNC(신규_일위대가목록!E10,0) -> 25923 | F11: =TRUNC(E11*D11, 0) -> 505498 | G11: =TRUNC(신규_일위대가목록!F10,0) -> 4934 | H11: =TRUNC(G11*D11, 0) -> 96213 | I11: =TRUNC(신규_일위대가목록!G10,0) -> 0 | J11: =TRUNC(I11*D11, 0) -> 0 | K11: =TRUNC(F11+H11+J11, 0) -> 601711 | L11: 신규호표 7 | M11: 56D721037238E46A4237DB110FD271 | P11: 01010101 | Q11: T | R11: F | S11: F | AT11: 0101010156D721037238E46A4237DB110FD271 | AU11: 5958
A12: 0.6/1kV 난연 전력 케이블(F-CV)-4열동시 | B12: 1C 50㎟ | C12: m | D12: 912 | E12: =TRUNC(신규_일위대가목록!E11,0) -> 7564 | F12: =TRUNC(E12*D12, 0) -> 6898368 | G12: =TRUNC(신규_일위대가목록!F11,0) -> 2445 | H12: =TRUNC(G12*D12, 0) -> 2229840 | I12: =TRUNC(신규_일위대가목록!G11,0) -> 0 | J12: =TRUNC(I12*D12, 0) -> 0 | K12: =TRUNC(F12+H12+J12, 0) -> 9128208 | L12: 신규호표 8 | M12: 56D721037238F471B0B3142049583E | P12: 01010101 | Q12: T | R12: F | S12: F | AT12: 0101010156D721037238F471B0B3142049583E | AU12: 5959
A13: 0.6/1kV 난연 전력 케이블(F-CV)-4열동시 | B13: 1C 185㎟ | C13: m | D13: 212 | E13: =TRUNC(신규_일위대가목록!E12,0) -> 28240 | F13: =TRUNC(E13*D13, 0) -> 5986880 | G13: =TRUNC(신규_일위대가목록!F12,0) -> 5128 | H13: =TRUNC(G13*D13, 0) -> 1087136 | I13: =TRUNC(신규_일위대가목록!G12,0) -> 0 | J13: =TRUNC(I13*D13, 0) -> 0 | K13: =TRUNC(F13+H13+J13, 0) -> 7074016 | L13: 신규호표 9 | M13: 56D721037238F471B0B31420484E79 | P13: 01010101 | Q13: T | R13: F | S13: F | AT13: 0101010156D721037238F471B0B31420484E79 | AU13: 5870
A14: 0.6/1kV 난연 전력 케이블(F-CV) | B14: 2C 4㎟ | C14: m | D14: 72 | E14: =TRUNC(신규_일위대가목록!E13,0) -> 1677 | F14: =TRUNC(E14*D14, 0) -> 120744 | G14: =TRUNC(신규_일위대가목록!F13,0) -> 4086 | H14: =TRUNC(G14*D14, 0) -> 294192 | I14: =TRUNC(신규_일위대가목록!G13,0) -> 0 | J14: =TRUNC(I14*D14, 0) -> 0 | K14: =TRUNC(F14+H14+J14, 0) -> 414936 | L14: 신규호표 10 | M14: 56D721037238F471B0B317F58E47CF | P14: 01010101 | Q14: T | R14: F | S14: F | AT14: 0101010156D721037238F471B0B317F58E47CF | AU14: 6031
A15: 0.6/1kV 난연 전력 케이블(F-CV) | B15: 4C 6㎟ | C15: m | D15: 47 | E15: =TRUNC(신규_일위대가목록!E14,0) -> 4046 | F15: =TRUNC(E15*D15, 0) -> 190162 | G15: =TRUNC(신규_일위대가목록!F14,0) -> 9238 | H15: =TRUNC(G15*D15, 0) -> 434186 | I15: =TRUNC(신규_일위대가목록!G14,0) -> 0 | J15: =TRUNC(I15*D15, 0) -> 0 | K15: =TRUNC(F15+H15+J15, 0) -> 624348 | L15: 신규호표 11 | M15: 56D721037238F471B0B3116C8247CE | P15: 01010101 | Q15: T | R15: F | S15: F | AT15: 0101010156D721037238F471B0B3116C8247CE | AU15: 6032
A16: 0.6/1kV 난연 전력 케이블(F-CV) | B16: 4C 16㎟ | C16: m | D16: 165 | E16: =TRUNC(신규_일위대가목록!E15,0) -> 10984 | F16: =TRUNC(E16*D16, 0) -> 1812360 | G16: =TRUNC(신규_일위대가목록!F15,0) -> 15272 | H16: =TRUNC(G16*D16, 0) -> 2519880 | I16: =TRUNC(신규_일위대가목록!G15,0) -> 0 | J16: =TRUNC(I16*D16, 0) -> 0 | K16: =TRUNC(F16+H16+J16, 0) -> 4332240 | L16: 신규호표 12 | M16: 56D721037238F471B0B3116C824479 | P16: 01010101 | Q16: T | R16: F | S16: F | AT16: 0101010156D721037238F471B0B3116C824479 | AU16: 5961
... A22: 핸드홀(수공1호) | B22: 950*450*700 | C22: 조 | D22: 3 | E22: =TRUNC(신규_일위대가목록!E21,0) -> 750497 | F22: =TRUNC(E22*D22, 0) -> 2251491 | G22: =TRUNC(신규_일위대가목록!F21,0) -> 436033 | H22: =TRUNC(G22*D22, 0) -> 1308099 | I22: =TRUNC(신규_일위대가목록!G21,0) -> 11085 | J22: =TRUNC(I22*D22, 0) -> 33255 | K22: =TRUNC(F22+H22+J22, 0) -> 3592845 | L22: 신규호표 18 | M22: 56D72103703DD43A1ED2B005ADF627 | P22: 01010101 | Q22: T | R22: F | S22: F | AT22: 0101010156D72103703DD43A1ED2B005ADF627 | AU22: 5966
A23: 접지공사(접지봉매설) | C23: 개소 | D23: 1 | E23: =TRUNC(신규_일위대가목록!E22,0) -> 52854 | F23: =TRUNC(E23*D23, 0) -> 52854 | G23: =TRUNC(신규_일위대가목록!F22,0) -> 126539 | H23: =TRUNC(G23*D23, 0) -> 126539 | I23: =TRUNC(신규_일위대가목록!G22,0) -> 2838 | J23: =TRUNC(I23*D23, 0) -> 2838 | K23: =TRUNC(F23+H23+J23, 0) -> 182231 | L23: 신규호표 19 | M23: 56D72103723894E92CAB35A83F0DCD | P23: 01010101 | Q23: T | R23: F | S23: F | AT23: 0101010156D72103723894E92CAB35A83F0DCD | AU23: 5781
A24: 파상형 폴리에틸렌 전선관 | B24: 30mm | C24: M | D24: 70 | E24: =TRUNC(신규_일위대가목록!E23,0) -> 487 | F24: =TRUNC(E24*D24, 0) -> 34090 | G24: =TRUNC(신규_일위대가목록!F23,0) -> 6535 | H24: =TRUNC(G24*D24, 0) -> 457450 | I24: =TRUNC(신규_일위대가목록!G23,0) -> 0 | J24: =TRUNC(I24*D24, 0) -> 0 | K24: =TRUNC(F24+H24+J24, 0) -> 491540 | L24: 신규호표 20 | M24: 56D721037238446715351CA32E7F48 | P24: 01010101 | Q24: T | R24: F | S24: F | AT24: 0101010156D721037238446715351CA32E7F48 | AU24: 6033
A25: 합성수지 파형관(ELP)설치 | B25: 40mm | C25: M | D25: 45 | E25: =TRUNC(신규_일위대가목록!E24,0) -> 638 | F25: =TRUNC(E25*D25, 0) -> 28710 | G25: =TRUNC(신규_일위대가목록!F24,0) -> 7996 | H25: =TRUNC(G25*D25, 0) -> 359820 | I25: =TRUNC(신규_일위대가목록!G24,0) -> 0 | J25: =TRUNC(I25*D25, 0) -> 0 | K25: =TRUNC(F25+H25+J25, 0) -> 388530 | L25: 신규호표 21 | M25: 56D721037238446715351CA32E7EA0 | P25: 01010101 | Q25: T | R25: F | S25: F | AT25: 0101010156D721037238446715351CA32E7EA0 | AU25: 5872
A26: 합성수지 파형관(ELP)설치 | B26: 50mm | C26: M | D26: 172.5 | E26: =TRUNC(신규_일위대가목록!E25,0) -> 927 | F26: =TRUNC(E26*D26, 0) -> 159907 | G26: =TRUNC(신규_일위대가목록!F25,0) -> 4965 | H26: =TRUNC(G26*D26, 0) -> 856462 | I26: =TRUNC(신규_일위대가목록!G25,0) -> 0 | J26: =TRUNC(I26*D26, 0) -> 0 | K26: =TRUNC(F26+H26+J26, 0) -> 1016369 | L26: 신규호표 22 | M26: 56D721037238446715351CA32E7EA3 | P26: 01010101 | Q26: T | R26: F | S26: F | AT26: 0101010156D721037238446715351CA32E7EA3 | AU26: 5967
A27: 합성수지 파형관(ELP)설치 | B27: 65mm | C27: M | D27: 220 | E27: =TRUNC(신규_일위대가목록!E26,0) -> 1117 | F27: =TRUNC(E27*D27, 0) -> 245740 | G27: =TRUNC(신규_일위대가목록!F26,0) -> 6225 | H27: =TRUNC(G27*D27, 0) -> 1369500 | I27: =TRUNC(신규_일위대가목록!G26,0) -> 0 | J27: =TRUNC(I27*D27, 0) -> 0 | K27: =TRUNC(F27+H27+J27, 0) -> 1615240 | L27: 신규호표 23 | M27: 56D721037238446715351CA32E793E | P27: 01010101 | Q27: T | R27: F | S27: F | AT27: 0101010156D721037238446715351CA32E793E | AU27: 5968
A28: 합성수지 파형관(ELP)설치 | B28: 100mm | C28: M | D28: 45 | E28: =TRUNC(신규_일위대가목록!E27,0) -> 2389 | F28: =TRUNC(E28*D28, 0) -> 107505 | G28: =TRUNC(신규_일위대가목록!F27,0) -> 9227 | H28: =TRUNC(G28*D28, 0) -> 415215 | I28: =TRUNC(신규_일위대가목록!G27,0) -> 0 | J28: =TRUNC(I28*D28, 0) -> 0 | K28: =TRUNC(F28+H28+J28, 0) -> 522720 | L28: 신규호표 24 | M28: 56D721037238446715351CA32E7819 | P28: 01010101 | Q28: T | R28: F | S28: F | AT28: 0101010156D721037238446715351CA32E7819 | AU28: 5873
A29: 자립형 함체 기초 | B29: 1,000x1,000x500 | C29: 식 | D29: 1 | E29: =TRUNC(신규_일위대가목록!E28,0) -> 72386 | F29: =TRUNC(E29*D29, 0) -> 72386 | G29: =TRUNC(신규_일위대가목록!F28,0) -> 105831 | H29: =TRUNC(G29*D29, 0) -> 105831 | I29: =TRUNC(신규_일위대가목록!G28,0) -> 891 | J29: =TRUNC(I29*D29, 0) -> 891 | K29: =TRUNC(F29+H29+J29, 0) -> 179108 | L29: 신규호표 25 | M29: 56D72103723894E928313793BD42CF | P29: 01010101 | Q29: T | R29: F | S29: F | AT29: 0101010156D72103723894E928313793BD42CF | AU29: 5969
A30: 계량기함 설치 | C30: 면 | D30: 1 | E30: =TRUNC(신규_일위대가목록!E29,0) -> 6697 | F30: =TRUNC(E30*D30, 0) -> 6697 | G30: =TRUNC(신규_일위대가목록!F29,0) -> 223248 | H30: =TRUNC(G30*D30, 0) -> 223248 | I30: =TRUNC(신규_일위대가목록!G29,0) -> 0 | J30: =TRUNC(I30*D30, 0) -> 0 | K30: =TRUNC(F30+H30+J30, 0) -> 229945 | L30: 신규호표 26 | M30: 56D721037238540E9D307EF2D93456 | P30: 01010101 | Q30: T | R30: F | S30: F | AT30: 0101010156D721037238540E9D307EF2D93456 | AU30: 5865
A31: 분전반 신설(LP-M) | B31: 옥외벽부자립형 | C31: 면 | D31: 1 | E31: =TRUNC(신규_일위대가목록!E30,0) -> 8671 | F31: =TRUNC(E31*D31, 0) -> 8671 | G31: =TRUNC(신규_일위대가목록!F30,0) -> 289048 | H31: =TRUNC(G31*D31, 0) -> 289048 | I31: =TRUNC(신규_일위대가목록!G30,0) -> 0 | J31: =TRUNC(I31*D31, 0) -> 0 | K31: =TRUNC(F31+H31+J31, 0) -> 297719 | L31: 신규호표 27 | M31: 56D721037238540E9D307EF2DBEACF | P31: 01010101 | Q31: T | R31: F | S31: F | AT31: 0101010156D721037238540E9D307EF2DBEACF | AU31: 5970
A32: 역전력 보호계전기 분전반 신설 | B32: 550*780*250 | C32: 면 | D32: 1 | E32: =TRUNC(신규_일위대가목록!E31,0) -> 3105702 | F32: =TRUNC(E32*D32, 0) -> 3105702 | G32: =TRUNC(신규_일위대가목록!F31,0) -> 223248 | H32: =TRUNC(G32*D32, 0) -> 223248 | I32: =TRUNC(신규_일위대가목록!G31,0) -> 0 | J32: =TRUNC(I32*D32, 0) -> 0 | K32: =TRUNC(F32+H32+J32, 0) -> 3328950 | L32: 신규호표 28 | M32: 56D721037238540E9D307EF2DBEBE9 | P32: 01010101 | Q32: T | R32: F | S32: F | AT32: 0101010156D721037238540E9D307EF2DBEBE9 | AU32: 6037
A33: 분전반 신설(LP-O1) | B33: 옥외 자립형 | C33: 면 | D33: 1 | E33: =TRUNC(신규_일위대가목록!E32,0) -> 7190 | F33: =TRUNC(E33*D33, 0) -> 7190 | G33: =TRUNC(신규_일위대가목록!F32,0) -> 239698 | H33: =TRUNC(G33*D33, 0) -> 239698 | I33: =TRUNC(신규_일위대가목록!G32,0) -> 0 | J33: =TRUNC(I33*D33, 0) -> 0 | K33: =TRUNC(F33+H33+J33, 0) -> 246888 | L33: 신규호표 29 | M33: 56D721037238540E9D307EF2DBEBEC | P33: 01010101 | Q33: T | R33: F | S33: F | AT33: 0101010156D721037238540E9D307EF2DBEBEC | AU33: 5971
A34: 엔트런스 캡 | B34: 2 1/4" (54mm)초과-104C | C34: 개 | D34: 2 | E34: =TRUNC(신규_일위대가목록!E33,0) -> 53440 | F34: =TRUNC(E34*D34, 0) -> 106880 | G34: =TRUNC(신규_일위대가목록!F33,0) -> 28199 | H34: =TRUNC(G34*D34, 0) -> 56398 | I34: =TRUNC(신규_일위대가목록!G33,0) -> 0 | J34: =TRUNC(I34*D34, 0) -> 0 | K34: =TRUNC(F34+H34+J34, 0) -> 163278 | L34: 신규호표 30 | M34: 56D721037238540E9D307CC4DD9E9E | P34: 01010101 | Q34: T | R34: F | S34: F | AT34: 0101010156D721037238540E9D307CC4DD9E9E | AU34: 5875
A35: 터파기(기계 9:1) | B35: 보통토사. 백호 90%+인력 10% | C35: ㎥ | D35: 123.75 | E35: =TRUNC(신규_일위대가목록!E34,0) -> 600 | F35: =TRUNC(E35*D35, 0) -> 74250 | G35: =TRUNC(신규_일위대가목록!F34,0) -> 6909 | H35: =TRUNC(G35*D35, 0) -> 854988 | I35: =TRUNC(신규_일위대가목록!G34,0) -> 785 | J35: =TRUNC(I35*D35, 0) -> 97143 | K35: =TRUNC(F35+H35+J35, 0) -> 1026381 | L35: 신규호표 31 | M35: 569DE103C338D485C142AB2FBA6AB2 | P35: 01010101 | Q35: T | R35: F | S35: F | AT35: 01010101569DE103C338D485C142AB2FBA6AB2 | AU35: 5785
A36: 되메우고 다지기(백호+래머) | B36: 토사, T=15cm | C36: M3 | D36: 123.75 | E36: =TRUNC(신규_일위대가목록!E35,0) -> 6606 | F36: =TRUNC(E36*D36, 0) -> 817492 | G36: =TRUNC(신규_일위대가목록!F35,0) -> 525 | H36: =TRUNC(G36*D36, 0) -> 64968 | I36: =TRUNC(신규_일위대가목록!G35,0) -> 419 | J36: =TRUNC(I36*D36, 0) -> 51851 | K36: =TRUNC(F36+H36+J36, 0) -> 934311 | L36: 신규호표 32 | M36: 569DE103C53B84CC97FB4DEFFA0997 | P36: 01010101 | Q36: T | R36: F | S36: F | AT36: 01010101569DE103C53B84CC97FB4DEFFA0997 | AU36: 5786
A37: 맨홀(저압) | B37: 1,500*1,500*1,500 | C37: 개소 | D37: 1 | E37: =TRUNC(신규_일위대가목록!E36,0) -> 835710 | F37: =TRUNC(E37*D37, 0) -> 835710 | G37: =TRUNC(신규_일위대가목록!F36,0) -> 893392 | H37: =TRUNC(G37*D37, 0) -> 893392 | I37: =TRUNC(신규_일위대가목록!G36,0) -> 118141 | J37: =TRUNC(I37*D37, 0) -> 118141 | K37: =TRUNC(F37+H37+J37, 0) -> 1847243 | L37: 신규호표 33 | M37: 56D72103723894E92F608073667515 | P37: 01010101 | Q37: T | R37: F | S37: F | AT37: 0101010156D72103723894E92F608073667515 | AU37: 5877
A51: [ 합 계 ] | F51: =SUM(F5:F50) -> 25153358 | H51: =SUM(H5:H50) -> 19805260 | J51: =SUM(J5:J50) -> 304119 | K51: =SUM(K5:K50) -> 45262737 | M51: TOTAL
A52: 1-1-2.옥외조명전원설비공사 | P52: 01010102
A53: 풀박스 | B53: 100X100X50 | C53: 개 | D53: 4 | E53: =TRUNC(신규_일위대가목록!E37,0) -> 2663 | F53: =TRUNC(E53*D53, 0) -> 10652 | G53: =TRUNC(신규_일위대가목록!F37,0) -> 9399 | H53: =TRUNC(G53*D53, 0) -> 37596 | I53: =TRUNC(신규_일위대가목록!G37,0) -> 0 | J53: =TRUNC(I53*D53, 0) -> 0 | K53: =TRUNC(F53+H53+J53, 0) -> 48248 | L53: 신규호표 34 | M53: 56D721037238540E9FFE4D14B82D67 | P53: 01010102 | Q53: T | R53: F | S53: F | AT53: 0101010256D721037238540E9FFE4D14B82D67 | AU53: 5972
A54: 난연 비닐 절연 접지용전선(F-GV) | B54: 0.6/1kV 4㎟ | C54: m | D54: 564.5 | E54: =TRUNC(신규_일위대가목록!E38,0) -> 964 | F54: =TRUNC(E54*D54, 0) -> 544178 | G54: =TRUNC(신규_일위대가목록!F38,0) -> 2114 | H54: =TRUNC(G54*D54, 0) -> 1193353 | I54: =TRUNC(신규_일위대가목록!G38,0) -> 0 | J54: =TRUNC(I54*D54, 0) -> 0 | K54: =TRUNC(F54+H54+J54, 0) -> 1737531 | L54: 신규호표 35 | M54: 56D721037238E46A4237DB110EC84B | P54: 01010102 | Q54: T | R54: F | S54: F | AT54: 0101010256D721037238E46A4237DB110EC84B | AU54: 5973
A55: 난연 비닐 절연 접지용전선(F-GV) | B55: 0.6/1kV 6㎟ | C55: m | D55: 654.5 | E55: =TRUNC(신규_일위대가목록!E7,0) -> 849 | F55: =TRUNC(E55*D55, 0) -> 555670 | G55: =TRUNC(신규_일위대가목록!F7,0) -> 2330 | H55: =TRUNC(G55*D55, 0) -> 1524985 | I55: =TRUNC(신규_일위대가목록!G7,0) -> 0 | J55: =TRUNC(I55*D55, 0) -> 0 | K55: =TRUNC(F55+H55+J55, 0) -> 2080655 | L55: 신규호표 4 | M55: 56D721037238E46A4237DB110EC952 | P55: 01010102 | Q55: T | R55: F | S55: F | AT55: 0101010256D721037238E46A4237DB110EC952 | AU55: 5974
A56: 0.6/1kV 난연 전력 케이블(F-CV) | B56: 2C 4㎟ | C56: m | D56: 564.5 | E56: =TRUNC(신규_일위대가목록!E13,0) -> 1677 | F56: =TRUNC(E56*D56, 0) -> 946666 | G56: =TRUNC(신규_일위대가목록!F13,0) -> 4086 | H56: =TRUNC(G56*D56, 0) -> 2306547 | I56: =TRUNC(신규_일위대가목록!G13,0) -> 0 | J56: =TRUNC(I56*D56, 0) -> 0 | K56: =TRUNC(F56+H56+J56, 0) -> 3253213 | L56: 신규호표 10 | M56: 56D721037238F471B0B317F58E47CF | P56: 01010102 | Q56: T | R56: F | S56: F | AT56: 0101010256D721037238F471B0B317F58E47CF | AU56: 5981
A57: 0.6/1kV 난연 전력 케이블(F-CV) | B57: 2C 6㎟ | C57: m | D57: 960 | E57: =TRUNC(신규_일위대가목록!E39,0) -> 2275 | F57: =TRUNC(E57*D57, 0) -> 2184000 | G57: =TRUNC(신규_일위대가목록!F39,0) -> 3685 | H57: =TRUNC(G57*D57, 0) -> 3537600 | I57: =TRUNC(신규_일위대가목록!G39,0) -> 0 | J57: =TRUNC(I57*D57, 0) -> 0 | K57: =TRUNC(F57+H57+J57, 0) -> 5721600 | L57: 신규호표 36 | M57: 56D721037238F471B0B317F58E4080 | P57: 01010102 | Q57: T | R57: F | S57: F | AT57: 0101010256D721037238F471B0B317F58E4080 | AU57: 5982
A58: 누전차단기 | B58: ELB 2P 30AF | C58: 개 | D58: 16 | E58: =TRUNC(신규_일위대가목록!E40,0) -> 40781 | F58: =TRUNC(E58*D58, 0) -> 652496 | G58: =TRUNC(신규_일위대가목록!F40,0) -> 31254 | H58: =TRUNC(G58*D58, 0) -> 500064 | I58: =TRUNC(신규_일위대가목록!G40,0) -> 0 | J58: =TRUNC(I58*D58, 0) -> 0 | K58: =TRUNC(F58+H58+J58, 0) -> 1152560 | L58: 신규호표 37 | M58: 56D72103723894E928313793BD474E | P58: 01010102 | Q58: T | R58: F | S58: F | AT58: 0101010256D72103723894E928313793BD474E | AU58: 5878
...

Sheet 일위대가목록
B1: 107 | C1: [ 평창 에코랜드 조성사업(전기) ] - 일위대가목차
A2: 번호 | B2: … | C2: 코드 | D2: 명 칭 | E2: 규 격 | F2: 단위 | G2: 수량 | H2: 재료비 | J2: 노무비 | M2: 경비 | O2: 계 | P2: 계 | Q2: 비고
H3: 단가 | I3: 금액 | J3: 수량 | K3: 단가 | L3: 금액 | M3: 단가 | N3: 금액 | O3: 단가
A4: 56950120022 | B4: 56950120022 | C4: 제 1호 | D4: 파이프행가 | E4: 22 C | F4: 개소 | H4: =일위대가!I12 -> 1515 | I4: =H4 -> 1515 | K4: =일위대가!L12 -> 8253 | L4: =K4 -> 8253 | M4: =일위대가!N12 -> 0 | N4: =M4 -> 0 | O4: =IF((H4+K4+M4)=0, "", (H4+K4+M4)) -> 9768 | P4: =SUM(I4,L4,N4) -> 9768
A5: 56950120036 | B5: 56950120036 | C5: 제 2호 | D5: 파이프행가 | E5: 36 C | F5: 개소 | H5: =일위대가!I22 -> 1548 | I5: =H5 -> 1548 | K5: =일위대가!L22 -> 8253 | L5: =K5 -> 8253 | M5: =일위대가!N22 -> 0 | N5: =M5 -> 0 | O5: =IF((H5+K5+M5)=0, "", (H5+K5+M5)) -> 9801 | P5: =SUM(I5,L5,N5) -> 9801
A6: 56950120104 | B6: 56950120104 | C6: 제 3호 | D6: 파이프행가 | E6: 104 C | F6: 개소 | H6: =일위대가!I32 -> 2334 | I6: =H6 -> 2334 | K6: =일위대가!L32 -> 8253 | L6: =K6 -> 8253 | M6: =일위대가!N32 -> 0 | N6: =M6 -> 0 | O6: =IF((H6+K6+M6)=0, "", (H6+K6+M6)) -> 10587 | P6: =SUM(I6,L6,N6) -> 10587
A7: 56950201000 | B7: 56950201000 | C7: 제 4호 | D7: 맨홀 | E7: 1000x1000x1000 | F7: 개소 | H7: =일위대가!I47 -> 592735 | I7: =H7 -> 592735 | K7: =일위대가!L47 -> 445385 | L7: =K7 -> 445385 | M7: =일위대가!N47 -> 45539 | N7: =M7 -> 45539 | O7: =IF((H7+K7+M7)=0, "", (H7+K7+M7)) -> 1083659 | P7: =SUM(I7,L7,N7) -> 1083659
A8: 56950220300 | B8: 56950220300 | C8: 제 5호 | D8: 접지공사 | E8: 3종 | F8: 개소 | H8: =일위대가!I58 -> 46799 | I8: =H8 -> 46799 | K8: =일위대가!L58 -> 112041 | L8: =K8 -> 112041 | M8: =일위대가!N58 -> 2512 | N8: =M8 -> 2512 | O8: =IF((H8+K8+M8)=0, "", (H8+K8+M8)) -> 161352 | P8: =SUM(I8,L8,N8) -> 161352
A9: 56951004514 | B9: 56951004514 | C9: 제 6호 | D9: 가로등중공기초 | E9: 접지(유),500*800*700 | F9: 개소 | H9: =일위대가!I67 -> 128594 | I9: =H9 -> 128594 | K9: =일위대가!L67 -> 55147 | L9: =K9 -> 55147 | M9: =일위대가!N67 -> 4818 | N9: =M9 -> 4818 | O9: =IF((H9+K9+M9)=0, "", (H9+K9+M9)) -> 188559 | P9: =SUM(I9,L9,N9) -> 188559
A10: 56951004517 | B10: 56951004517 | C10: 제 7호 | D10: 가로등 건주 기계화 시공 | E10: 일반 5m-7m | F10: 개소 | H10: =일위대가!I73 -> 8287 | I10: =H10 -> 8287 | K10: =일위대가!L73 -> 90382 | L10: =K10 -> 90382 | M10: =일위대가!N73 -> 24982 | N10: =M10 -> 24982 | O10: =IF((H10+K10+M10)=0, "", (H10+K10+M10)) -> 123651 | P10: =SUM(I10,L10,N10) -> 123651
A11: 56959000166 | B11: 56959000166 | C11: 제 8호 | D11: 정원등중공기초 | E11: 400x500x565x400 | F11: 개소 | H11: =일위대가!I82 -> 90884 | I11: =H11 -> 90884 | K11: =일위대가!L82 -> 33485 | L11: =K11 -> 33485 | M11: =일위대가!N82 -> 4818 | N11: =M11 -> 4818 | O11: =IF((H11+K11+M11)=0, "", (H11+K11+M11)) -> 129187 | P11: =SUM(I11,L11,N11) -> 129187
A12: 5975A337002 | B12: 5975A337002 | C12: 제 9호 | D12: 강제전선관 | E12: 아연도 22 mm | F12: M | H12: =일위대가!I90 -> 2968 | I12: =H12 -> 2968 | K12: =일위대가!L90 -> 25217 | L12: =K12 -> 25217 | M12: =일위대가!N90 -> 0 | N12: =M12 -> 0 | O12: =IF((H12+K12+M12)=0, "", (H12+K12+M12)) -> 28185 | P12: =SUM(I12,L12,N12) -> 28185
A13: 5975A337004 | B13: 5975A337004 | C13: 제 10호 | D13: 강제전선관 | E13: 아연도 36 mm | F13: M | H13: =일위대가!I98 -> 4998 | I13: =H13 -> 4998 | K13: =일위대가!L98 -> 45850 | L13: =K13 -> 45850 | M13: =일위대가!N98 -> 0 | N13: =M13 -> 0 | O13: =IF((H13+K13+M13)=0, "", (H13+K13+M13)) -> 50848 | P13: =SUM(I13,L13,N13) -> 50848
A14: 5975A337010 | B14: 5975A337010 | C14: 제 11호 | D14: 강제전선관 | E14: 아연도 104 mm | F14: M | H14: =일위대가!I106 -> 18742 | I14: =H14 -> 18742 | K14: =일위대가!L106 -> 162769 | L14: =K14 -> 162769 | M14: =일위대가!N106 -> 0 | N14: =M14 -> 0 | O14: =IF((H14+K14+M14)=0, "", (H14+K14+M14)) -> 181511 | P14: =SUM(I14,L14,N14) -> 181511
A15: 5975A337012 | B15: 5975A337012 | C15: 제 12호 | D15: 강제전선관(노출) | E15: 아연도 22 mm | F15: M | H15: =일위대가!I114 -> 3069 | I15: =H15 -> 3069 | K15: =일위대가!L114 -> 30261 | L15: =K15 -> 30261 | M15: =일위대가!N114 -> 0 | N15: =M15 -> 0 | O15: =IF((H15+K15+M15)=0, "", (H15+K15+M15)) -> 33330 | P15: =SUM(I15,L15,N15) -> 33330
A16: 5975B467012 | B16: 5975B467012 | C16: 제 13호 | D16: 경질비닐전선관 | E16: HI 16 mm | F16: M | H16: =일위대가!I122 -> 495 | I16: =H16 -> 495 | K16: =일위대가!L122 -> 11462 | L16: =K16 -> 11462 | M16: =일위대가!N122 -> 0 | N16: =M16 -> 0 | O16: =IF((H16+K16+M16)=0, "", (H16+K16+M16)) -> 11957 | P16: =SUM(I16,L16,N16) -> 11957
A17: 5975B467014 | B17: 5975B467014 | C17: 제 14호 | D17: 경질비닐전선관 | E17: HI 28 mm | F17: M | H17: =일위대가!I130 -> 994 | I17: =H17 -> 994 | K17: =일위대가!L130 -> 18340 | L17: =K17 -> 18340 | M17: =일위대가!N130 -> 0 | N17: =M17 -> 0 | O17: =IF((H17+K17+M17)=0, "", (H17+K17+M17)) -> 19334 | P17: =SUM(I17,L17,N17) -> 19334
A18: 5975B467015 | B18: 5975B467015 | C18: 제 15호 | D18: 경질비닐전선관 | E18: HI 36 mm | F18: M | H18: =일위대가!I138 -> 1249 | I18: =H18 -> 1249 | K18: =일위대가!L138 -> 22925 | L18: =K18 -> 22925 | M18: =일위대가!N138 -> 0 | N18: =M18 -> 0 | O18: =IF((H18+K18+M18)=0, "", (H18+K18+M18)) -> 24174 | P18: =SUM(I18,L18,N18) -> 24174
A19: 5975B467016 | B19: 5975B467016 | C19: 제 16호 | D19: 경질비닐전선관 | E19: HI 42 mm | F19: M | H19: =일위대가!I146 -> 1564 | I19: =H19 -> 1564 | K19: =일위대가!L146 -> 29802 | L19: =K19 -> 29802 | M19: =일위대가!N146 -> 0 | N19: =M19 -> 0 | O19: =IF((H19+K19+M19)=0, "", (H19+K19+M19)) -> 31366 | P19: =SUM(I19,L19,N19) -> 31366
A20: 5975B467018 | B20: 5975B467018 | C20: 제 17호 | D20: 경질비닐전선관 | E20: HI 70 mm | F20: M | H20: =일위대가!I154 -> 3224 | I20: =H20 -> 3224 | K20: =일위대가!L154 -> 64190 | L20: =K20 -> 64190 | M20: =일위대가!N154 -> 0 | N20: =M20 -> 0 | O20: =IF((H20+K20+M20)=0, "", (H20+K20+M20)) -> 67414 | P20: =SUM(I20,L20,N20) -> 67414
A21: 5975B467020 | B21: 5975B467020 | C21: 제 18호 | D21: 경질비닐전선관 | E21: HI 104 mm | F21: M | H21: =일위대가!I162 -> 5938 | I21: =H21 -> 5938 | K21: =일위대가!L162 -> 105456 | L21: =K21 -> 105456 | M21: =일위대가!N162 -> 0 | N21: =M21 -> 0 | O21: =IF((H21+K21+M21)=0, "", (H21+K21+M21)) -> 111394 | P21: =SUM(I21,L21,N21) -> 111394
